Workbook
Name b0: NSS!$C$248
Name b0: '[1]Nelson Siegel Model'!$B$16
Name b1_: NSS!$C$249
Name b1_: '[1]Nelson Siegel Model'!$B$17
Name b2_: NSS!$C$250
Name b2_: '[1]Nelson Siegel Model'!$B$18
Name b3_: '[2]Nelson Siegel Svensson Model'!$C$39
Name b3_: NSS!$C$251
Name b3_: '[2]Nelson Siegel Svensson Model'!$C$39
Name b3_: #REF!
Name tau1_: NSS!$C$252
Name tau1_: '[1]Nelson Siegel Model'!$B$19
Name tau2_: '[2]Nelson Siegel Svensson Model'!$C$41
Name tau2_: NSS!$C$253
Name tau2_: '[2]Nelson Siegel Svensson Model'!$C$41
Name tau2_: #REF!

Sheet Bloomberg (Online)
A1: Instrument | B1: Name | C1: Ticker | D1: Country/Region | E1: Currency | F1: Maturity | G1: Coupon Type | H1: Coupon Frequency | I1: Coupon | J1: Ask Yield to Maturity | K1: Bid Yield to Maturity | L1: Ask Price | M1: Bid Price | N1: Identifier | O1: ISIN | P1: Bloomberg Composite Rating | Q1: Announce | R1: Next Coupon Settle Date | S1: Time
A2: YL396238 Corp | B2: {=_xll.BDP("YL396238 Corp","DS520")} -> #NAME? | C2: {=_xll.BDP("YL396238 Corp","DS001")} -> #NAME? | D2: {=_xll.BDP("YL396238 Corp","DS458")} -> #NAME? | E2: {=_xll.BDP("YL396238 Corp","DS004")} -> #NAME? | F2: {=_xll.BDP("YL396238 Corp","DS035")} -> #NAME? | G2: {=_xll.BDP(A2,"DS086")} -> #NAME? | H2: {=_xll.BDP(A2,"DS034")} -> #NAME? | I2: {=_xll.BDP("YL396238 Corp","DS033")} -> #NAME? | J2: {=_xll.BDP(A2,"YL018")} -> #NAME? | K2: {=_xll.BDP("YL396238 Corp","YL016")} -> #NAME? | L2: {=_xll.BDP("YL396238 Corp","PR004")} -> #NAME? | M2: {=_xll.BDP(A2,"PR002")} -> #NAME? | N2: {=_xll.BDP(A2,"ID028")} -> #NAME? | O2: {=_xll.BDP("YL396238 Corp","ID005")} -> #NAME? | P2: {=_xll.BDP("YL396238 Corp","RA007")} -> #NAME? | Q2: {=_xll.BDP("YL396238 Corp","DS219")} -> #NAME? | R2: {=_xll.BDP(A2,"DS040")} -> #NAME? | S2: =(F2-TODAY())/365.25 -> #NAME? | T2: {=_xll.BDP(C2,"HS022")} -> #NAME?
A3: ZI885852 Corp | B3: {=_xll.BDP("ZI885852 Corp","DS520")} -> #NAME? | C3: {=_xll.BDP("ZI885852 Corp","DS001")} -> #NAME? | D3: {=_xll.BDP("ZI885852 Corp","DS458")} -> #NAME? | E3: {=_xll.BDP("ZI885852 Corp","DS004")} -> #NAME? | F3: {=_xll.BDP("ZI885852 Corp","DS035")} -> #NAME? | G3: {=_xll.BDP(A3,"DS086")} -> #NAME? | H3: {=_xll.BDP(A3,"DS034")} -> #NAME? | I3: {=_xll.BDP("ZI885852 Corp","DS033")} -> #NAME? | J3: {=_xll.BDP(A3,"YL018")} -> #NAME? | K3: {=_xll.BDP("ZI885852 Corp","YL016")} -> #NAME? | L3: {=_xll.BDP("ZI885852 Corp","PR004")} -> #NAME? | M3: {=_xll.BDP(A3,"PR002")} -> #NAME? | N3: {=_xll.BDP(A3,"ID028")} -> #NAME? | O3: {=_xll.BDP("ZI885852 Corp","ID005")} -> #NAME? | P3: {=_xll.BDP("ZI885852 Corp","RA007")} -> #NAME? | Q3: {=_xll.BDP("ZI885852 Corp","DS219")} -> #NAME? | R3: {=_xll.BDP(A3,"DS040")} -> #NAME? | S3: =(F3-TODAY())/365.25 -> #NAME?
A4: LW169500 Corp | B4: {=_xll.BDP("LW169500 Corp","DS520")} -> #NAME? | C4: {=_xll.BDP("LW169500 Corp","DS001")} -> #NAME? | D4: {=_xll.BDP("LW169500 Corp","DS458")} -> #NAME? | E4: {=_xll.BDP("LW169500 Corp","DS004")} -> #NAME? | F4: {=_xll.BDP("LW169500 Corp","DS035")} -> #NAME? | G4: {=_xll.BDP(A4,"DS086")} -> #NAME? | H4: {=_xll.BDP(A4,"DS034")} -> #NAME? | I4: {=_xll.BDP("LW169500 Corp","DS033")} -> #NAME? | J4: {=_xll.BDP(A4,"YL018")} -> #NAME? | K4: {=_xll.BDP("LW169500 Corp","YL016")} -> #NAME? | L4: {=_xll.BDP("LW169500 Corp","PR004")} -> #NAME? | M4: {=_xll.BDP(A4,"PR002")} -> #NAME? | N4: {=_xll.BDP(A4,"ID028")} -> #NAME? | O4: {=_xll.BDP("LW169500 Corp","ID005")} -> #NAME? | P4: {=_xll.BDP("LW169500 Corp","RA007")} -> #NAME? | Q4: {=_xll.BDP("LW169500 Corp","DS219")} -> #NAME? | R4: {=_xll.BDP(A4,"DS040")} -> #NAME? | S4: =(F4-TODAY())/365.25 -> #NAME?
A5: AN666227 Corp | B5: {=_xll.BDP("AN666227 Corp","DS520")} -> #NAME? | C5: {=_xll.BDP("AN666227 Corp","DS001")} -> #NAME? | D5: {=_xll.BDP("AN666227 Corp","DS458")} -> #NAME? | E5: {=_xll.BDP("AN666227 Corp","DS004")} -> #NAME? | F5: {=_xll.BDP("AN666227 Corp","DS035")} -> #NAME? | G5: {=_xll.BDP(A5,"DS086")} -> #NAME? | H5: {=_xll.BDP(A5,"DS034")} -> #NAME? | I5: {=_xll.BDP("AN666227 Corp","DS033")} -> #NAME? | J5: {=_xll.BDP(A5,"YL018")} -> #NAME? | K5: {=_xll.BDP("AN666227 Corp","YL016")} -> #NAME? | L5: {=_xll.BDP("AN666227 Corp","PR004")} -> #NAME? | M5: {=_xll.BDP(A5,"PR002")} -> #NAME? | N5: {=_xll.BDP(A5,"ID028")} -> #NAME? | O5: {=_xll.BDP("AN666227 Corp","ID005")} -> #NAME? | P5: {=_xll.BDP("AN666227 Corp","RA007")} -> #NAME? | Q5: {=_xll.BDP("AN666227 Corp","DS219")} -> #NAME? | R5: {=_xll.BDP(A5,"DS040")} -> #NAME? | S5: =(F5-TODAY())/365.25 -> #NAME?
A6: BO356983 Corp | B6: {=_xll.BDP("BO356983 Corp","DS520")} -> #NAME? | C6: {=_xll.BDP("BO356983 Corp","DS001")} -> #NAME? | D6: {=_xll.BDP("BO356983 Corp","DS458")} -> #NAME? | E6: {=_xll.BDP("BO356983 Corp","DS004")} -> #NAME? | F6: {=_xll.BDP("BO356983 Corp","DS035")} -> #NAME? | G6: {=_xll.BDP(A6,"DS086")} -> #NAME? | H6: {=_xll.BDP(A6,"DS034")} -> #NAME? | I6: {=_xll.BDP("BO356983 Corp","DS033")} -> #NAME? | J6: {=_xll.BDP(A6,"YL018")} -> #NAME? | K6: {=_xll.BDP("BO356983 Corp","YL016")} -> #NAME? | L6: {=_xll.BDP("BO356983 Corp","PR004")} -> #NAME? | M6: {=_xll.BDP(A6,"PR002")} -> #NAME? | N6: {=_xll.BDP(A6,"ID028")} -> #NAME? | O6: {=_xll.BDP("BO356983 Corp","ID005")} -> #NAME? | P6: {=_xll.BDP("BO356983 Corp","RA007")} -> #NAME? | Q6: {=_xll.BDP("BO356983 Corp","DS219")} -> #NAME? | R6: {=_xll.BDP(A6,"DS040")} -> #NAME? | S6: =(F6-TODAY())/365.25 -> #NAME?
A7: BO356985 Corp | B7: {=_xll.BDP("BO356985 Corp","DS520")} -> #NAME? | C7: {=_xll.BDP("BO356985 Corp","DS001")} -> #NAME? | D7: {=_xll.BDP("BO356985 Corp","DS458")} -> #NAME? | E7: {=_xll.BDP("BO356985 Corp","DS004")} -> #NAME? | F7: {=_xll.BDP("BO356985 Corp","DS035")} -> #NAME? | G7: {=_xll.BDP(A7,"DS086")} -> #NAME? | H7: {=_xll.BDP(A7,"DS034")} -> #NAME? | I7: {=_xll.BDP("BO356985 Corp","DS033")} -> #NAME? | J7: {=_xll.BDP(A7,"YL018")} -> #NAME? | K7: {=_xll.BDP("BO356985 Corp","YL016")} -> #NAME? | L7: {=_xll.BDP("BO356985 Corp","PR004")} -> #NAME? | M7: {=_xll.BDP(A7,"PR002")} -> #NAME? | N7: {=_xll.BDP(A7,"ID028")} -> #NAME? | O7: {=_xll.BDP("BO356985 Corp","ID005")} -> #NAME? | P7: {=_xll.BDP("BO356985 Corp","RA007")} -> #NAME? | Q7: {=_xll.BDP("BO356985 Corp","DS219")} -> #NAME? | R7: {=_xll.BDP(A7,"DS040")} -> #NAME? | S7: =(F7-TODAY())/365.25 -> #NAME?
A8: BO356982 Corp | B8: {=_xll.BDP("BO356982 Corp","DS520")} -> #NAME? | C8: {=_xll.BDP("BO356982 Corp","DS001")} -> #NAME? | D8: {=_xll.BDP("BO356982 Corp","DS458")} -> #NAME? | E8: {=_xll.BDP("BO356982 Corp","DS004")} -> #NAME? | F8: {=_xll.BDP("BO356982 Corp","DS035")} -> #NAME? | G8: {=_xll.BDP(A8,"DS086")} -> #NAME? | H8: {=_xll.BDP(A8,"DS034")} -> #NAME? | I8: {=_xll.BDP("BO356982 Corp","DS033")} -> #NAME? | J8: {=_xll.BDP(A8,"YL018")} -> #NAME? | K8: {=_xll.BDP("BO356982 Corp","YL016")} -> #NAME? | L8: {=_xll.BDP("BO356982 Corp","PR004")} -> #NAME? | M8: {=_xll.BDP(A8,"PR002")} -> #NAME? | N8: {=_xll.BDP(A8,"ID028")} -> #NAME? | O8: {=_xll.BDP("BO356982 Corp","ID005")} -> #NAME? | P8: {=_xll.BDP("BO356982 Corp","RA007")} -> #NAME? | Q8: {=_xll.BDP("BO356982 Corp","DS219")} -> #NAME? | R8: {=_xll.BDP(A8,"DS040")} -> #NAME? | S8: =(F8-TODAY())/365.25 -> #NAME?
A9: DA928584 Corp | B9: {=_xll.BDP("DA928584 Corp","DS520")} -> #NAME? | C9: {=_xll.BDP("DA928584 Corp","DS001")} -> #NAME? | D9: {=_xll.BDP("DA928584 Corp","DS458")} -> #NAME? | E9: {=_xll.BDP("DA928584 Corp","DS004")} -> #NAME? | F9: {=_xll.BDP("DA928584 Corp","DS035")} -> #NAME? | G9: {=_xll.BDP(A9,"DS086")} -> #NAME? | H9: {=_xll.BDP(A9,"DS034")} -> #NAME? | I9: {=_xll.BDP("DA928584 Corp","DS033")} -> #NAME? | J9: {=_xll.BDP(A9,"YL018")} -> #NAME? | K9: {=_xll.BDP("DA928584 Corp","YL016")} -> #NAME? | L9: {=_xll.BDP("DA928584 Corp","PR004")} -> #NAME? | M9: {=_xll.BDP(A9,"PR002")} -> #NAME? | N9: {=_xll.BDP(A9,"ID028")} -> #NAME? | O9: {=_xll.BDP("DA928584 Corp","ID005")} -> #NAME? | P9: {=_xll.BDP("DA928584 Corp","RA007")} -> #NAME? | Q9: {=_xll.BDP("DA928584 Corp","DS219")} -> #NAME? | R9: {=_xll.BDP(A9,"DS040")} -> #NAME? | S9: =(F9-TODAY())/365.25 -> #NAME?
A10: YL396232 Corp | B10: {=_xll.BDP("YL396232 Corp","DS520")} -> #NAME? | C10: {=_xll.BDP("YL396232 Corp","DS001")} -> #NAME? | D10: {=_xll.BDP("YL396232 Corp","DS458")} -> #NAME? | E10: {=_xll.BDP("YL396232 Corp","DS004")} -> #NAME? | F10: {=_xll.BDP("YL396232 Corp","DS035")} -> #NAME? | G10: {=_xll.BDP(A10,"DS086")} -> #NAME? | H10: {=_xll.BDP(A10,"DS034")} -> #NAME? | I10: {=_xll.BDP("YL396232 Corp","DS033")} -> #NAME? | J10: {=_xll.BDP(A10,"YL018")} -> #NAME? | K10: {=_xll.BDP("YL396232 Corp","YL016")} -> #NAME? | L10: {=_xll.BDP("YL396232 Corp","PR004")} -> #NAME? | M10: {=_xll.BDP(A10,"PR002")} -> #NAME? | N10: {=_xll.BDP(A10,"ID028")} -> #NAME? | O10: {=_xll.BDP("YL396232 Corp","ID005")} -> #NAME? | P10: {=_xll.BDP("YL396232 Corp","RA007")} -> #NAME? | Q10: {=_xll.BDP("YL396232 Corp","DS219")} -> #NAME? | R10: {=_xll.BDP(A10,"DS040")} -> #NAME? | S10: =(F10-TODAY())/365.25 -> #NAME?
A11: YK173563 Corp | B11: {=_xll.BDP("YK173563 Corp","DS520")} -> #NAME? | C11: {=_xll.BDP("YK173563 Corp","DS001")} -> #NAME? | D11: {=_xll.BDP("YK173563 Corp","DS458")} -> #NAME? | E11: {=_xll.BDP("YK173563 Corp","DS004")} -> #NAME? | F11: {=_xll.BDP("YK173563 Corp","DS035")} -> #NAME? | G11: {=_xll.BDP(A11,"DS086")} -> #NAME? | H11: {=_xll.BDP(A11,"DS034")} -> #NAME? | I11: {=_xll.BDP("YK173563 Corp","DS033")} -> #NAME? | J11: {=_xll.BDP(A11,"YL018")} -> #NAME? | K11: {=_xll.BDP("YK173563 Corp","YL016")} -> #NAME? | L11: {=_xll.BDP("YK173563 Corp","PR004")} -> #NAME? | M11: {=_xll.BDP(A11,"PR002")} -> #NAME? | N11: {=_xll.BDP(A11,"ID028")} -> #NAME? | O11: {=_xll.BDP("YK173563 Corp","ID005")} -> #NAME? | P11: {=_xll.BDP("YK173563 Corp","RA007")} -> #NAME? | Q11: {=_xll.BDP("YK173563 Corp","DS219")} -> #NAME? | R11: {=_xll.BDP(A11,"DS040")} -> #NAME? | S11: =(F11-TODAY())/365.25 -> #NAME?
A12: YN599739 Corp | B12: {=_xll.BDP("YN599739 Corp","DS520")} -> #NAME? | C12: {=_xll.BDP("YN599739 Corp","DS001")} -> #NAME? | D12: {=_xll.BDP("YN599739 Corp","DS458")} -> #NAME? | E12: {=_xll.BDP("YN599739 Corp","DS004")} -> #NAME? | F12: {=_xll.BDP("YN599739 Corp","DS035")} -> #NAME? | G12: {=_xll.BDP(A12,"DS086")} -> #NAME? | H12: {=_xll.BDP(A12,"DS034")} -> #NAME? | I12: {=_xll.BDP("YN599739 Corp","DS033")} -> #NAME? | J12: {=_xll.BDP(A12,"YL018")} -> #NAME? | K12: {=_xll.BDP("YN599739 Corp","YL016")} -> #NAME? | L12: {=_xll.BDP("YN599739 Corp","PR004")} -> #NAME? | M12: {=_xll.BDP(A12,"PR002")} -> #NAME? | N12: {=_xll.BDP(A12,"ID028")} -> #NAME? | O12: {=_xll.BDP("YN599739 Corp","ID005")} -> #NAME? | P12: {=_xll.BDP("YN599739 Corp","RA007")} -> #NAME? | Q12: {=_xll.BDP("YN599739 Corp","DS219")} -> #NAME? | R12: {=_xll.BDP(A12,"DS040")} -> #NAME? | S12: =(F12-TODAY())/365.25 -> #NAME?
A13: YN599935 Corp | B13: {=_xll.BDP("YN599935 Corp","DS520")} -> #NAME? | C13: {=_xll.BDP("YN599935 Corp","DS001")} -> #NAME? | D13: {=_xll.BDP("YN599935 Corp","DS458")} -> #NAME? | E13: {=_xll.BDP("YN599935 Corp","DS004")} -> #NAME? | F13: {=_xll.BDP("YN599935 Corp","DS035")} -> #NAME? | G13: {=_xll.BDP(A13,"DS086")} -> #NAME? | H13: {=_xll.BDP(A13,"DS034")} -> #NAME? | I13: {=_xll.BDP("YN599935 Corp","DS033")} -> #NAME? | J13: {=_xll.BDP(A13,"YL018")} -> #NAME? | K13: {=_xll.BDP("YN599935 Corp","YL016")} -> #NAME? | L13: {=_xll.BDP("YN599935 Corp","PR004")} -> #NAME? | M13: {=_xll.BDP(A13,"PR002")} -> #NAME? | N13: {=_xll.BDP(A13,"ID028")} -> #NAME? | O13: {=_xll.BDP("YN599935 Corp","ID005")} -> #NAME? | P13: {=_xll.BDP("YN599935 Corp","RA007")} -> #NAME? | Q13: {=_xll.BDP("YN599935 Corp","DS219")} -> #NAME? | R13: {=_xll.BDP(A13,"DS040")} -> #NAME? | S13: =(F13-TODAY())/365.25 -> #NAME?
A14: YN600126 Corp | B14: {=_xll.BDP("YN600126 Corp","DS520")} -> #NAME? | C14: {=_xll.BDP("YN600126 Corp","DS001")} -> #NAME? | D14: {=_xll.BDP("YN600126 Corp","DS458")} -> #NAME? | E14: {=_xll.BDP("YN600126 Corp","DS004")} -> #NAME? | F14: {=_xll.BDP("YN600126 Corp","DS035")} -> #NAME? | G14: {=_xll.BDP(A14,"DS086")} -> #NAME? | H14: {=_xll.BDP(A14,"DS034")} -> #NAME? | I14: {=_xll.BDP("YN600126 Corp","DS033")} -> #NAME? | J14: {=_xll.BDP(A14,"YL018")} -> #NAME? | K14: {=_xll.BDP("YN600126 Corp","YL016")} -> #NAME? | L14: {=_xll.BDP("YN600126 Corp","PR004")} -> #NAME? | M14: {=_xll.BDP(A14,"PR002")} -> #NAME? | N14: {=_xll.BDP(A14,"ID028")} -> #NAME? | O14: {=_xll.BDP("YN600126 Corp","ID005")} -> #NAME? | P14: {=_xll.BDP("YN600126 Corp","RA007")} -> #NAME? | Q14: {=_xll.BDP("YN600126 Corp","DS219")} -> #NAME? | R14: {=_xll.BDP(A14,"DS040")} -> #NAME? | S14: =(F14-TODAY())/365.25 -> #NAME?
A15: ZD637375 Corp | B15: {=_xll.BDP("ZD637375 Corp","DS520")} -> #NAME? | C15: {=_xll.BDP("ZD637375 Corp","DS001")} -> #NAME? | D15: {=_xll.BDP("ZD637375 Corp","DS458")} -> #NAME? | E15: {=_xll.BDP("ZD637375 Corp","DS004")} -> #NAME? | F15: {=_xll.BDP("ZD637375 Corp","DS035")} -> #NAME? | G15: {=_xll.BDP(A15,"DS086")} -> #NAME? | H15: {=_xll.BDP(A15,"DS034")} -> #NAME? | I15: {=_xll.BDP("ZD637375 Corp","DS033")} -> #NAME? | J15: {=_xll.BDP(A15,"YL018")} -> #NAME? | K15: {=_xll.BDP("ZD637375 Corp","YL016")} -> #NAME? | L15: {=_xll.BDP("ZD637375 Corp","PR004")} -> #NAME? | M15: {=_xll.BDP(A15,"PR002")} -> #NAME? | N15: {=_xll.BDP(A15,"ID028")} -> #NAME? | O15: {=_xll.BDP("ZD637375 Corp","ID005")} -> #NAME? | P15: {=_xll.BDP("ZD637375 Corp","RA007")} -> #NAME? | Q15: {=_xll.BDP("ZD637375 Corp","DS219")} -> #NAME? | R15: {=_xll.BDP(A15,"DS040")} -> #NAME? | S15: =(F15-TODAY())/365.25 -> #NAME?
A16: AN666209 Corp | B16: {=_xll.BDP("AN666209 Corp","DS520")} -> #NAME? | C16: {=_xll.BDP("AN666209 Corp","DS001")} -> #NAME? | D16: {=_xll.BDP("AN666209 Corp","DS458")} -> #NAME? | E16: {=_xll.BDP("AN666209 Corp","DS004")} -> #NAME? | F16: {=_xll.BDP("AN666209 Corp","DS035")} -> #NAME? | G16: {=_xll.BDP(A16,"DS086")} -> #NAME? | H16: {=_xll.BDP(A16,"DS034")} -> #NAME? | I16: {=_xll.BDP("AN666209 Corp","DS033")} -> #NAME? | J16: {=_xll.BDP(A16,"YL018")} -> #NAME? | K16: {=_xll.BDP("AN666209 Corp","YL016")} -> #NAME? | L16: {=_xll.BDP("AN666209 Corp","PR004")} -> #NAME? | M16: {=_xll.BDP(A16,"PR002")} -> #NAME? | N16: {=_xll.BDP(A16,"ID028")} -> #NAME? | O16: {=_xll.BDP("AN666209 Corp","ID005")} -> #NAME? | P16: {=_xll.BDP("AN666209 Corp","RA007")} -> #NAME? | Q16: {=_xll.BDP("AN666209 Corp","DS219")} -> #NAME? | R16: {=_xll.BDP(A16,"DS040")} -> #NAME? | S16: =(F16-TODAY())/365.25 -> #NAME?
A17: YS631917 Corp | B17: {=_xll.BDP("YS631917 Corp","DS520")} -> #NAME? | C17: {=_xll.BDP("YS631917 Corp","DS001")} -> #NAME? | D17: {=_xll.BDP("YS631917 Corp","DS458")} -> #NAME? | E17: {=_xll.BDP("YS631917 Corp","DS004")} -> #NAME? | F17: {=_xll.BDP("YS631917 Corp","DS035")} -> #NAME? | G17: {=_xll.BDP(A17,"DS086")} -> #NAME? | H17: {=_xll.BDP(A17,"DS034")} -> #NAME? | I17: {=_xll.BDP("YS631917 Corp","DS033")} -> #NAME? | J17: {=_xll.BDP(A17,"YL018")} -> #NAME? | K17: {=_xll.BDP("YS631917 Corp","YL016")} -> #NAME? | L17: {=_xll.BDP("YS631917 Corp","PR004")} -> #NAME? | M17: {=_xll.BDP(A17,"PR002")} -> #NAME? | N17: {=_xll.BDP(A17,"ID028")} -> #NAME? | O17: {=_xll.BDP("YS631917 Corp","ID005")} -> #NAME? | P17: {=_xll.BDP("YS631917 Corp","RA007")} -> #NAME? | Q17: {=_xll.BDP("YS631917 Corp","DS219")} -> #NAME? | R17: {=_xll.BDP(A17,"DS040")} -> #NAME? | S17: =(F17-TODAY())/365.25 -> #NAME?
A18: BW601183 Corp | B18: {=_xll.BDP("BW601183 Corp","DS520")} -> #NAME? | C18: {=_xll.BDP("BW601183 Corp","DS001")} -> #NAME? | D18: {=_xll.BDP("BW601183 Corp","DS458")} -> #NAME? | E18: {=_xll.BDP("BW601183 Corp","DS004")} -> #NAME? | F18: {=_xll.BDP("BW601183 Corp","DS035")} -> #NAME? | G18: {=_xll.BDP(A18,"DS086")} -> #NAME? | H18: {=_xll.BDP(A18,"DS034")} -> #NAME? | I18: {=_xll.BDP("BW601183 Corp","DS033")} -> #NAME? | J18: {=_xll.BDP(A18,"YL018")} -> #NAME? | K18: {=_xll.BDP("BW601183 Corp","YL016")} -> #NAME? | L18: {=_xll.BDP("BW601183 Corp","PR004")} -> #NAME? | M18: {=_xll.BDP(A18,"PR002")} -> #NAME? | N18: {=_xll.BDP(A18,"ID028")} -> #NAME? | O18: {=_xll.BDP("BW601183 Corp","ID005")} -> #NAME? | P18: {=_xll.BDP("BW601183 Corp","RA007")} -> #NAME? | Q18: {=_xll.BDP("BW601183 Corp","DS219")} -> #NAME? | R18: {=_xll.BDP(A18,"DS040")} -> #NAME? | S18: =(F18-TODAY())/365.25 -> #NAME?
A19: YT821868 Corp | B19: {=_xll.BDP("YT821868 Corp","DS520")} -> #NAME? | C19: {=_xll.BDP("YT821868 Corp","DS001")} -> #NAME? | D19: {=_xll.BDP("YT821868 Corp","DS458")} -> #NAME? | E19: {=_xll.BDP("YT821868 Corp","DS004")} -> #NAME? | F19: {=_xll.BDP("YT821868 Corp","DS035")} -> #NAME? | G19: {=_xll.BDP(A19,"DS086")} -> #NAME? | H19: {=_xll.BDP(A19,"DS034")} -> #NAME? | I19: {=_xll.BDP("YT821868 Corp","DS033")} -> #NAME? | J19: {=_xll.BDP(A19,"YL018")} -> #NAME? | K19: {=_xll.BDP("YT821868 Corp","YL016")} -> #NAME? | L19: {=_xll.BDP("YT821868 Corp","PR004")} -> #NAME? | M19: {=_xll.BDP(A19,"PR002")} -> #NAME? | N19: {=_xll.BDP(A19,"ID028")} -> #NAME? | O19: {=_xll.BDP("YT821868 Corp","ID005")} -> #NAME? | P19: {=_xll.BDP("YT821868 Corp","RA007")} -> #NAME? | Q19: {=_xll.BDP("YT821868 Corp","DS219")} -> #NAME? | R19: {=_xll.BDP(A19,"DS040")} -> #NAME? | S19: =(F19-TODAY())/365.25 -> #NAME?
A20: YT968038 Corp | B20: {=_xll.BDP("YT968038 Corp","DS520")} -> #NAME? | C20: {=_xll.BDP("YT968038 Corp","DS001")} -> #NAME? | D20: {=_xll.BDP("YT968038 Corp","DS458")} -> #NAME? | E20: {=_xll.BDP("YT968038 Corp","DS004")} -> #NAME? | F20: {=_xll.BDP("YT968038 Corp","DS035")} -> #NAME? | G20: {=_xll.BDP(A20,"DS086")} -> #NAME? | H20: {=_xll.BDP(A20,"DS034")} -> #NAME? | I20: {=_xll.BDP("YT968038 Corp","DS033")} -> #NAME? | J20: {=_xll.BDP(A20,"YL018")} -> #NAME? | K20: {=_xll.BDP("YT968038 Corp","YL016")} -> #NAME? | L20: {=_xll.BDP("YT968038 Corp","PR004")} -> #NAME? | M20: {=_xll.BDP(A20,"PR002")} -> #NAME? | N20: {=_xll.BDP(A20,"ID028")} -> #NAME? | O20: {=_xll.BDP("YT968038 Corp","ID005")} -> #NAME? | P20: {=_xll.BDP("YT968038 Corp","RA007")} -> #NAME? | Q20: {=_xll.BDP("YT968038 Corp","DS219")} -> #NAME? | R20: {=_xll.BDP(A20,"DS040")} -> #NAME? | S20: =(F20-TODAY())/365.25 -> #NAME?
A21: AP577034 Corp | B21: {=_xll.BDP("AP577034 Corp","DS520")} -> #NAME? | C21: {=_xll.BDP("AP577034 Corp","DS001")} -> #NAME? | D21: {=_xll.BDP("AP577034 Corp","DS458")} -> #NAME? | E21: {=_xll.BDP("AP577034 Corp","DS004")} -> #NAME? | F21: {=_xll.BDP("AP577034 Corp","DS035")} -> #NAME? | G21: {=_xll.BDP(A21,"DS086")} -> #NAME? | H21: {=_xll.BDP(A21,"DS034")} -> #NAME? | I21: {=_xll.BDP("AP577034 Corp","DS033")} -> #NAME? | J21: {=_xll.BDP(A21,"YL018")} -> #NAME? | K21: {=_xll.BDP("AP577034 Corp","YL016")} -> #NAME? | L21: {=_xll.BDP("AP577034 Corp","PR004")} -> #NAME? | M21: {=_xll.BDP(A21,"PR002")} -> #NAME? | N21: {=_xll.BDP(A21,"ID028")} -> #NAME? | O21: {=_xll.BDP("AP577034 Corp","ID005")} -> #NAME? | P21: {=_xll.BDP("AP577034 Corp","RA007")} -> #NAME? | Q21: {=_xll.BDP("AP577034 Corp","DS219")} -> #NAME? | R21: {=_xll.BDP(A21,"DS040")} -> #NAME? | S21: =(F21-TODAY())/365.25 -> #NAME?
A22: LW169503 Corp | B22: {=_xll.BDP("LW169503 Corp","DS520")} -> #NAME? | C22: {=_xll.BDP("LW169503 Corp","DS001")} -> #NAME? | D22: {=_xll.BDP("LW169503 Corp","DS458")} -> #NAME? | E22: {=_xll.BDP("LW169503 Corp","DS004")} -> #NAME? | F22: {=_xll.BDP("LW169503 Corp","DS035")} -> #NAME? | G22: {=_xll.BDP(A22,"DS086")} -> #NAME? | H22: {=_xll.BDP(A22,"DS034")} -> #NAME? | I22: {=_xll.BDP("LW169503 Corp","DS033")} -> #NAME? | J22: {=_xll.BDP(A22,"YL018")} -> #NAME? | K22: {=_xll.BDP("LW169503 Corp","YL016")} -> #NAME? | L22: {=_xll.BDP("LW169503 Corp","PR004")} -> #NAME? | M22: {=_xll.BDP(A22,"PR002")} -> #NAME? | N22: {=_xll.BDP(A22,"ID028")} -> #NAME? | O22: {=_xll.BDP("LW169503 Corp","ID005")} -> #NAME? | P22: {=_xll.BDP("LW169503 Corp","RA007")} -> #NAME? | Q22: {=_xll.BDP("LW169503 Corp","DS219")} -> #NAME? | R22: {=_xll.BDP(A22,"DS040")} -> #NAME? | S22: =(F22-TODAY())/365.25 -> #NAME?
A23: YK943560 Corp | B23: {=_xll.BDP("YK943560 Corp","DS520")} -> #NAME? | C23: {=_xll.BDP("YK943560 Corp","DS001")} -> #NAME? | D23: {=_xll.BDP("YK943560 Corp","DS458")} -> #NAME? | E23: {=_xll.BDP("YK943560 Corp","DS004")} -> #NAME? | F23: {=_xll.BDP("YK943560 Corp","DS035")} -> #NAME? | G23: {=_xll.BDP(A23,"DS086")} -> #NAME? | H23: {=_xll.BDP(A23,"DS034")} -> #NAME? | I23: {=_xll.BDP("YK943560 Corp","DS033")} -> #NAME? | J23: {=_xll.BDP(A23,"YL018")} -> #NAME? | K23: {=_xll.BDP("YK943560 Corp","YL016")} -> #NAME? | L23: {=_xll.BDP("YK943560 Corp","PR004")} -> #NAME? | M23: {=_xll.BDP(A23,"PR002")} -> #NAME? | N23: {=_xll.BDP(A23,"ID028")} -> #NAME? | O23: {=_xll.BDP("YK943560 Corp","ID005")} -> #NAME? | P23: {=_xll.BDP("YK943560 Corp","RA007")} -> #NAME? | Q23: {=_xll.BDP("YK943560 Corp","DS219")} -> #NAME? | R23: {=_xll.BDP(A23,"DS040")} -> #NAME? | S23: =(F23-TODAY())/365.25 -> #NAME?
A24: YT967931 Corp | B24: {=_xll.BDP("YT967931 Corp","DS520")} -> #NAME? | C24: {=_xll.BDP("YT967931 Corp","DS001")} -> #NAME? | D24: {=_xll.BDP("YT967931 Corp","DS458")} -> #NAME? | E24: {=_xll.BDP("YT967931 Corp","DS004")} -> #NAME? | F24: {=_xll.BDP("YT967931 Corp","DS035")} -> #NAME? | G24: {=_xll.BDP(A24,"DS086")} -> #NAME? | H24: {=_xll.BDP(A24,"DS034")} -> #NAME? | I24: {=_xll.BDP("YT967931 Corp","DS033")} -> #NAME? | J24: {=_xll.BDP(A24,"YL018")} -> #NAME? | K24: {=_xll.BDP("YT967931 Corp","YL016")} -> #NAME? | L24: {=_xll.BDP("YT967931 Corp","PR004")} -> #NAME? | M24: {=_xll.BDP(A24,"PR002")} -> #NAME? | N24: {=_xll.BDP(A24,"ID028")} -> #NAME? | O24: {=_xll.BDP("YT967931 Corp","ID005")} -> #NAME? | P24: {=_xll.BDP("YT967931 Corp","RA007")} -> #NAME? | Q24: {=_xll.BDP("YT967931 Corp","DS219")} -> #NAME? | R24: {=_xll.BDP(A24,"DS040")} -> #NAME? | S24: =(F24-TODAY())/365.25 -> #NAME?
A25: YV792963 Corp | B25: {=_xll.BDP("YV792963 Corp","DS520")} -> #NAME? | C25: {=_xll.BDP("YV792963 Corp","DS001")} -> #NAME? | D25: {=_xll.BDP("YV792963 Corp","DS458")} -> #NAME? | E25: {=_xll.BDP("YV792963 Corp","DS004")} -> #NAME? | F25: {=_xll.BDP("YV792963 Corp","DS035")} -> #NAME? | G25: {=_xll.BDP(A25,"DS086")} -> #NAME? | H25: {=_xll.BDP(A25,"DS034")} -> #NAME? | I25: {=_xll.BDP("YV792963 Corp","DS033")} -> #NAME? | J25: {=_xll.BDP(A25,"YL018")} -> #NAME? | K25: {=_xll.BDP("YV792963 Corp","YL016")} -> #NAME? | L25: {=_xll.BDP("YV792963 Corp","PR004")} -> #NAME? | M25: {=_xll.BDP(A25,"PR002")} -> #NAME? | N25: {=_xll.BDP(A25,"ID028")} -> #NAME? | O25: {=_xll.BDP("YV792963 Corp","ID005")} -> #NAME? | P25: {=_xll.BDP("YV792963 Corp","RA007")} -> #NAME? | Q25: {=_xll.BDP("YV792963 Corp","DS219")} -> #NAME? | R25: {=_xll.BDP(A25,"DS040")} -> #NAME? | S25: =(F25-TODAY())/365.25 -> #NAME?
A26: YV793180 Corp | B26: {=_xll.BDP("YV793180 Corp","DS520")} -> #NAME? | C26: {=_xll.BDP("YV793180 Corp","DS001")} -> #NAME? | D26: {=_xll.BDP("YV793180 Corp","DS458")} -> #NAME? | E26: {=_xll.BDP("YV793180 Corp","DS004")} -> #NAME? | F26: {=_xll.BDP("YV793180 Corp","DS035")} -> #NAME? | G26: {=_xll.BDP(A26,"DS086")} -> #NAME? | H26: {=_xll.BDP(A26,"DS034")} -> #NAME? | I26: {=_xll.BDP("YV793180 Corp","DS033")} -> #NAME? | J26: {=_xll.BDP(A26,"YL018")} -> #NAME? | K26: {=_xll.BDP("YV793180 Corp","YL016")} -> #NAME? | L26: {=_xll.BDP("YV793180 Corp","PR004")} -> #NAME? | M26: {=_xll.BDP(A26,"PR002")} -> #NAME? | N26: {=_xll.BDP(A26,"ID028")} -> #NAME? | O26: {=_xll.BDP("YV793180 Corp","ID005")} -> #NAME? | P26: {=_xll.BDP("YV793180 Corp","RA007")} -> #NAME? | Q26: {=_xll.BDP("YV793180 Corp","DS219")} -> #NAME? | R26: {=_xll.BDP(A26,"DS040")} -> #NAME? | S26: =(F26-TODAY())/365.25 -> #NAME?
A27: ZD637368 Corp | B27: {=_xll.BDP("ZD637368 Corp","DS520")} -> #NAME? | C27: {=_xll.BDP("ZD637368 Corp","DS001")} -> #NAME? | D27: {=_xll.BDP("ZD637368 Corp","DS458")} -> #NAME? | E27: {=_xll.BDP("ZD637368 Corp","DS004")} -> #NAME? | F27: {=_xll.BDP("ZD637368 Corp","DS035")} -> #NAME? | G27: {=_xll.BDP(A27,"DS086")} -> #NAME? | H27: {=_xll.BDP(A27,"DS034")} -> #NAME? | I27: {=_xll.BDP("ZD637368 Corp","DS033")} -> #NAME? | J27: {=_xll.BDP(A27,"YL018")} -> #NAME? | K27: {=_xll.BDP("ZD637368 Corp","YL016")} -> #NAME? | L27: {=_xll.BDP("ZD637368 Corp","PR004")} -> #NAME? | M27: {=_xll.BDP(A27,"PR002")} -> #NAME? | N27: {=_xll.BDP(A27,"ID028")} -> #NAME? | O27: {=_xll.BDP("ZD637368 Corp","ID005")} -> #NAME? | P27: {=_xll.BDP("ZD637368 Corp","RA007")} -> #NAME? | Q27: {=_xll.BDP("ZD637368 Corp","DS219")} -> #NAME? | R27: {=_xll.BDP(A27,"DS040")} -> #NAME? | S27: =(F27-TODAY())/365.25 -> #NAME?
A28: ZK701516 Corp | B28: {=_xll.BDP("ZK701516 Corp","DS520")} -> #NAME? | C28: {=_xll.BDP("ZK701516 Corp","DS001")} -> #NAME? | D28: {=_xll.BDP("ZK701516 Corp","DS458")} -> #NAME? | E28: {=_xll.BDP("ZK701516 Corp","DS004")} -> #NAME? | F28: {=_xll.BDP("ZK701516 Corp","DS035")} -> #NAME? | G28: {=_xll.BDP(A28,"DS086")} -> #NAME? | H28: {=_xll.BDP(A28,"DS034")} -> #NAME? | I28: {=_xll.BDP("ZK701516 Corp","DS033")} -> #NAME? | J28: {=_xll.BDP(A28,"YL018")} -> #NAME? | K28: {=_xll.BDP("ZK701516 Corp","YL016")} -> #NAME? | L28: {=_xll.BDP("ZK701516 Corp","PR004")} -> #NAME? | M28: {=_xll.BDP(A28,"PR002")} -> #NAME? | N28: {=_xll.BDP(A28,"ID028")} -> #NAME? | O28: {=_xll.BDP("ZK701516 Corp","ID005")} -> #NAME? | P28: {=_xll.BDP("ZK701516 Corp","RA007")} -> #NAME? | Q28: {=_xll.BDP("ZK701516 Corp","DS219")} -> #NAME? | R28: {=_xll.BDP(A28,"DS040")} -> #NAME? | S28: =(F28-TODAY())/365.25 -> #NAME?
A29: ZK701649 Corp | B29: {=_xll.BDP("ZK701649 Corp","DS520")} -> #NAME? | C29: {=_xll.BDP("ZK701649 Corp","DS001")} -> #NAME? | D29: {=_xll.BDP("ZK701649 Corp","DS458")} -> #NAME? | E29: {=_xll.BDP("ZK701649 Corp","DS004")} -> #NAME? | F29: {=_xll.BDP("ZK701649 Corp","DS035")} -> #NAME? | G29: {=_xll.BDP(A29,"DS086")} -> #NAME? | H29: {=_xll.BDP(A29,"DS034")} -> #NAME? | I29: {=_xll.BDP("ZK701649 Corp","DS033")} -> #NAME? | J29: {=_xll.BDP(A29,"YL018")} -> #NAME? | K29: {=_xll.BDP("ZK701649 Corp","YL016")} -> #NAME? | L29: {=_xll.BDP("ZK701649 Corp","PR004")} -> #NAME? | M29: {=_xll.BDP(A29,"PR002")} -> #NAME? | N29: {=_xll.BDP(A29,"ID028")} -> #NAME? | O29: {=_xll.BDP("ZK701649 Corp","ID005")} -> #NAME? | P29: {=_xll.BDP("ZK701649 Corp","RA007")} -> #NAME? | Q29: {=_xll.BDP("ZK701649 Corp","DS219")} -> #NAME? | R29: {=_xll.BDP(A29,"DS040")} -> #NAME? | S29: =(F29-TODAY())/365.25 -> #NAME?
A30: AO295977 Corp | B30: {=_xll.BDP("AO295977 Corp","DS520")} -> #NAME? | C30: {=_xll.BDP("AO295977 Corp","DS001")} -> #NAME? | D30: {=_xll.BDP("AO295977 Corp","DS458")} -> #NAME? | E30: {=_xll.BDP("AO295977 Corp","DS004")} -> #NAME? | F30: {=_xll.BDP("AO295977 Corp","DS035")} -> #NAME? | G30: {=_xll.BDP(A30,"DS086")} -> #NAME? | H30: {=_xll.BDP(A30,"DS034")} -> #NAME? | I30: {=_xll.BDP("AO295977 Corp","DS033")} -> #NAME? | J30: {=_xll.BDP(A30,"YL018")} -> #NAME? | K30: {=_xll.BDP("AO295977 Corp","YL016")} -> #NAME? | L30: {=_xll.BDP("AO295977 Corp","PR004")} -> #NAME? | M30: {=_xll.BDP(A30,"PR002")} -> #NAME? | N30: {=_xll.BDP(A30,"ID028")} -> #NAME? | O30: {=_xll.BDP("AO295977 Corp","ID005")} -> #NAME? | P30: {=_xll.BDP("AO295977 Corp","RA007")} -> #NAME? | Q30: {=_xll.BDP("AO295977 Corp","DS219")} -> #NAME? | R30: {=_xll.BDP(A30,"DS040")} -> #NAME? | S30: =(F30-TODAY())/365.25 -> #NAME?
A31: AU925890 Corp | B31: {=_xll.BDP("AU925890 Corp","DS520")} -> #NAME? | C31: {=_xll.BDP("AU925890 Corp","DS001")} -> #NAME? | D31: {=_xll.BDP("AU925890 Corp","DS458")} -> #NAME? | E31: {=_xll.BDP("AU925890 Corp","DS004")} -> #NAME? | F31: {=_xll.BDP("AU925890 Corp","DS035")} -> #NAME? | G31: {=_xll.BDP(A31,"DS086")} -> #NAME? | H31: {=_xll.BDP(A31,"DS034")} -> #NAME? | I31: {=_xll.BDP("AU925890 Corp","DS033")} -> #NAME? | J31: {=_xll.BDP(A31,"YL018")} -> #NAME? | K31: {=_xll.BDP("AU925890 Corp","YL016")} -> #NAME? | L31: {=_xll.BDP("AU925890 Corp","PR004")} -> #NAME? | M31: {=_xll.BDP(A31,"PR002")} -> #NAME? | N31: {=_xll.BDP(A31,"ID028")} -> #NAME? | O31: {=_xll.BDP("AU925890 Corp","ID005")} -> #NAME? | P31: {=_xll.BDP("AU925890 Corp","RA007")} -> #NAME? | Q31: {=_xll.BDP("AU925890 Corp","DS219")} -> #NAME? | R31: {=_xll.BDP(A31,"DS040")} -> #NAME? | S31: =(F31-TODAY())/365.25 -> #NAME?
A32: BO579315 Corp | B32: {=_xll.BDP("BO579315 Corp","DS520")} -> #NAME? | C32: {=_xll.BDP("BO579315 Corp","DS001")} -> #NAME? | D32: {=_xll.BDP("BO579315 Corp","DS458")} -> #NAME? | E32: {=_xll.BDP("BO579315 Corp","DS004")} -> #NAME? | F32: {=_xll.BDP("BO579315 Corp","DS035")} -> #NAME? | G32: {=_xll.BDP(A32,"DS086")} -> #NAME? | H32: {=_xll.BDP(A32,"DS034")} -> #NAME? | I32: {=_xll.BDP("BO579315 Corp","DS033")} -> #NAME? | J32: {=_xll.BDP(A32,"YL018")} -> #NAME? | K32: {=_xll.BDP("BO579315 Corp","YL016")} -> #NAME? | L32: {=_xll.BDP("BO579315 Corp","PR004")} -> #NAME? | M32: {=_xll.BDP(A32,"PR002")} -> #NAME? | N32: {=_xll.BDP(A32,"ID028")} -> #NAME? | O32: {=_xll.BDP("BO579315 Corp","ID005")} -> #NAME? | P32: {=_xll.BDP("BO579315 Corp","RA007")} -> #NAME? | Q32: {=_xll.BDP("BO579315 Corp","DS219")} -> #NAME? | R32: {=_xll.BDP(A32,"DS040")} -> #NAME? | S32: =(F32-TODAY())/365.25 -> #NAME?
A33: BW601098 Corp | B33: {=_xll.BDP("BW601098 Corp","DS520")} -> #NAME? | C33: {=_xll.BDP("BW601098 Corp","DS001")} -> #NAME? | D33: {=_xll.BDP("BW601098 Corp","DS458")} -> #NAME? | E33: {=_xll.BDP("BW601098 Corp","DS004")} -> #NAME? | F33: {=_xll.BDP("BW601098 Corp","DS035")} -> #NAME? | G33: {=_xll.BDP(A33,"DS086")} -> #NAME? | H33: {=_xll.BDP(A33,"DS034")} -> #NAME? | I33: {=_xll.BDP("BW601098 Corp","DS033")} -> #NAME? | J33: {=_xll.BDP(A33,"YL018")} -> #NAME? | K33: {=_xll.BDP("BW601098 Corp","YL016")} -> #NAME? | L33: {=_xll.BDP("BW601098 Corp","PR004")} -> #NAME? | M33: {=_xll.BDP(A33,"PR002")} -> #NAME? | N33: {=_xll.BDP(A33,"ID028")} -> #NAME? | O33: {=_xll.BDP("BW601098 Corp","ID005")} -> #NAME? | P33: {=_xll.BDP("BW601098 Corp","RA007")} -> #NAME? | Q33: {=_xll.BDP("BW601098 Corp","DS219")} -> #NAME? | R33: {=_xll.BDP(A33,"DS040")} -> #NAME? | S33: =(F33-TODAY())/365.25 -> #NAME?
A34: YK173548 Corp | B34: {=_xll.BDP("YK173548 Corp","DS520")} -> #NAME? | C34: {=_xll.BDP("YK173548 Corp","DS001")} -> #NAME? | D34: {=_xll.BDP("YK173548 Corp","DS458")} -> #NAME? | E34: {=_xll.BDP("YK173548 Corp","DS004")} -> #NAME? | F34: {=_xll.BDP("YK173548 Corp","DS035")} -> #NAME? | G34: {=_xll.BDP(A34,"DS086")} -> #NAME? | H34: {=_xll.BDP(A34,"DS034")} -> #NAME? | I34: {=_xll.BDP("YK173548 Corp","DS033")} -> #NAME? | J34: {=_xll.BDP(A34,"YL018")} -> #NAME? | K34: {=_xll.BDP("YK173548 Corp","YL016")} -> #NAME? | L34: {=_xll.BDP("YK173548 Corp","PR004")} -> #NAME? | M34: {=_xll.BDP(A34,"PR002")} -> #NAME? | N34: {=_xll.BDP(A34,"ID028")} -> #NAME? | O34: {=_xll.BDP("YK173548 Corp","ID005")} -> #NAME? | P34: {=_xll.BDP("YK173548 Corp","RA007")} -> #NAME? | Q34: {=_xll.BDP("YK173548 Corp","DS219")} -> #NAME? | R34: {=_xll.BDP(A34,"DS040")} -> #NAME? | S34: =(F34-TODAY())/365.25 -> #NAME?
A35: ZI885869 Corp | B35: {=_xll.BDP("ZI885869 Corp","DS520")} -> #NAME? | C35: {=_xll.BDP("ZI885869 Corp","DS001")} -> #NAME? | D35: {=_xll.BDP("ZI885869 Corp","DS458")} -> #NAME? | E35: {=_xll.BDP("ZI885869 Corp","DS004")} -> #NAME? | F35: {=_xll.BDP("ZI885869 Corp","DS035")} -> #NAME? | G35: {=_xll.BDP(A35,"DS086")} -> #NAME? | H35: {=_xll.BDP(A35,"DS034")} -> #NAME? | I35: {=_xll.BDP("ZI885869 Corp","DS033")} -> #NAME? | J35: {=_xll.BDP(A35,"YL018")} -> #NAME? | K35: {=_xll.BDP("ZI885869 Corp","YL016")} -> #NAME? | L35: {=_xll.BDP("ZI885869 Corp","PR004")} -> #NAME? | M35: {=_xll.BDP(A35,"PR002")} -> #NAME? | N35: {=_xll.BDP(A35,"ID028")} -> #NAME? | O35: {=_xll.BDP("ZI885869 Corp","ID005")} -> #NAME? | P35: {=_xll.BDP("ZI885869 Corp","RA007")} -> #NAME? | Q35: {=_xll.BDP("ZI885869 Corp","DS219")} -> #NAME? | R35: {=_xll.BDP(A35,"DS040")} -> #NAME? | S35: =(F35-TODAY())/365.25 -> #NAME?
A36: ZS613802 Corp | B36: {=_xll.BDP("ZS613802 Corp","DS520")} -> #NAME? | C36: {=_xll.BDP("ZS613802 Corp","DS001")} -> #NAME? | D36: {=_xll.BDP("ZS613802 Corp","DS458")} -> #NAME? | E36: {=_xll.BDP("ZS613802 Corp","DS004")} -> #NAME? | F36: {=_xll.BDP("ZS613802 Corp","DS035")} -> #NAME? | G36: {=_xll.BDP(A36,"DS086")} -> #NAME? | H36: {=_xll.BDP(A36,"DS034")} -> #NAME? | I36: {=_xll.BDP("ZS613802 Corp","DS033")} -> #NAME? | J36: {=_xll.BDP(A36,"YL018")} -> #NAME? | K36: {=_xll.BDP("ZS613802 Corp","YL016")} -> #NAME? | L36: {=_xll.BDP("ZS613802 Corp","PR004")} -> #NAME? | M36: {=_xll.BDP(A36,"PR002")} -> #NAME? | N36: {=_xll.BDP(A36,"ID028")} -> #NAME? | O36: {=_xll.BDP("ZS613802 Corp","ID005")} -> #NAME? | P36: {=_xll.BDP("ZS613802 Corp","RA007")} -> #NAME? | Q36: {=_xll.BDP("ZS613802 Corp","DS219")} -> #NAME? | R36: {=_xll.BDP(A36,"DS040")} -> #NAME? | S36: =(F36-TODAY())/365.25 -> #NAME?
A37: BZ742454 Corp | B37: {=_xll.BDP("BZ742454 Corp","DS520")} -> #NAME? | C37: {=_xll.BDP("BZ742454 Corp","DS001")} -> #NAME? | D37: {=_xll.BDP("BZ742454 Corp","DS458")} -> #NAME? | E37: {=_xll.BDP("BZ742454 Corp","DS004")} -> #NAME? | F37: {=_xll.BDP("BZ742454 Corp","DS035")} -> #NAME? | G37: {=_xll.BDP(A37,"DS086")} -> #NAME? | H37: {=_xll.BDP(A37,"DS034")} -> #NAME? | I37: {=_xll.BDP("BZ742454 Corp","DS033")} -> #NAME? | J37: {=_xll.BDP(A37,"YL018")} -> #NAME? | K37: {=_xll.BDP("BZ742454 Corp","YL016")} -> #NAME? | L37: {=_xll.BDP("BZ742454 Corp","PR004")} -> #NAME? | M37: {=_xll.BDP(A37,"PR002")} -> #NAME? | N37: {=_xll.BDP(A37,"ID028")} -> #NAME? | O37: {=_xll.BDP("BZ742454 Corp","ID005")} -> #NAME? | P37: {=_xll.BDP("BZ742454 Corp","RA007")} -> #NAME? | Q37: {=_xll.BDP("BZ742454 Corp","DS219")} -> #NAME? | R37: {=_xll.BDP(A37,"DS040")} -> #NAME? | S37: =(F37-TODAY())/365.25 -> #NAME?
A38: YK172992 Corp | B38: {=_xll.BDP("YK172992 Corp","DS520")} -> #NAME? | C38: {=_xll.BDP("YK172992 Corp","DS001")} -> #NAME? | D38: {=_xll.BDP("YK172992 Corp","DS458")} -> #NAME? | E38: {=_xll.BDP("YK172992 Corp","DS004")} -> #NAME? | F38: {=_xll.BDP("YK172992 Corp","DS035")} -> #NAME? | G38: {=_xll.BDP(A38,"DS086")} -> #NAME? | H38: {=_xll.BDP(A38,"DS034")} -> #NAME? | I38: {=_xll.BDP("YK172992 Corp","DS033")} -> #NAME? | J38: {=_xll.BDP(A38,"YL018")} -> #NAME? | K38: {=_xll.BDP("YK172992 Corp","YL016")} -> #NAME? | L38: {=_xll.BDP("YK172992 Corp","PR004")} -> #NAME? | M38: {=_xll.BDP(A38,"PR002")} -> #NAME? | N38: {=_xll.BDP(A38,"ID028")} -> #NAME? | O38: {=_xll.BDP("YK172992 Corp","ID005")} -> #NAME? | P38: {=_xll.BDP("YK172992 Corp","RA007")} -> #NAME? | Q38: {=_xll.BDP("YK172992 Corp","DS219")} -> #NAME? | R38: {=_xll.BDP(A38,"DS040")} -> #NAME? | S38: =(F38-TODAY())/365.25 -> #NAME?

Sheet Offline
A1: Instrument | B1: Name | C1: Ticker | D1: Country/Region | E1: Currency | F1: Maturity | G1: Coupon Type | H1: Coupon Frequency | I1: Coupon | J1: Ask Yield to Maturity | K1: Bid Yield to Maturity | L1: Ask Price | M1: Bid Price | N1: Identifier | O1: ISIN | P1: Bloomberg Composite Rating | Q1: Announce | R1: Next Coupon Settle Date | S1: Time | T1: AVG Price | U1: ID | V1: TIMEish | W1: years ago | X1: Accrued Interest | Y1: Clean price | Z1: AVG yield
A2: YL396238 Corp | B2: Toyota Motor Corp | C2: TOYOTA | D2: JP | E2: JPY | F2: 04/09/2035 | G2: FIXED | H2: 2 | I2: 1.793 | J2: 2.507 | K2: 2.507 | L2: 94.531 | M2: 94.531 | N2: YL3962385 | O2: JP363340AR99 | P2: A+ | Q2: 29/08/2025 | R2: 04/09/2026 | S2: =(F2-TODAY())/365.25 -> 9.431896 | T2: =+AVERAGE(L2:M2) -> 94.531 | U2: {=_xlfn.SEQUENCE(COUNT(H:H))} -> 1 | V2: =ROUNDDOWN(S2,0)+IF(S2-ROUNDDOWN(S2,0)>0.5,0.5,0) -> 9 | W2: =YEAR(TODAY())-YEAR(Q2) -> 1 | X2: =(TODAY()-DATE(YEAR(R2),MONTH(R2)-6,DAY(R2)))/182*(I2) -> 0.25614286 | Y2: =T2-X2 -> 94.274857 | Z2: =AVERAGE(J2:K2) -> 2.507
A3: ZI885852 Corp | B3: Toyota Finance Corp | C3: TOYOTA | D3: JP | E3: JPY | F3: 13/10/2026 | G3: FIXED | H3: 2 | I3: 0.37 | J3: 1.163 | K3: 1.163 | L3: 99.538 | M3: 99.538 | N3: ZI8858527 | O3: JP363360APA1 | P3: A+ | Q3: 06/10/2023 | R3: 13/04/2026 | S3: =(F3-TODAY())/365.25 -> 0.53935661 | T3: =+AVERAGE(L3:M3) -> 99.538 | U3: 2 | V3: =ROUNDDOWN(S3,0)+IF(S3-ROUNDDOWN(S3,0)>0.5,0.5,0) -> 0.5 | W3: =YEAR(TODAY())-YEAR(Q3) -> 3 | X3: =(TODAY()-DATE(YEAR(R3),MONTH(R3)-6,DAY(R3)))/182*(I3) -> 0.34153846 | Y3: =T3-X3 -> 99.196462 | Z3: =AVERAGE(J3:K3) -> 1.163
A4: LW169500 Corp | B4: Toyota Motor Corp | C4: TOYOTA | D4: JP | E4: JPY | F4: 03/06/2026 | G4: FIXED | H4: 2 | I4: 0.09 | J4: 0.864 | K4: 1.134 | L4: 99.826 | M4: 99.766 | N4: LW1695003 | O4: JP363340AG68 | P4: A+ | Q4: 27/05/2016 | R4: 03/06/2026 | S4: =(F4-TODAY())/365.25 -> 0.1779603 | T4: =+AVERAGE(L4:M4) -> 99.796 | U4: 3 | V4: =ROUNDDOWN(S4,0)+IF(S4-ROUNDDOWN(S4,0)>0.5,0.5,0) -> 0 | W4: =YEAR(TODAY())-YEAR(Q4) -> 10 | X4: =(TODAY()-DATE(YEAR(R4),MONTH(R4)-6,DAY(R4)))/182*(I4) -> 0.057857143 | Y4: =T4-X4 -> 99.738143 | Z4: =AVERAGE(J4:K4) -> 0.999
A5: AN666227 Corp | B5: Toyota Motor Corp | C5: TOYOTA | D5: JP | E5: JPY | F5: 02/06/2037 | G5: FIXED | H5: 2 | I5: 0.651 | J5: 2.962 | K5: 2.962 | L5: 80.535 | M5: 80.535 | N5: AN6662273 | O5: JP363340DH64 | P5: A+ | Q5: 26/05/2017 | R5: 02/06/2026 | S5: =(F5-TODAY())/365.25 -> 11.175907 | T5: =+AVERAGE(L5:M5) -> 80.535 | U5: 4 | V5: =ROUNDDOWN(S5,0)+IF(S5-ROUNDDOWN(S5,0)>0.5,0.5,0) -> 11 | W5: =YEAR(TODAY())-YEAR(Q5) -> 9 | X5: =(TODAY()-DATE(YEAR(R5),MONTH(R5)-6,DAY(R5)))/182*(I5) -> 0.42207692 | Y5: =T5-X5 -> 80.112923 | Z5: =AVERAGE(J5:K5) -> 2.962
A6: BO356983 Corp | B6: Toyota Motor Corp | C6: TOYOTA | D6: JP | E6: JPY | F6: 18/03/2031 | G6: FIXED | H6: 2 | I6: 0.219 | J6: 1.982 | K6: 1.982 | L6: 91.959 | M6: 91.959 | N6: BO3569833 | O6: JP363340CM35 | P6: A+ | Q6: 12/03/2021 | R6: 18/03/2026 | S6: =(F6-TODAY())/365.25 -> 4.9664613 | T6: =+AVERAGE(L6:M6) -> 91.959 | U6: 5 | V6: =ROUNDDOWN(S6,0)+IF(S6-ROUNDDOWN(S6,0)>0.5,0.5,0) -> 4.5 | W6: =YEAR(TODAY())-YEAR(Q6) -> 5 | X6: =(TODAY()-DATE(YEAR(R6),MONTH(R6)-6,DAY(R6)))/182*(I6) -> 0.23223626 | Y6: =T6-X6 -> 91.726764 | Z6: =AVERAGE(J6:K6) -> 1.982
A7: BO356985 Corp | B7: Toyota Motor Corp | C7: TOYOTA | D7: JP | E7: JPY | F7: 27/03/2026 | G7: FIXED | H7: 2 | I7: 0.1 | J7: 1.173 | K7: 1.176 | L7: 99.958 | M7: 99.958 | N7: BO3569858 | O7: JP363340AM37 | P7: #N/A N/A | Q7: 12/03/2021 | R7: 27/03/2026 | S7: =(F7-TODAY())/365.25 -> -0.0082135524 | T7: =+AVERAGE(L7:M7) -> 99.958 | U7: 6 | V7: =ROUNDDOWN(S7,0)+IF(S7-ROUNDDOWN(S7,0)>0.5,0.5,0) -> 0 | W7: =YEAR(TODAY())-YEAR(Q7) -> 5 | X7: =(TODAY()-DATE(YEAR(R7),MONTH(R7)-6,DAY(R7)))/182*(I7) -> 0.1010989 | Y7: =T7-X7 -> 99.856901 | Z7: =AVERAGE(J7:K7) -> 1.1745
A8: BO356982 Corp | B8: Toyota Motor Corp | C8: TOYOTA | D8: JP | E8: JPY | F8: 18/03/2026 | G8: FIXED | H8: 2 | I8: 0.05 | J8: 1.477 | K8: 1.483 | L8: 99.98 | M8: 99.98 | N8: BO3569825 | O8: JP363340BM36 | P8: A+ | Q8: 12/03/2021 | R8: 18/03/2026 | S8: =(F8-TODAY())/365.25 -> -0.032854209 | T8: =+AVERAGE(L8:M8) -> 99.98 | U8: 7 | V8: =ROUNDDOWN(S8,0)+IF(S8-ROUNDDOWN(S8,0)>0.5,0.5,0) -> 0 | W8: =YEAR(TODAY())-YEAR(Q8) -> 5 | X8: =(TODAY()-DATE(YEAR(R8),MONTH(R8)-6,DAY(R8)))/182*(I8) -> 0.053021978 | Y8: =T8-X8 -> 99.926978 | Z8: =AVERAGE(J8:K8) -> 1.48
A9: DA928584 Corp | B9: Toyota Finance Corp | C9: TOYOTA | D9: JP | E9: JPY | F9: 01/12/2028 | G9: FIXED | H9: 2 | I9: 1.35 | J9: 1.407 | K9: 1.607 | L9: 99.849 | M9: 99.328 | N9: DA9285846 | O9: JP363360ARQ3 | P9: #N/A N/A | Q9: 27/11/2025 | R9: 03/06/2026 | S9: =(F9-TODAY())/365.25 -> 2.6748802 | T9: =+AVERAGE(L9:M9) -> 99.5885 | U9: 8 | V9: =ROUNDDOWN(S9,0)+IF(S9-ROUNDDOWN(S9,0)>0.5,0.5,0) -> 2.5 | W9: =YEAR(TODAY())-YEAR(Q9) -> 1 | X9: =(TODAY()-DATE(YEAR(R9),MONTH(R9)-6,DAY(R9)))/182*(I9) -> 0.86785714 | Y9: =T9-X9 -> 98.720643 | Z9: =AVERAGE(J9:K9) -> 1.507
A10: YL396232 Corp | B10: Toyota Motor Corp | C10: TOYOTA | D10: JP | E10: JPY | F10: 04/09/2030 | G10: FIXED | H10: 2 | I10: 1.296 | J10: 1.838 | K10: 1.838 | L10: 97.756 | M10: 97.756 | N10: YL3962328 | O10: JP363340BR98 | P10: A+ | Q10: 29/08/2025 | R10: 04/09/2026 | S10: =(F10-TODAY())/365.25 -> 4.4325804 | T10: =+AVERAGE(L10:M10) -> 97.756 | U10: 9 | V10: =ROUNDDOWN(S10,0)+IF(S10-ROUNDDOWN(S10,0)>0.5,0.5,0) -> 4 | W10: =YEAR(TODAY())-YEAR(Q10) -> 1 | X10: =(TODAY()-DATE(YEAR(R10),MONTH(R10)-6,DAY(R10)))/182*(I10) -> 0.18514286 | Y10: =T10-X10 -> 97.570857 | Z10: =AVERAGE(J10:K10) -> 1.838
A11: YK173563 Corp | B11: Toyota Finance Corp | C11: TOYOTA | D11: JP | E11: JPY | F11: 17/10/2030 | G11: FIXED | H11: 2 | I11: 1.493 | J11: 1.888 | K11: 1.888 | L11: 98.329 | M11: 98.329 | N11: YK1735637 | O11: JP363360ARA7 | P11: A+ | Q11: 10/10/2025 | R11: 17/04/2026 | S11: =(F11-TODAY())/365.25 -> 4.550308 | T11: =+AVERAGE(L11:M11) -> 98.329 | U11: 10 | V11: =ROUNDDOWN(S11,0)+IF(S11-ROUNDDOWN(S11,0)>0.5,0.5,0) -> 4.5 | W11: =YEAR(TODAY())-YEAR(Q11) -> 1 | X11: =(TODAY()-DATE(YEAR(R11),MONTH(R11)-6,DAY(R11)))/182*(I11) -> 1.3453407 | Y11: =T11-X11 -> 96.983659 | Z11: =AVERAGE(J11:K11) -> 1.888
A12: YN599739 Corp | B12: Toyota Finance Corp | C12: TOYOTA | D12: JP | E12: JPY | F12: 22/07/2027 | G12: FIXED | H12: 2 | I12: 0.966 | J12: 1.34 | K12: 1.354 | L12: 99.5 | M12: 99.482 | N12: YN5997393 | O12: JP363360AR78 | P12: A+ | Q12: 15/07/2025 | R12: 22/07/2026 | S12: =(F12-TODAY())/365.25 -> 1.3114305 | T12: =+AVERAGE(L12:M12) -> 99.491 | U12: 11 | V12: =ROUNDDOWN(S12,0)+IF(S12-ROUNDDOWN(S12,0)>0.5,0.5,0) -> 1 | W12: =YEAR(TODAY())-YEAR(Q12) -> 1 | X12: =(TODAY()-DATE(YEAR(R12),MONTH(R12)-6,DAY(R12)))/182*(I12) -> 0.35561538 | Y12: =T12-X12 -> 99.135385 | Z12: =AVERAGE(J12:K12) -> 1.347
A13: YN599935 Corp | B13: Toyota Finance Corp | C13: TOYOTA | D13: JP | E13: JPY | F13: 21/07/2028 | G13: FIXED | H13: 2 | I13: 1.082 | J13: 1.468 | K13: 1.521 | L13: 99.12 | M13: 98.999 | N13: YN5999357 | O13: JP363360BR77 | P13: A+ | Q13: 15/07/2025 | R13: 22/07/2026 | S13: =(F13-TODAY())/365.25 -> 2.3107461 | T13: =+AVERAGE(L13:M13) -> 99.0595 | U13: 12 | V13: =ROUNDDOWN(S13,0)+IF(S13-ROUNDDOWN(S13,0)>0.5,0.5,0) -> 2 | W13: =YEAR(TODAY())-YEAR(Q13) -> 1 | X13: =(TODAY()-DATE(YEAR(R13),MONTH(R13)-6,DAY(R13)))/182*(I13) -> 0.39831868 | Y13: =T13-X13 -> 98.661181 | Z13: =AVERAGE(J13:K13) -> 1.4945
A14: YN600126 Corp | B14: Toyota Finance Corp | C14: TOYOTA | D14: JP | E14: JPY | F14: 22/07/2030 | G14: FIXED | H14: 2 | I14: 1.326 | J14: 1.821 | K14: 1.85 | L14: 98.001 | M14: 97.886 | N14: YN6001260 | O14: JP363360CR76 | P14: A+ | Q14: 15/07/2025 | R14: 22/07/2026 | S14: =(F14-TODAY())/365.25 -> 4.312115 | T14: =+AVERAGE(L14:M14) -> 97.9435 | U14: 13 | V14: =ROUNDDOWN(S14,0)+IF(S14-ROUNDDOWN(S14,0)>0.5,0.5,0) -> 4 | W14: =YEAR(TODAY())-YEAR(Q14) -> 1 | X14: =(TODAY()-DATE(YEAR(R14),MONTH(R14)-6,DAY(R14)))/182*(I14) -> 0.48814286 | Y14: =T14-X14 -> 97.455357 | Z14: =AVERAGE(J14:K14) -> 1.8355
... A38: YK172992 Corp | B38: Toyota Finance Corp | C38: TOYOTA | D38: JP | E38: JPY | F38: 15/10/2027 | G38: FIXED | H38: 2 | I38: 1.089 | J38: 1.396 | K38: 1.411 | L38: 99.521 | M38: 99.498 | N38: YK1729929 | O38: JP363360CRA3 | P38: A+ | Q38: 10/10/2025 | R38: 17/04/2026 | S38: =(F38-TODAY())/365.25 -> 1.5441478 | T38: =+AVERAGE(L38:M38) -> 99.5095 | U38: 37 | V38: =ROUNDDOWN(S38,0)+IF(S38-ROUNDDOWN(S38,0)>0.5,0.5,0) -> 1.5 | W38: =YEAR(TODAY())-YEAR(Q38) -> 1 | X38: =(TODAY()-DATE(YEAR(R38),MONTH(R38)-6,DAY(R38)))/182*(I38) -> 0.9812967 | Y38: =T38-X38 -> 98.528203 | Z38: =AVERAGE(J38:K38) -> 1.4035

Sheet SORT
A1: {=+OFFSET(Offline!A1,,,1,COUNTA(Offline!1:1))} -> Instrument | B1: Name | C1: Ticker | D1: Country/Region | E1: Currency | F1: Maturity | G1: Coupon Type | H1: Coupon Frequency | I1: Coupon | J1: Ask Yield to Maturity | K1: Bid Yield to Maturity | L1: Ask Price | M1: Bid Price | N1: Identifier | O1: ISIN | P1: Bloomberg Composite Rating | Q1: Announce | R1: Next Coupon Settle Date | S1: Time | T1: AVG Price | U1: ID | V1: TIMEish | W1: years ago | X1: Accrued Interest | Y1: Clean price | Z1: AVG yield
A2: {=_xlfn._xlws.SORT(OFFSET(Offline!A2,,,COUNTA(Offline!A:A)-1,COUNTA(Offline!1:1)),COLUMN(Offline!S1))} -> BO356982 Corp | B2: Toyota Motor Corp | C2: TOYOTA | D2: JP | E2: JPY | F2: 18/03/2026 | G2: FIXED | H2: 2 | I2: 0.05 | J2: 1.477 | K2: 1.483 | L2: 99.98 | M2: 99.98 | N2: BO3569825 | O2: JP363340BM36 | P2: A+ | Q2: 12/03/2021 | R2: 18/03/2026 | S2: -0.032854209 | T2: 99.98 | U2: 7 | V2: 0 | W2: 5 | X2: 0.053021978 | Y2: 99.926978 | Z2: 1.48
A3: BO356985 Corp | B3: Toyota Motor Corp | C3: TOYOTA | D3: JP | E3: JPY | F3: 27/03/2026 | G3: FIXED | H3: 2 | I3: 0.1 | J3: 1.173 | K3: 1.176 | L3: 99.958 | M3: 99.958 | N3: BO3569858 | O3: JP363340AM37 | P3: #N/A N/A | Q3: 12/03/2021 | R3: 27/03/2026 | S3: -0.0082135524 | T3: 99.958 | U3: 6 | V3: 0 | W3: 5 | X3: 0.1010989 | Y3: 99.856901 | Z3: 1.1745
A4: BO579315 Corp | B4: Toyota Finance Corp | C4: TOYOTA | D4: JP | E4: JPY | F4: 15/04/2026 | G4: FIXED | H4: 2 | I4: 0.06 | J4: 1.099 | K4: 1.1 | L4: 99.906 | M4: 99.906 | N4: BO5793159 | O4: JP363360BM49 | P4: A+ | Q4: 09/04/2021 | R4: 15/04/2026 | S4: 0.043805613 | T4: 99.906 | U4: 31 | V4: 0 | W4: 5 | X4: 0.054725275 | Y4: 99.851275 | Z4: 1.0995
A5: LW169500 Corp | B5: Toyota Motor Corp | C5: TOYOTA | D5: JP | E5: JPY | F5: 03/06/2026 | G5: FIXED | H5: 2 | I5: 0.09 | J5: 0.864 | K5: 1.134 | L5: 99.826 | M5: 99.766 | N5: LW1695003 | O5: JP363340AG68 | P5: A+ | Q5: 27/05/2016 | R5: 03/06/2026 | S5: 0.1779603 | T5: 99.796 | U5: 3 | V5: 0 | W5: 10 | X5: 0.057857143 | Y5: 99.738143 | Z5: 0.999
A6: ZI885852 Corp | B6: Toyota Finance Corp | C6: TOYOTA | D6: JP | E6: JPY | F6: 13/10/2026 | G6: FIXED | H6: 2 | I6: 0.37 | J6: 1.163 | K6: 1.163 | L6: 99.538 | M6: 99.538 | N6: ZI8858527 | O6: JP363360APA1 | P6: A+ | Q6: 06/10/2023 | R6: 13/04/2026 | S6: 0.53935661 | T6: 99.538 | U6: 2 | V6: 0.5 | W6: 3 | X6: 0.34153846 | Y6: 99.196462 | Z6: 1.163
A7: YT821868 Corp | B7: Toyota Finance Corp | C7: TOYOTA | D7: JP | E7: JPY | F7: 11/12/2026 | G7: FIXED | H7: 2 | I7: 0.773 | J7: 1.014 | K7: 1.214 | L7: 99.821 | M7: 99.673 | N7: YT8218687 | O7: JP363360AQQ5 | P7: #N/A N/A | Q7: 06/12/2024 | R7: 12/06/2026 | S7: 0.7008898 | T7: 99.747 | U7: 18 | V7: 0.5 | W7: 2 | X7: 0.4587033 | Y7: 99.288297 | Z7: 1.114
A8: ZD637368 Corp | B8: Toyota Finance Corp | C8: TOYOTA | D8: JP | E8: JPY | F8: 09/04/2027 | G8: FIXED | H8: 2 | I8: 0.414 | J8: 1.259 | K8: 1.281 | L8: 99.104 | M8: 99.081 | N8: ZD6373686 | O8: JP363360AQ46 | P8: A+ | Q8: 05/04/2024 | R8: 10/04/2026 | S8: 1.026694 | T8: 99.0925 | U8: 26 | V8: 1 | W8: 2 | X8: 0.38897802 | Y8: 98.703522 | Z8: 1.27
A9: AN666209 Corp | B9: Toyota Motor Corp | C9: TOYOTA | D9: JP | E9: JPY | F9: 02/06/2027 | G9: FIXED | H9: 2 | I9: 0.22 | J9: 1.274 | K9: 1.292 | L9: 98.73 | M9: 98.709 | N9: AN6662091 | O9: JP363340CH65 | P9: A+ | Q9: 26/05/2017 | R9: 02/06/2026 | S9: 1.174538 | T9: 98.7195 | U9: 15 | V9: 1 | W9: 9 | X9: 0.14263736 | Y9: 98.576863 | Z9: 1.283
A10: BW601098 Corp | B10: Toyota Motor Corp | C10: TOYOTA | D10: JP | E10: JPY | F10: 02/06/2027 | G10: FIXED | H10: 2 | I10: 0.11 | J10: 1.273 | K10: 1.291 | L10: 98.599 | M10: 98.578 | N10: BW6010985 | O10: JP363340AN69 | P10: A+ | Q10: 27/05/2022 | R10: 02/06/2026 | S10: 1.174538 | T10: 98.5885 | U10: 32 | V10: 1 | W10: 4 | X10: 0.071318681 | Y10: 98.517181 | Z10: 1.282
A11: YN599739 Corp | B11: Toyota Finance Corp | C11: TOYOTA | D11: JP | E11: JPY | F11: 22/07/2027 | G11: FIXED | H11: 2 | I11: 0.966 | J11: 1.34 | K11: 1.354 | L11: 99.5 | M11: 99.482 | N11: YN5997393 | O11: JP363360AR78 | P11: A+ | Q11: 15/07/2025 | R11: 22/07/2026 | S11: 1.3114305 | T11: 99.491 | U11: 11 | V11: 1 | W11: 1 | X11: 0.35561538 | Y11: 99.135385 | Z11: 1.347
A12: AO295977 Corp | B12: Toyota Finance Corp | C12: TOYOTA | D12: JP | E12: JPY | F12: 23/07/2027 | G12: FIXED | H12: 2 | I12: 0.265 | J12: 1.346 | K12: 1.36 | L12: 98.553 | M12: 98.534 | N12: AO2959770 | O12: JP363360CH78 | P12: A+ | Q12: 14/07/2017 | R12: 24/07/2026 | S12: 1.3141684 | T12: 98.5435 | U12: 29 | V12: 1 | W12: 9 | X12: 0.094642857 | Y12: 98.448857 | Z12: 1.353
A13: YV792963 Corp | B13: Toyota Finance Corp | C13: TOYOTA | D13: JP | E13: JPY | F13: 08/10/2027 | G13: FIXED | H13: 2 | I13: 0.573 | J13: 1.406 | K13: 1.421 | L13: 98.716 | M13: 98.694 | N13: YV7929636 | O13: JP363360AQA9 | P13: A+ | Q13: 04/10/2024 | R13: 10/04/2026 | S13: 1.5249829 | T13: 98.705 | U13: 24 | V13: 1.5 | W13: 2 | X13: 0.53836813 | Y13: 98.166632 | Z13: 1.4135
A14: YK172992 Corp | B14: Toyota Finance Corp | C14: TOYOTA | D14: JP | E14: JPY | F14: 15/10/2027 | G14: FIXED | H14: 2 | I14: 1.089 | J14: 1.396 | K14: 1.411 | L14: 99.521 | M14: 99.498 | N14: YK1729929 | O14: JP363360CRA3 | P14: A+ | Q14: 10/10/2025 | R14: 17/04/2026 | S14: 1.5441478 | T14: 99.5095 | U14: 37 | V14: 1.5 | W14: 1 | X14: 0.9812967 | Y14: 98.528203 | Z14: 1.4035
... A38: AN666227 Corp | B38: Toyota Motor Corp | C38: TOYOTA | D38: JP | E38: JPY | F38: 02/06/2037 | G38: FIXED | H38: 2 | I38: 0.651 | J38: 2.962 | K38: 2.962 | L38: 80.535 | M38: 80.535 | N38: AN6662273 | O38: JP363340DH64 | P38: A+ | Q38: 26/05/2017 | R38: 02/06/2026 | S38: 11.175907 | T38: 80.535 | U38: 4 | V38: 11 | W38: 9 | X38: 0.42207692 | Y38: 80.112923 | Z38: 2.962

Sheet ID filter
A1: ID | B1: {=_xlfn.ANCHORARRAY(SORT!A1)} -> Instrument | C1: Name | D1: Ticker | E1: Country/Region | F1: Currency | G1: Maturity | H1: Coupon Type | I1: Coupon Frequency | J1: Coupon | K1: Ask Yield to Maturity | L1: Bid Yield to Maturity | M1: Ask Price | N1: Bid Price | O1: Identifier | P1: ISIN | Q1: Bloomberg Composite Rating | R1: Announce | S1: Next Coupon Settle Date | T1: Time | U1: AVG Price | V1: ID | W1: TIMEish | X1: years ago | Y1: Accrued Interest | Z1: Clean price | AA1: AVG yield
A2: 3 | B2: {=_xlfn.XLOOKUP(A2,SORT!$U$2:$U$38,_xlfn.ANCHORARRAY(SORT!$A$2),,0)} -> LW169500 Corp | C2: Toyota Motor Corp | D2: TOYOTA | E2: JP | F2: JPY | G2: 03/06/2026 | H2: FIXED | I2: 2 | J2: 0.09 | K2: 0.864 | L2: 1.134 | M2: 99.826 | N2: 99.766 | O2: LW1695003 | P2: JP363340AG68 | Q2: A+ | R2: 27/05/2016 | S2: 03/06/2026 | T2: 0.1779603 | U2: 99.796 | V2: 3 | W2: 0 | X2: 10 | Y2: 0.057857143 | Z2: 99.738143 | AA2: 0.999
A3: 18 | B3: {=_xlfn.XLOOKUP(A3,SORT!$U$2:$U$38,_xlfn.ANCHORARRAY(SORT!$A$2),,0)} -> YT821868 Corp | C3: Toyota Finance Corp | D3: TOYOTA | E3: JP | F3: JPY | G3: 11/12/2026 | H3: FIXED | I3: 2 | J3: 0.773 | K3: 1.014 | L3: 1.214 | M3: 99.821 | N3: 99.673 | O3: YT8218687 | P3: JP363360AQQ5 | Q3: #N/A N/A | R3: 06/12/2024 | S3: 12/06/2026 | T3: 0.7008898 | U3: 99.747 | V3: 18 | W3: 0.5 | X3: 2 | Y3: 0.4587033 | Z3: 99.288297 | AA3: 1.114
A4: 29 | B4: {=_xlfn.XLOOKUP(A4,SORT!$U$2:$U$38,_xlfn.ANCHORARRAY(SORT!$A$2),,0)} -> AO295977 Corp | C4: Toyota Finance Corp | D4: TOYOTA | E4: JP | F4: JPY | G4: 23/07/2027 | H4: FIXED | I4: 2 | J4: 0.265 | K4: 1.346 | L4: 1.36 | M4: 98.553 | N4: 98.534 | O4: AO2959770 | P4: JP363360CH78 | Q4: A+ | R4: 14/07/2017 | S4: 24/07/2026 | T4: 1.3141684 | U4: 98.5435 | V4: 29 | W4: 1 | X4: 9 | Y4: 0.094642857 | Z4: 98.448857 | AA4: 1.353
A5: 23 | B5: {=_xlfn.XLOOKUP(A5,SORT!$U$2:$U$38,_xlfn.ANCHORARRAY(SORT!$A$2),,0)} -> YT967931 Corp | C5: Toyota Finance Corp | D5: TOYOTA | E5: JP | F5: JPY | G5: 21/01/2028 | H5: FIXED | I5: 2 | J5: 0.9 | K5: 1.452 | L5: 1.464 | M5: 99 | N5: 98.978 | O5: YT9679317 | P5: JP363360AR11 | Q5: A+ | R5: 17/01/2025 | S5: 23/07/2026 | T5: 1.8124572 | U5: 98.989 | V5: 23 | W5: 1.5 | X5: 1 | Y5: 0.32637363 | Z5: 98.662626 | AA5: 1.458
A6: 12 | B6: {=_xlfn.XLOOKUP(A6,SORT!$U$2:$U$38,_xlfn.ANCHORARRAY(SORT!$A$2),,0)} -> YN599935 Corp | C6: Toyota Finance Corp | D6: TOYOTA | E6: JP | F6: JPY | G6: 21/07/2028 | H6: FIXED | I6: 2 | J6: 1.082 | K6: 1.468 | L6: 1.521 | M6: 99.12 | N6: 98.999 | O6: YN5999357 | P6: JP363360BR77 | Q6: A+ | R6: 15/07/2025 | S6: 22/07/2026 | T6: 2.3107461 | U6: 99.0595 | V6: 12 | W6: 2 | X6: 1 | Y6: 0.39831868 | Z6: 98.661181 | AA6: 1.4945
A7: 35 | B7: {=_xlfn.XLOOKUP(A7,SORT!$U$2:$U$38,_xlfn.ANCHORARRAY(SORT!$A$2),,0)} -> ZS613802 Corp | C7: Toyota Motor Corp | D7: TOYOTA | E7: JP | F7: JPY | G7: 24/05/2029 | H7: FIXED | I7: 2 | J7: 0.15 | K7: 1.653 | L7: 1.665 | M7: 95.435 | N7: 95.4 | O7: ZS6138029 | P7: JP363340BK53 | Q7: A+ | R7: 17/05/2019 | S7: 22/05/2026 | T7: 3.1512663 | U7: 95.4175 | V7: 35 | W7: 3 | X7: 7 | Y7: 0.10549451 | Z7: 95.312005 | AA7: 1.659
A8: 25 | B8: {=_xlfn.XLOOKUP(A8,SORT!$U$2:$U$38,_xlfn.ANCHORARRAY(SORT!$A$2),,0)} -> YV793180 Corp | C8: Toyota Finance Corp | D8: TOYOTA | E8: JP | F8: JPY | G8: 10/10/2029 | H8: FIXED | I8: 2 | J8: 0.71 | K8: 1.77 | L8: 1.77 | M8: 96.433 | N8: 96.433 | O8: YV7931806 | P8: JP363360BQA7 | Q8: A+ | R8: 04/10/2024 | S8: 10/04/2026 | T8: 3.5318275 | U8: 96.433 | V8: 25 | W8: 3.5 | X8: 2 | Y8: 0.66708791 | Z8: 95.765912 | AA8: 1.77
A9: 19 | B9: {=_xlfn.XLOOKUP(A9,SORT!$U$2:$U$38,_xlfn.ANCHORARRAY(SORT!$A$2),,0)} -> YT968038 Corp | C9: Toyota Finance Corp | D9: TOYOTA | E9: JP | F9: JPY | G9: 23/01/2030 | H9: FIXED | I9: 2 | J9: 1.051 | K9: 1.809 | L9: 1.809 | M9: 97.261 | N9: 97.261 | O9: YT9680380 | P9: JP363360BR10 | Q9: A+ | R9: 17/01/2025 | S9: 23/07/2026 | T9: 3.8193018 | U9: 97.261 | V9: 19 | W9: 3.5 | X9: 1 | Y9: 0.38113187 | Z9: 96.879868 | AA9: 1.809
A10: 9 | B10: {=_xlfn.XLOOKUP(A10,SORT!$U$2:$U$38,_xlfn.ANCHORARRAY(SORT!$A$2),,0)} -> YL396232 Corp | C10: Toyota Motor Corp | D10: TOYOTA | E10: JP | F10: JPY | G10: 04/09/2030 | H10: FIXED | I10: 2 | J10: 1.296 | K10: 1.838 | L10: 1.838 | M10: 97.756 | N10: 97.756 | O10: YL3962328 | P10: JP363340BR98 | Q10: A+ | R10: 29/08/2025 | S10: 04/09/2026 | T10: 4.4325804 | U10: 97.756 | V10: 9 | W10: 4 | X10: 1 | Y10: 0.18514286 | Z10: 97.570857 | AA10: 1.838
A11: 10 | B11: {=_xlfn.XLOOKUP(A11,SORT!$U$2:$U$38,_xlfn.ANCHORARRAY(SORT!$A$2),,0)} -> YK173563 Corp | C11: Toyota Finance Corp | D11: TOYOTA | E11: JP | F11: JPY | G11: 17/10/2030 | H11: FIXED | I11: 2 | J11: 1.493 | K11: 1.888 | L11: 1.888 | M11: 98.329 | N11: 98.329 | O11: YK1735637 | P11: JP363360ARA7 | Q11: A+ | R11: 10/10/2025 | S11: 17/04/2026 | T11: 4.550308 | U11: 98.329 | V11: 10 | W11: 4.5 | X11: 1 | Y11: 1.3453407 | Z11: 96.983659 | AA11: 1.888
A12: 5 | B12: {=_xlfn.XLOOKUP(A12,SORT!$U$2:$U$38,_xlfn.ANCHORARRAY(SORT!$A$2),,0)} -> BO356983 Corp | C12: Toyota Motor Corp | D12: TOYOTA | E12: JP | F12: JPY | G12: 18/03/2031 | H12: FIXED | I12: 2 | J12: 0.219 | K12: 1.982 | L12: 1.982 | M12: 91.959 | N12: 91.959 | O12: BO3569833 | P12: JP363340CM35 | Q12: A+ | R12: 12/03/2021 | S12: 18/03/2026 | T12: 4.9664613 | U12: 91.959 | V12: 5 | W12: 4.5 | X12: 5 | Y12: 0.23223626 | Z12: 91.726764 | AA12: 1.982
A13: 16 | B13: {=_xlfn.XLOOKUP(A13,SORT!$U$2:$U$38,_xlfn.ANCHORARRAY(SORT!$A$2),,0)} -> YS631917 Corp | C13: Toyota Finance Corp | D13: TOYOTA | E13: JP | F13: JPY | G13: 23/01/2032 | H13: FIXED | I13: 2 | J13: 1.18 | K13: 2.088 | L13: 2.088 | M13: 95.255 | N13: 95.255 | O13: YS6319174 | P13: JP363360CR19 | Q13: A+ | R13: 17/01/2025 | S13: 23/07/2026 | T13: 5.8179329 | U13: 95.255 | V13: 16 | W13: 5.5 | X13: 1 | Y13: 0.42791209 | Z13: 94.827088 | AA13: 2.088
... A19: 4 | B19: {=_xlfn.XLOOKUP(A19,SORT!$U$2:$U$38,_xlfn.ANCHORARRAY(SORT!$A$2),,0)} -> AN666227 Corp | C19: Toyota Motor Corp | D19: TOYOTA | E19: JP | F19: JPY | G19: 02/06/2037 | H19: FIXED | I19: 2 | J19: 0.651 | K19: 2.962 | L19: 2.962 | M19: 80.535 | N19: 80.535 | O19: AN6662273 | P19: JP363340DH64 | Q19: A+ | R19: 26/05/2017 | S19: 02/06/2026 | T19: 11.175907 | U19: 80.535 | V19: 4 | W19: 11 | X19: 9 | Y19: 0.42207692 | Z19: 80.112923 | AA19: 2.962

Sheet F coupon<0.5
A1: ID | B1: {=_xlfn.ANCHORARRAY(SORT!A1)} -> Instrument | C1: Name | D1: Ticker | E1: Country/Region | F1: Currency | G1: Maturity | H1: Coupon Type | I1: Coupon Frequency | J1: Coupon | K1: Ask Yield to Maturity | L1: Bid Yield to Maturity | M1: Ask Price | N1: Bid Price | O1: Identifier | P1: ISIN | Q1: Bloomberg Composite Rating | R1: Announce | S1: Next Coupon Settle Date | T1: Time | U1: AVG Price | V1: ID | W1: TIMEish | X1: years ago | Y1: Accrued Interest | Z1: Clean price | AA1: AVG yield | AE1: {=_xlfn.ANCHORARRAY(B1)} -> Instrument | AF1: Name | AG1: Ticker | AH1: Country/Region | AI1: Currency | AJ1: Maturity | AK1: Coupon Type | AL1: Coupon Frequency | AM1: Coupon | AN1: Ask Yield to Maturity | AO1: Bid Yield to Maturity | AP1: Ask Price | AQ1: Bid Price | AR1: Identifier | AS1: ISIN | AT1: Bloomberg Composite Rating | AU1: Announce | AV1: Next Coupon Settle Date | AW1: Time | AX1: AVG Price | AY1: ID | AZ1: TIMEish | BA1: years ago | BB1: Accrued Interest | BC1: Clean price | BD1: AVG yield
B2: {=_xlfn._xlws.FILTER(_xlfn.ANCHORARRAY(AE2),OFFSET(AZ1,1,,COUNT(AZ:AZ))>0)} -> ZI885852 Corp | C2: Toyota Finance Corp | D2: TOYOTA | E2: JP | F2: JPY | G2: 13/10/2026 | H2: FIXED | I2: 2 | J2: 0.37 | K2: 1.163 | L2: 1.163 | M2: 99.538 | N2: 99.538 | O2: ZI8858527 | P2: JP363360APA1 | Q2: A+ | R2: 06/10/2023 | S2: 13/04/2026 | T2: 0.53935661 | U2: 99.538 | V2: 2 | W2: 0.5 | X2: 3 | Y2: 0.34153846 | Z2: 99.196462 | AA2: 1.163 | AE2: {=_xlfn._xlws.FILTER(_xlfn.ANCHORARRAY(SORT!A2),SORT!I2:I38<0.5)} -> BO356982 Corp | AF2: Toyota Motor Corp | AG2: TOYOTA | AH2: JP | AI2: JPY | AJ2: 18/03/2026 | AK2: FIXED | AL2: 2 | AM2: 0.05 | AN2: 1.477 | AO2: 1.483 | AP2: 99.98 | AQ2: 99.98 | AR2: BO3569825 | AS2: JP363340BM36 | AT2: A+ | AU2: 12/03/2021 | AV2: 18/03/2026 | AW2: -0.032854209 | AX2: 99.98 | AY2: 7 | AZ2: 0 | BA2: 5 | BB2: 0.053021978 | BC2: 99.926978 | BD2: 1.48
B3: ZD637368 Corp | C3: Toyota Finance Corp | D3: TOYOTA | E3: JP | F3: JPY | G3: 09/04/2027 | H3: FIXED | I3: 2 | J3: 0.414 | K3: 1.259 | L3: 1.281 | M3: 99.104 | N3: 99.081 | O3: ZD6373686 | P3: JP363360AQ46 | Q3: A+ | R3: 05/04/2024 | S3: 10/04/2026 | T3: 1.026694 | U3: 99.0925 | V3: 26 | W3: 1 | X3: 2 | Y3: 0.38897802 | Z3: 98.703522 | AA3: 1.27 | AE3: BO356985 Corp | AF3: Toyota Motor Corp | AG3: TOYOTA | AH3: JP | AI3: JPY | AJ3: 27/03/2026 | AK3: FIXED | AL3: 2 | AM3: 0.1 | AN3: 1.173 | AO3: 1.176 | AP3: 99.958 | AQ3: 99.958 | AR3: BO3569858 | AS3: JP363340AM37 | AT3: #N/A N/A | AU3: 12/03/2021 | AV3: 27/03/2026 | AW3: -0.0082135524 | AX3: 99.958 | AY3: 6 | AZ3: 0 | BA3: 5 | BB3: 0.1010989 | BC3: 99.856901 | BD3: 1.1745
B4: AN666209 Corp | C4: Toyota Motor Corp | D4: TOYOTA | E4: JP | F4: JPY | G4: 02/06/2027 | H4: FIXED | I4: 2 | J4: 0.22 | K4: 1.274 | L4: 1.292 | M4: 98.73 | N4: 98.709 | O4: AN6662091 | P4: JP363340CH65 | Q4: A+ | R4: 26/05/2017 | S4: 02/06/2026 | T4: 1.174538 | U4: 98.7195 | V4: 15 | W4: 1 | X4: 9 | Y4: 0.14263736 | Z4: 98.576863 | AA4: 1.283 | AE4: BO579315 Corp | AF4: Toyota Finance Corp | AG4: TOYOTA | AH4: JP | AI4: JPY | AJ4: 15/04/2026 | AK4: FIXED | AL4: 2 | AM4: 0.06 | AN4: 1.099 | AO4: 1.1 | AP4: 99.906 | AQ4: 99.906 | AR4: BO5793159 | AS4: JP363360BM49 | AT4: A+ | AU4: 09/04/2021 | AV4: 15/04/2026 | AW4: 0.043805613 | AX4: 99.906 | AY4: 31 | AZ4: 0 | BA4: 5 | BB4: 0.054725275 | BC4: 99.851275 | BD4: 1.0995
B5: BW601098 Corp | C5: Toyota Motor Corp | D5: TOYOTA | E5: JP | F5: JPY | G5: 02/06/2027 | H5: FIXED | I5: 2 | J5: 0.11 | K5: 1.273 | L5: 1.291 | M5: 98.599 | N5: 98.578 | O5: BW6010985 | P5: JP363340AN69 | Q5: A+ | R5: 27/05/2022 | S5: 02/06/2026 | T5: 1.174538 | U5: 98.5885 | V5: 32 | W5: 1 | X5: 4 | Y5: 0.071318681 | Z5: 98.517181 | AA5: 1.282 | AE5: LW169500 Corp | AF5: Toyota Motor Corp | AG5: TOYOTA | AH5: JP | AI5: JPY | AJ5: 03/06/2026 | AK5: FIXED | AL5: 2 | AM5: 0.09 | AN5: 0.864 | AO5: 1.134 | AP5: 99.826 | AQ5: 99.766 | AR5: LW1695003 | AS5: JP363340AG68 | AT5: A+ | AU5: 27/05/2016 | AV5: 03/06/2026 | AW5: 0.1779603 | AX5: 99.796 | AY5: 3 | AZ5: 0 | BA5: 10 | BB5: 0.057857143 | BC5: 99.738143 | BD5: 0.999
B6: AO295977 Corp | C6: Toyota Finance Corp | D6: TOYOTA | E6: JP | F6: JPY | G6: 23/07/2027 | H6: FIXED | I6: 2 | J6: 0.265 | K6: 1.346 | L6: 1.36 | M6: 98.553 | N6: 98.534 | O6: AO2959770 | P6: JP363360CH78 | Q6: A+ | R6: 14/07/2017 | S6: 24/07/2026 | T6: 1.3141684 | U6: 98.5435 | V6: 29 | W6: 1 | X6: 9 | Y6: 0.094642857 | Z6: 98.448857 | AA6: 1.353 | AE6: ZI885852 Corp | AF6: Toyota Finance Corp | AG6: TOYOTA | AH6: JP | AI6: JPY | AJ6: 13/10/2026 | AK6: FIXED | AL6: 2 | AM6: 0.37 | AN6: 1.163 | AO6: 1.163 | AP6: 99.538 | AQ6: 99.538 | AR6: ZI8858527 | AS6: JP363360APA1 | AT6: A+ | AU6: 06/10/2023 | AV6: 13/04/2026 | AW6: 0.53935661 | AX6: 99.538 | AY6: 2 | AZ6: 0.5 | BA6: 3 | BB6: 0.34153846 | BC6: 99.196462 | BD6: 1.163
