Workbook
Name b0_c: 'NSS Corporate'!$C$78
Name b0_G: 'NSS Goverment'!$C$78
Name b1_c: 'NSS Corporate'!$C$79
Name b1_G: 'NSS Goverment'!$C$79
Name b2_c: 'NSS Corporate'!$C$80
Name b2_G: 'NSS Goverment'!$C$80
Name b3_c: 'NSS Corporate'!$C$81
Name b3_G: 'NSS Goverment'!$C$81
Name tau1_c: 'NSS Corporate'!$C$82
Name tau1_G: 'NSS Goverment'!$C$82
Name tau2_c: 'NSS Corporate'!$C$83
Name tau2_G: 'NSS Goverment'!$C$83

Sheet DATA Goverment
A1: Instrument | B1: Name | C1: Ticker | D1: Country/Region | E1: Currency | F1: Maturity | G1: Coupon Type | H1: Coupon Frequency | I1: Coupon | J1: Ask Yield to Maturity | K1: Bid Yield to Maturity | L1: Ask Price | M1: Bid Price | N1: Identifier | O1: ISIN | P1: Bloomberg Composite Rating | Q1: Announce | R1: Next Coupon Settle Date | S1: Time | T1: AVG price | U1: id | V1: TIME rounded | W1: years ago | X1: Last Coupon Settle Date | Y1: Accrued Interest | Z1: Clean price | AA1: AVG yield
A2: BO997638 Corp | B2: Japan Government Five Year Bond | C2: JGB | D2: JP | E2: JPY | F2: 20/03/2026 | G2: FIXED | H2: 2 | I2: 0.005 | J2: 0.74800001 | K2: 0.76600001 | L2: 99.983 | M2: 99.983 | N2: BO9976388 | O2: JP1051471M45 | P2: A+ | Q2: 44287 | R2: 46101 | S2: 0 | T2: 99.983 | U2: 47 | V2: 0 | W2: 5 | X2: 45921 | Y2: =((TODAY()-10)-X2)/180 -> 0.94444444 | Z2: =T2-Y2 -> 99.038556 | AA2: 0.75700001
A3: EF329501 Corp | B3: Japan Government Twenty Year Bond | C3: JGB | D3: JP | E3: JPY | F3: 20/03/2026 | G3: FIXED | H3: 2 | I3: 2.1 | J3: 0.748 | K3: 0.771 | L3: 100.029 | M3: 100.029 | N3: EF3295013 | O3: JP1200851630 | P3: A+ | Q3: 38792 | R3: 46101 | S3: 0 | T3: 100.029 | U3: 103 | V3: 0 | W3: 20 | X3: 45921 | Y3: =((TODAY()-10)-X3)/180*(I3/2) -> 0.99166667 | Z3: =T3-Y3 -> 99.037333 | AA3: 0.7595
A4: EF381218 Corp | B4: Japan Government Twenty Year Bond | C4: JGB | D4: JP | E4: JPY | F4: 20/03/2026 | G4: FIXED | H4: 2 | I4: 2.3 | J4: 0.736 | K4: 0.768 | L4: 100.034 | M4: 100.033 | N4: EF3812189 | O4: JP1200861647 | P4: A+ | Q4: 38832 | R4: 46101 | S4: 0 | T4: 100.0335 | U4: 105 | V4: 0 | W4: 20 | X4: 45921 | Y4: =((TODAY()-10)-X4)/180*(I4/2) -> 1.0861111 | Z4: =T4-Y4 -> 98.947389 | AA4: 0.752
A5: EF452796 Corp | B5: Japan Government Twenty Year Bond | C5: JGB | D5: JP | E5: JPY | F5: 20/03/2026 | G5: FIXED | H5: 2 | I5: 2.2 | J5: 0.737 | K5: 0.762 | L5: 100.032 | M5: 100.031 | N5: EF4527968 | O5: JP1200871653 | P5: A+ | Q5: 38862 | R5: 46101 | S5: 0 | T5: 100.0315 | U5: 106 | V5: 0 | W5: 20 | X5: 45921 | Y5: =((TODAY()-10)-X5)/180*(I5/2) -> 1.0388889 | Z5: =T5-Y5 -> 98.992611 | AA5: 0.7495
A6: JK298261 Corp | B6: Japan Government Ten Year Bond | C6: JGB | D6: JP | E6: JPY | F6: 20/03/2026 | G6: FIXED | H6: 2 | I6: 0.1 | J6: 0.74 | K6: 0.763 | L6: 99.985 | M6: 99.985 | N6: JK2982615 | O6: JP1103421G35 | P6: A+ | Q6: 42430 | R6: 46101 | S6: 0 | T6: 99.985 | U6: 206 | V6: 0 | W6: 10 | X6: 45921 | Y6: =((TODAY()-10)-X6)/180*(I6/2) -> 0.047222222 | Z6: =T6-Y6 -> 99.937778 | AA6: 0.7515
A7: ZB137529 Corp | B7: Japan Government Two Year Bond | C7: JGB | D7: JP | E7: JPY | F7: 01/04/2026 | G7: FIXED | H7: 2 | I7: 0.2 | J7: 0.735 | K7: 0.75800001 | L7: 99.97 | M7: 99.969 | N7: ZB1375292 | O7: JP1024591Q43 | P7: A+ | Q7: 45373 | R7: 46113 | S7: 0.032854209 | T7: 99.9695 | U7: 280 | V7: 0 | W7: 2 | X7: 45933 | Y7: =((TODAY()-10)-X7)/180*(I7/2) -> 0.087777778 | Z7: =T7-Y7 -> 99.881722 | AA7: 0.7465
A8: ZB651229 Corp | B8: Japan Government Two Year Bond | C8: JGB | D8: JP | E8: JPY | F8: 01/05/2026 | G8: FIXED | H8: 2 | I8: 0.3 | J8: 0.75 | K8: 0.773 | L8: 99.938 | M8: 99.935 | N8: ZB6512295 | O8: JP1024601Q58 | P8: A+ | Q8: 45398 | R8: 46143 | S8: 0.11498973 | T8: 99.9365 | U8: 285 | V8: 0 | W8: 2 | X8: 45963 | Y8: =((TODAY()-10)-X8)/180*(I8/2) -> 0.10666667 | Z8: =T8-Y8 -> 99.829833 | AA8: 0.7615
A9: YX440521 Corp | B9: Japan Government Two Year Bond | C9: JGB | D9: JP | E9: JPY | F9: 01/06/2026 | G9: FIXED | H9: 2 | I9: 0.4 | J9: 0.763 | K9: 0.785 | L9: 99.919 | M9: 99.914 | N9: YX4405214 | O9: JP1024611Q64 | P9: A+ | Q9: 45435 | R9: 46174 | S9: 0.19986311 | T9: 99.9165 | U9: 278 | V9: 0 | W9: 2 | X9: 45994 | Y9: =((TODAY()-10)-X9)/180*(I9/2) -> 0.10777778 | Z9: =T9-Y9 -> 99.808722 | AA9: 0.774
A10: BQ447894 Corp | B10: Japan Government Five Year Bond | C10: JGB | D10: JP | E10: JPY | F10: 20/06/2026 | G10: FIXED | H10: 2 | I10: 0.005 | J10: 0.78 | K10: 0.803 | L10: 99.788 | M10: 99.781 | N10: BQ4478948 | O10: JP1051481M76 | P10: NR | Q10: 44378 | R10: 46193 | S10: 0.25188227 | T10: 99.7845 | U10: 52 | V10: 0 | W10: 5 | X10: 46013 | Y10: =((TODAY()-10)-X10)/180*(I10/2) -> 0.0010833333 | Z10: =T10-Y10 -> 99.783417 | AA10: 0.7915
A11: EF500367 Corp | B11: Japan Government Twenty Year Bond | C11: JGB | D11: JP | E11: JPY | F11: 20/06/2026 | G11: FIXED | H11: 2 | I11: 2.3 | J11: 0.786 | K11: 0.81 | L11: 100.413 | M11: 100.407 | N11: EF5003670 | O11: JP1200881660 | P11: A+ | Q11: 38888 | R11: 46193 | S11: 0.25188227 | T11: 100.41 | U11: 107 | V11: 0 | W11: 20 | X11: 46013 | Y11: =((TODAY()-10)-X11)/180*(I11/2) -> 0.49833333 | Z11: =T11-Y11 -> 99.911667 | AA11: 0.798
A12: EF659299 Corp | B12: Japan Government Twenty Year Bond | C12: JGB | D12: JP | E12: JPY | F12: 20/06/2026 | G12: FIXED | H12: 2 | I12: 2.2 | J12: 0.78 | K12: 0.81 | L12: 100.388 | M12: 100.379 | N12: EF6592994 | O12: JP1200891685 | P12: A+ | Q12: 38953 | R12: 46193 | S12: 0.25188227 | T12: 100.3835 | U12: 109 | V12: 0 | W12: 20 | X12: 46013 | Y12: =((TODAY()-10)-X12)/180*(I12/2) -> 0.47666667 | Z12: =T12-Y12 -> 99.906833 | AA12: 0.795
A13: LW316486 Corp | B13: Japan Government Ten Year Bond | C13: JGB | D13: JP | E13: JPY | F13: 20/06/2026 | G13: FIXED | H13: 2 | I13: 0.1 | J13: 0.772 | K13: 0.794 | L13: 99.816 | M13: 99.81 | N13: LW3164867 | O13: JP1103431G66 | P13: A+ | Q13: 42523 | R13: 46193 | S13: 0.25188227 | T13: 99.813 | U13: 212 | V13: 0 | W13: 10 | X13: 46013 | Y13: =((TODAY()-10)-X13)/180*(I13/2) -> 0.021666667 | Z13: =T13-Y13 -> 99.791333 | AA13: 0.783
A14: YW041715 Corp | B14: Japan Government Two Year Bond | C14: JGB | D14: JP | E14: JPY | F14: 01/07/2026 | G14: FIXED | H14: 2 | I14: 0.4 | J14: 0.79 | K14: 0.813 | L14: 99.881 | M14: 99.874 | N14: YW0417157 | O14: JP1024621Q70 | P14: A+ | Q14: 45463 | R14: 46204 | S14: 0.28199863 | T14: 99.8775 | U14: 268 | V14: 0 | W14: 2 | X14: 46024 | Y14: =((TODAY()-10)-X14)/180*(I14/2) -> 0.074444444 | Z14: =T14-Y14 -> 99.803056 | AA14: 0.8015
... A327: YO939740 Corp | B327: Japan Government Forty Year Bond | C327: JGB | D327: JP | E327: JPY | F327: 20/03/2065 | G327: FIXED | H327: 2 | I327: 3.1 | J327: 3.611 | K327: 3.669 | L327: 91.722 | M327: 90.869 | N327: YO9397408 | O327: JP1400181R57 | P327: A+ | Q327: 45798 | R327: 46101 | S327: 39.000684 | T327: 91.2955 | U327: 241 | V327: 39 | W327: 1 | X327: 45921 | Y327: =((TODAY()-10)-X327)/180*(I327/2) -> 1.4638889 | Z327: =T327-Y327 -> 89.831611 | AA327: 3.64

Sheet NSS Goverment
A1: Maturity | B1: Coupon | C1: Market Price | D1: Model Price | E1: Error | F1: Abs Error | G1: Yield | H1: Yield Model | I1: Yield Error | J1: - prices | K1: Cashflows | CN1: FITTED VISUALISATION
K2: {=_xlfn.SEQUENCE(1,79,0,0.5)} -> 0 | L2: 0.5 | M2: 1 | N2: 1.5 | O2: 2 | P2: 2.5 | Q2: 3 | R2: 3.5 | S2: 4 | T2: 4.5 | U2: 5 | V2: 5.5 | W2: 6 | X2: 6.5 | Y2: 7 | Z2: 7.5 | AA2: 8 | AB2: 8.5 | AC2: 9 | AD2: 9.5 | AE2: 10 | AF2: 10.5 | AG2: 11 | AH2: 11.5 | AI2: 12 | AJ2: 12.5 | AK2: 13 | AL2: 13.5 | AM2: 14 | AN2: 14.5 | AO2: 15 | AP2: 15.5 | AQ2: 16 | AR2: 16.5 | AS2: 17 | AT2: 17.5 | AU2: 18 | AV2: 18.5 | AW2: 19 | AX2: 19.5 | AY2: 20 | AZ2: 20.5 | BA2: 21 | BB2: 21.5 | BC2: 22 | BD2: 22.5 | BE2: 23 | BF2: 23.5 | BG2: 24 | BH2: 24.5 | BI2: 25 | BJ2: 25.5 | BK2: 26 | BL2: 26.5 | BM2: 27 | BN2: 27.5 | BO2: 28 | BP2: 28.5 | BQ2: 29 | BR2: 29.5 | BS2: 30 | BT2: 30.5 | BU2: 31 | BV2: 31.5 | BW2: 32 | BX2: 32.5 | BY2: 33 | BZ2: 33.5 | CA2: 34 | CB2: 34.5 | CC2: 35 | CD2: 35.5 | CE2: 36 | CF2: 36.5 | CG2: 37 | CH2: 37.5 | CI2: 38 | CJ2: 38.5 | CK2: 39 | CN2: Time discretization | CO2: Long term spot | CP2: Time decay | CQ2: First hump | CR2: Second hump | CS2: Total
A3: 0.5 | B3: 5e-05 | C3: 99.539 | D3: =SUMPRODUCT(L3:CK3,$L$79:$CK$79) -> 99.237417 | E3: =+D3-C3 -> -0.30158253 | F3: =ABS(C3-D3) -> 0.30158253 | G3: =+IFERROR(IRR(K3:CK3,0),0) -> 0.0046815821 | H3: =IFERROR(IRR((J3,L3:CK3),0),0) -> 0.0077348096 | I3: =IFERROR(H3-G3,0) -> 0.0030532275 | J3: =-D3 -> -99.237417 | K3: =-C3 -> -99.539 | L3: =$B3*100*(L$2<$A3)+100*(1+$B3)*(L$2=$A3) -> 100.005 | M3: =$B3*100*(M$2<$A3)+100*(1+$B3)*(M$2=$A3) -> 0 | N3: =$B3*100*(N$2<$A3)+100*(1+$B3)*(N$2=$A3) -> 0 | O3: =$B3*100*(O$2<$A3)+100*(1+$B3)*(O$2=$A3) -> 0 | P3: =$B3*100*(P$2<$A3)+100*(1+$B3)*(P$2=$A3) -> 0 | Q3: =$B3*100*(Q$2<$A3)+100*(1+$B3)*(Q$2=$A3) -> 0 | R3: =$B3*100*(R$2<$A3)+100*(1+$B3)*(R$2=$A3) -> 0 | S3: =$B3*100*(S$2<$A3)+100*(1+$B3)*(S$2=$A3) -> 0 | ... CK3: =$B3*100*(CK$2<$A3)+100*(1+$B3)*(CK$2=$A3) -> 0 | CN3: 1e-06 | CO3: =$C$78 -> 0.055604949 | CP3: =b1_G*(1-EXP(-CN3/tau1_G))/(CN3/tau1_G) -> -0.040658777 | CQ3: =b2_G*((1-EXP(-CN3/tau1_G))/(CN3/tau1_G)-EXP(-CN3/tau1_G)) -> -5.3576813e-09 | CR3: =+b3_G*((1-EXP(-CN3/tau2_G))/(CN3/tau2_G)-EXP(-CN3/tau2_G)) -> 2.5003682e-09 | CS3: =SUM(CO3:CR3) -> 0.014946169
A4: 0.5 | B4: 0.001 | C4: 99.592 | D4: =SUMPRODUCT(L4:CK4,$L$79:$CK$79) -> 99.331688 | E4: =+D4-C4 -> -0.2603117 | F4: =ABS(C4-D4) -> 0.2603117 | G4: =+IFERROR(IRR(K4:CK4,0),0) -> 0.0051008113 | H4: =IFERROR(IRR((J4,L4:CK4),0),0) -> 0.0077348096 | I4: =IFERROR(H4-G4,0) -> 0.0026339983 | J4: =-D4 -> -99.331688 | K4: =-C4 -> -99.592 | L4: =$B4*100*(L$2<$A4)+100*(1+$B4)*(L$2=$A4) -> 100.1 | M4: =$B4*100*(M$2<$A4)+100*(1+$B4)*(M$2=$A4) -> 0 | N4: =$B4*100*(N$2<$A4)+100*(1+$B4)*(N$2=$A4) -> 0 | O4: =$B4*100*(O$2<$A4)+100*(1+$B4)*(O$2=$A4) -> 0 | P4: =$B4*100*(P$2<$A4)+100*(1+$B4)*(P$2=$A4) -> 0 | Q4: =$B4*100*(Q$2<$A4)+100*(1+$B4)*(Q$2=$A4) -> 0 | R4: =$B4*100*(R$2<$A4)+100*(1+$B4)*(R$2=$A4) -> 0 | S4: =$B4*100*(S$2<$A4)+100*(1+$B4)*(S$2=$A4) -> 0 | ... CK4: =$B4*100*(CK$2<$A4)+100*(1+$B4)*(CK$2=$A4) -> 0 | CN4: {=_xlfn.SEQUENCE(500,,0.5,0.5)} -> 0.5 | CO4: {=_xlfn.ANCHORARRAY(CN4)-_xlfn.ANCHORARRAY(CN4)+$B$78} -> 0.05 | CP4: {=b1_G*(1-EXP(-_xlfn.ANCHORARRAY(CN4)/tau1_G))/(_xlfn.ANCHORARRAY(CN4)/tau1_G)} -> -0.038388015 | CQ4: {=b2_G*((1-EXP(-_xlfn.ANCHORARRAY(CN4)/tau1_G))/(_xlfn.ANCHORARRAY(CN4)/tau1_G)-EXP(-_xlfn.ANCHORARRAY(CN4)/tau1_G))} -> -0.002479083 | CR4: {=+b3_G*((1-EXP(-_xlfn.ANCHORARRAY(CN4)/tau2_G))/(_xlfn.ANCHORARRAY(CN4)/tau2_G)-EXP(-_xlfn.ANCHORARRAY(CN4)/tau2_G))} -> 0.00079159629 | CS4: =SUM(CO4:CR4) -> 0.0099244979
A5: 0.5 | B5: 0.004 | C5: 99.7295 | D5: =SUMPRODUCT(L5:CK5,$L$79:$CK$79) -> 99.629386 | E5: =+D5-C5 -> -0.10011433 | F5: =ABS(C5-D5) -> 0.10011433 | G5: =+IFERROR(IRR(K5:CK5,0),0) -> 0.0067231862 | H5: =IFERROR(IRR((J5,L5:CK5),0),0) -> 0.0077348096 | I5: =IFERROR(H5-G5,0) -> 0.0010116234 | J5: =-D5 -> -99.629386 | K5: =-C5 -> -99.7295 | L5: =$B5*100*(L$2<$A5)+100*(1+$B5)*(L$2=$A5) -> 100.4 | M5: =$B5*100*(M$2<$A5)+100*(1+$B5)*(M$2=$A5) -> 0 | N5: =$B5*100*(N$2<$A5)+100*(1+$B5)*(N$2=$A5) -> 0 | O5: =$B5*100*(O$2<$A5)+100*(1+$B5)*(O$2=$A5) -> 0 | P5: =$B5*100*(P$2<$A5)+100*(1+$B5)*(P$2=$A5) -> 0 | Q5: =$B5*100*(Q$2<$A5)+100*(1+$B5)*(Q$2=$A5) -> 0 | R5: =$B5*100*(R$2<$A5)+100*(1+$B5)*(R$2=$A5) -> 0 | S5: =$B5*100*(S$2<$A5)+100*(1+$B5)*(S$2=$A5) -> 0 | ... CK5: =$B5*100*(CK$2<$A5)+100*(1+$B5)*(CK$2=$A5) -> 0 | CN5: 1 | CO5: 0.05 | CP5: -0.036284745 | CQ5: -0.0045942128 | CR5: 0.0010330657 | CS5: =SUM(CO5:CR5) -> 0.010154107
A6: 0.5 | B6: 0.001 | C6: 99.3315 | D6: =SUMPRODUCT(L6:CK6,$L$79:$CK$79) -> 99.331688 | E6: =+D6-C6 -> 0.00018830187 | F6: =ABS(C6-D6) -> 0.00018830187 | G6: =+IFERROR(IRR(K6:CK6,0),0) -> 0.00773672 | H6: =IFERROR(IRR((J6,L6:CK6),0),0) -> 0.0077348096 | I6: =IFERROR(H6-G6,0) -> -1.9103542e-06 | J6: =-D6 -> -99.331688 | K6: =-C6 -> -99.3315 | L6: =$B6*100*(L$2<$A6)+100*(1+$B6)*(L$2=$A6) -> 100.1 | M6: =$B6*100*(M$2<$A6)+100*(1+$B6)*(M$2=$A6) -> 0 | N6: =$B6*100*(N$2<$A6)+100*(1+$B6)*(N$2=$A6) -> 0 | O6: =$B6*100*(O$2<$A6)+100*(1+$B6)*(O$2=$A6) -> 0 | P6: =$B6*100*(P$2<$A6)+100*(1+$B6)*(P$2=$A6) -> 0 | Q6: =$B6*100*(Q$2<$A6)+100*(1+$B6)*(Q$2=$A6) -> 0 | R6: =$B6*100*(R$2<$A6)+100*(1+$B6)*(R$2=$A6) -> 0 | S6: =$B6*100*(S$2<$A6)+100*(1+$B6)*(S$2=$A6) -> 0 | ... CK6: =$B6*100*(CK$2<$A6)+100*(1+$B6)*(CK$2=$A6) -> 0 | CN6: 1.5 | CO6: 0.05 | CP6: -0.034335126 | CQ6: -0.0063903867 | CR6: 0.0010435906 | CS6: =SUM(CO6:CR6) -> 0.010318078
A7: 0.5 | B7: 5e-05 | C7: 99.263 | D7: =SUMPRODUCT(L7:CK7,$L$79:$CK$79) -> 99.237417 | E7: =+D7-C7 -> -0.025582531 | F7: =ABS(C7-D7) -> 0.025582531 | G7: =+IFERROR(IRR(K7:CK7,0),0) -> 0.0074750914 | H7: =IFERROR(IRR((J7,L7:CK7),0),0) -> 0.0077348096 | I7: =IFERROR(H7-G7,0) -> 0.0002597182 | J7: =-D7 -> -99.237417 | K7: =-C7 -> -99.263 | L7: =$B7*100*(L$2<$A7)+100*(1+$B7)*(L$2=$A7) -> 100.005 | M7: =$B7*100*(M$2<$A7)+100*(1+$B7)*(M$2=$A7) -> 0 | N7: =$B7*100*(N$2<$A7)+100*(1+$B7)*(N$2=$A7) -> 0 | O7: =$B7*100*(O$2<$A7)+100*(1+$B7)*(O$2=$A7) -> 0 | P7: =$B7*100*(P$2<$A7)+100*(1+$B7)*(P$2=$A7) -> 0 | Q7: =$B7*100*(Q$2<$A7)+100*(1+$B7)*(Q$2=$A7) -> 0 | R7: =$B7*100*(R$2<$A7)+100*(1+$B7)*(R$2=$A7) -> 0 | S7: =$B7*100*(S$2<$A7)+100*(1+$B7)*(S$2=$A7) -> 0 | ... CK7: =$B7*100*(CK$2<$A7)+100*(1+$B7)*(CK$2=$A7) -> 0 | CN7: 2 | CO7: 0.05 | CP7: -0.032526528 | CQ7: -0.0079073324 | CR7: 0.00096772586 | CS7: =SUM(CO7:CR7) -> 0.010533865
A8: 0.5 | B8: 0.001 | C8: 99.0785 | D8: =SUMPRODUCT(L8:CK8,$L$79:$CK$79) -> 99.331688 | E8: =+D8-C8 -> 0.2531883 | F8: =ABS(C8-D8) -> 0.2531883 | G8: =+IFERROR(IRR(K8:CK8,0),0) -> 0.010310007 | H8: =IFERROR(IRR((J8,L8:CK8),0),0) -> 0.0077348096 | I8: =IFERROR(H8-G8,0) -> -0.0025751971 | J8: =-D8 -> -99.331688 | K8: =-C8 -> -99.0785 | L8: =$B8*100*(L$2<$A8)+100*(1+$B8)*(L$2=$A8) -> 100.1 | M8: =$B8*100*(M$2<$A8)+100*(1+$B8)*(M$2=$A8) -> 0 | N8: =$B8*100*(N$2<$A8)+100*(1+$B8)*(N$2=$A8) -> 0 | O8: =$B8*100*(O$2<$A8)+100*(1+$B8)*(O$2=$A8) -> 0 | P8: =$B8*100*(P$2<$A8)+100*(1+$B8)*(P$2=$A8) -> 0 | Q8: =$B8*100*(Q$2<$A8)+100*(1+$B8)*(Q$2=$A8) -> 0 | R8: =$B8*100*(R$2<$A8)+100*(1+$B8)*(R$2=$A8) -> 0 | S8: =$B8*100*(S$2<$A8)+100*(1+$B8)*(S$2=$A8) -> 0 | ... CK8: =$B8*100*(CK$2<$A8)+100*(1+$B8)*(CK$2=$A8) -> 0 | CN8: 2.5 | CO8: 0.05 | CP8: -0.030847433 | CQ8: -0.0091801102 | CR8: 0.0008683995 | CS8: =SUM(CO8:CR8) -> 0.010840856
A9: 0.5 | B9: 5e-05 | C9: 98.9895 | D9: =SUMPRODUCT(L9:CK9,$L$79:$CK$79) -> 99.237417 | E9: =+D9-C9 -> 0.24791747 | F9: =ABS(C9-D9) -> 0.24791747 | G9: =+IFERROR(IRR(K9:CK9,0),0) -> 0.010258664 | H9: =IFERROR(IRR((J9,L9:CK9),0),0) -> 0.0077348096 | I9: =IFERROR(H9-G9,0) -> -0.0025238542 | J9: =-D9 -> -99.237417 | K9: =-C9 -> -98.9895 | L9: =$B9*100*(L$2<$A9)+100*(1+$B9)*(L$2=$A9) -> 100.005 | M9: =$B9*100*(M$2<$A9)+100*(1+$B9)*(M$2=$A9) -> 0 | N9: =$B9*100*(N$2<$A9)+100*(1+$B9)*(N$2=$A9) -> 0 | O9: =$B9*100*(O$2<$A9)+100*(1+$B9)*(O$2=$A9) -> 0 | P9: =$B9*100*(P$2<$A9)+100*(1+$B9)*(P$2=$A9) -> 0 | Q9: =$B9*100*(Q$2<$A9)+100*(1+$B9)*(Q$2=$A9) -> 0 | R9: =$B9*100*(R$2<$A9)+100*(1+$B9)*(R$2=$A9) -> 0 | S9: =$B9*100*(S$2<$A9)+100*(1+$B9)*(S$2=$A9) -> 0 | ... CK9: =$B9*100*(CK$2<$A9)+100*(1+$B9)*(CK$2=$A9) -> 0 | CN9: 3 | CO9: 0.05 | CP9: -0.029287325 | CQ9: -0.010239647 | CR9: 0.00077110825 | CS9: =SUM(CO9:CR9) -> 0.011244136
A10: 0.5 | B10: 0.001 | C10: 99.085 | D10: =SUMPRODUCT(L10:CK10,$L$79:$CK$79) -> 99.331688 | E10: =+D10-C10 -> 0.2466883 | F10: =ABS(C10-D10) -> 0.2466883 | G10: =+IFERROR(IRR(K10:CK10,0),0) -> 0.01024373 | H10: =IFERROR(IRR((J10,L10:CK10),0),0) -> 0.0077348096 | I10: =IFERROR(H10-G10,0) -> -0.0025089205 | J10: =-D10 -> -99.331688 | K10: =-C10 -> -99.085 | L10: =$B10*100*(L$2<$A10)+100*(1+$B10)*(L$2=$A10) -> 100.1 | M10: =$B10*100*(M$2<$A10)+100*(1+$B10)*(M$2=$A10) -> 0 | N10: =$B10*100*(N$2<$A10)+100*(1+$B10)*(N$2=$A10) -> 0 | O10: =$B10*100*(O$2<$A10)+100*(1+$B10)*(O$2=$A10) -> 0 | P10: =$B10*100*(P$2<$A10)+100*(1+$B10)*(P$2=$A10) -> 0 | Q10: =$B10*100*(Q$2<$A10)+100*(1+$B10)*(Q$2=$A10) -> 0 | R10: =$B10*100*(R$2<$A10)+100*(1+$B10)*(R$2=$A10) -> 0 | S10: =$B10*100*(S$2<$A10)+100*(1+$B10)*(S$2=$A10) -> 0 | ... CK10: =$B10*100*(CK$2<$A10)+100*(1+$B10)*(CK$2=$A10) -> 0 | CN10: 3.5 | CO10: 0.05 | CP10: -0.027836603 | CQ10: -0.011113212 | CR10: 0.00068469113 | CS10: =SUM(CO10:CR10) -> 0.011734876
A11: 1 | B11: 0.001 | C11: 98.776 | D11: =SUMPRODUCT(L11:CK11,$L$79:$CK$79) -> 98.746553 | E11: =+D11-C11 -> -0.029447039 | F11: =ABS(C11-D11) -> 0.029447039 | G11: =+IFERROR(IRR(K11:CK11,0),0) -> 0.0071860466 | H11: =IFERROR(IRR((J11,L11:CK11),0),0) -> 0.0073362866 | I11: =IFERROR(H11-G11,0) -> 0.00015023993 | J11: =-D11 -> -98.746553 | K11: =-C11 -> -98.776 | L11: =$B11*100*(L$2<$A11)+100*(1+$B11)*(L$2=$A11) -> 0.1 | M11: =$B11*100*(M$2<$A11)+100*(1+$B11)*(M$2=$A11) -> 100.1 | N11: =$B11*100*(N$2<$A11)+100*(1+$B11)*(N$2=$A11) -> 0 | O11: =$B11*100*(O$2<$A11)+100*(1+$B11)*(O$2=$A11) -> 0 | P11: =$B11*100*(P$2<$A11)+100*(1+$B11)*(P$2=$A11) -> 0 | Q11: =$B11*100*(Q$2<$A11)+100*(1+$B11)*(Q$2=$A11) -> 0 | R11: =$B11*100*(R$2<$A11)+100*(1+$B11)*(R$2=$A11) -> 0 | S11: =$B11*100*(S$2<$A11)+100*(1+$B11)*(S$2=$A11) -> 0 | ... CK11: =$B11*100*(CK$2<$A11)+100*(1+$B11)*(CK$2=$A11) -> 0 | CN11: 4 | CO11: 0.05 | CP11: -0.026486498 | CQ11: -0.011824834 | CR11: 0.00061094067 | CS11: =SUM(CO11:CR11) -> 0.012299608
A12: 1 | B12: 5e-05 | C12: 98.6575 | D12: =SUMPRODUCT(L12:CK12,$L$79:$CK$79) -> 98.558661 | E12: =+D12-C12 -> -0.098839205 | F12: =ABS(C12-D12) -> 0.098839205 | G12: =+IFERROR(IRR(K12:CK12,0),0) -> 0.0068313613 | H12: =IFERROR(IRR((J12,L12:CK12),0),0) -> 0.0073360962 | I12: =IFERROR(H12-G12,0) -> 0.00050473484 | J12: =-D12 -> -98.558661 | K12: =-C12 -> -98.6575 | L12: =$B12*100*(L$2<$A12)+100*(1+$B12)*(L$2=$A12) -> 0.005 | M12: =$B12*100*(M$2<$A12)+100*(1+$B12)*(M$2=$A12) -> 100.005 | N12: =$B12*100*(N$2<$A12)+100*(1+$B12)*(N$2=$A12) -> 0 | O12: =$B12*100*(O$2<$A12)+100*(1+$B12)*(O$2=$A12) -> 0 | P12: =$B12*100*(P$2<$A12)+100*(1+$B12)*(P$2=$A12) -> 0 | Q12: =$B12*100*(Q$2<$A12)+100*(1+$B12)*(Q$2=$A12) -> 0 | R12: =$B12*100*(R$2<$A12)+100*(1+$B12)*(R$2=$A12) -> 0 | S12: =$B12*100*(S$2<$A12)+100*(1+$B12)*(S$2=$A12) -> 0 | ... CK12: =$B12*100*(CK$2<$A12)+100*(1+$B12)*(CK$2=$A12) -> 0 | CN12: 4.5 | CO12: 0.05 | CP12: -0.025228998 | CQ12: -0.012395678 | CR12: 0.00054894447 | CS12: =SUM(CO12:CR12) -> 0.012924269
A13: 1.5 | B13: 0.001 | C13: 98.426 | D13: =SUMPRODUCT(L13:CK13,$L$79:$CK$79) -> 98.104478 | E13: =+D13-C13 -> -0.32152202 | F13: =ABS(C13-D13) -> 0.32152202 | G13: =+IFERROR(IRR(K13:CK13,0),0) -> 0.0063130506 | H13: =IFERROR(IRR((J13,L13:CK13),0),0) -> 0.0074123052 | I13: =IFERROR(H13-G13,0) -> 0.0010992546 | J13: =-D13 -> -98.104478 | K13: =-C13 -> -98.426 | L13: =$B13*100*(L$2<$A13)+100*(1+$B13)*(L$2=$A13) -> 0.1 | M13: =$B13*100*(M$2<$A13)+100*(1+$B13)*(M$2=$A13) -> 0.1 | N13: =$B13*100*(N$2<$A13)+100*(1+$B13)*(N$2=$A13) -> 100.1 | O13: =$B13*100*(O$2<$A13)+100*(1+$B13)*(O$2=$A13) -> 0 | P13: =$B13*100*(P$2<$A13)+100*(1+$B13)*(P$2=$A13) -> 0 | Q13: =$B13*100*(Q$2<$A13)+100*(1+$B13)*(Q$2=$A13) -> 0 | R13: =$B13*100*(R$2<$A13)+100*(1+$B13)*(R$2=$A13) -> 0 | S13: =$B13*100*(S$2<$A13)+100*(1+$B13)*(S$2=$A13) -> 0 | ... CK13: =$B13*100*(CK$2<$A13)+100*(1+$B13)*(CK$2=$A13) -> 0 | CN13: 5 | CO13: 0.05 | CP13: -0.024056777 | CQ13: -0.012844372 | CR13: 0.00049697223 | CS13: =SUM(CO13:CR13) -> 0.013595823
A14: 1.5 | B14: 0.001 | C14: 98.417 | D14: =SUMPRODUCT(L14:CK14,$L$79:$CK$79) -> 98.104478 | E14: =+D14-C14 -> -0.31252202 | F14: =ABS(C14-D14) -> 0.31252202 | G14: =+IFERROR(IRR(K14:CK14,0),0) -> 0.0063437556 | H14: =IFERROR(IRR((J14,L14:CK14),0),0) -> 0.0074123052 | I14: =IFERROR(H14-G14,0) -> 0.0010685497 | J14: =-D14 -> -98.104478 | K14: =-C14 -> -98.417 | L14: =$B14*100*(L$2<$A14)+100*(1+$B14)*(L$2=$A14) -> 0.1 | M14: =$B14*100*(M$2<$A14)+100*(1+$B14)*(M$2=$A14) -> 0.1 | N14: =$B14*100*(N$2<$A14)+100*(1+$B14)*(N$2=$A14) -> 100.1 | O14: =$B14*100*(O$2<$A14)+100*(1+$B14)*(O$2=$A14) -> 0 | P14: =$B14*100*(P$2<$A14)+100*(1+$B14)*(P$2=$A14) -> 0 | Q14: =$B14*100*(Q$2<$A14)+100*(1+$B14)*(Q$2=$A14) -> 0 | R14: =$B14*100*(R$2<$A14)+100*(1+$B14)*(R$2=$A14) -> 0 | S14: =$B14*100*(S$2<$A14)+100*(1+$B14)*(S$2=$A14) -> 0 | ... CK14: =$B14*100*(CK$2<$A14)+100*(1+$B14)*(CK$2=$A14) -> 0 | CN14: 5.5 | CO14: 0.05 | CP14: -0.022963135 | CQ14: -0.013187305 | CR14: 0.0004532419 | CS14: =SUM(CO14:CR14) -> 0.014302802
A15: 1.5 | B15: 0.001 | C15: 98.1045 | D15: =SUMPRODUCT(L15:CK15,$L$79:$CK$79) -> 98.104478 | E15: =+D15-C15 -> -2.2018722e-05 | F15: =ABS(C15-D15) -> 2.2018722e-05 | G15: =+IFERROR(IRR(K15:CK15,0),0) -> 0.0074122298 | H15: =IFERROR(IRR((J15,L15:CK15),0),0) -> 0.0074123052 | I15: =IFERROR(H15-G15,0) -> 7.5444533e-08 | J15: =-D15 -> -98.104478 | K15: =-C15 -> -98.1045 | L15: =$B15*100*(L$2<$A15)+100*(1+$B15)*(L$2=$A15) -> 0.1 | M15: =$B15*100*(M$2<$A15)+100*(1+$B15)*(M$2=$A15) -> 0.1 | N15: =$B15*100*(N$2<$A15)+100*(1+$B15)*(N$2=$A15) -> 100.1 | O15: =$B15*100*(O$2<$A15)+100*(1+$B15)*(O$2=$A15) -> 0 | P15: =$B15*100*(P$2<$A15)+100*(1+$B15)*(P$2=$A15) -> 0 | Q15: =$B15*100*(Q$2<$A15)+100*(1+$B15)*(Q$2=$A15) -> 0 | R15: =$B15*100*(R$2<$A15)+100*(1+$B15)*(R$2=$A15) -> 0 | S15: =$B15*100*(S$2<$A15)+100*(1+$B15)*(S$2=$A15) -> 0 | ... CK15: =$B15*100*(CK$2<$A15)+100*(1+$B15)*(CK$2=$A15) -> 0 | CN15: 6 | CO15: 0.05 | CP15: -0.021941943 | CQ15: -0.01343888 | CR15: 0.00041618955 | CS15: =SUM(CO15:CR15) -> 0.015035366
A16: 1.5 | B16: 0.002 | C16: 98.2755 | D16: =SUMPRODUCT(L16:CK16,$L$79:$CK$79) -> 98.400068 | E16: =+D16-C16 -> 0.1245681 | F16: =ABS(C16-D16) -> 0.1245681 | G16: =+IFERROR(IRR(K16:CK16,0),0) -> 0.0078386867 | H16: =IFERROR(IRR((J16,L16:CK16),0),0) -> 0.0074123628 | I16: =IFERROR(H16-G16,0) -> -0.00042632385 | J16: =-D16 -> -98.400068 | K16: =-C16 -> -98.2755 | L16: =$B16*100*(L$2<$A16)+100*(1+$B16)*(L$2=$A16) -> 0.2 | M16: =$B16*100*(M$2<$A16)+100*(1+$B16)*(M$2=$A16) -> 0.2 | N16: =$B16*100*(N$2<$A16)+100*(1+$B16)*(N$2=$A16) -> 100.2 | O16: =$B16*100*(O$2<$A16)+100*(1+$B16)*(O$2=$A16) -> 0 | P16: =$B16*100*(P$2<$A16)+100*(1+$B16)*(P$2=$A16) -> 0 | Q16: =$B16*100*(Q$2<$A16)+100*(1+$B16)*(Q$2=$A16) -> 0 | R16: =$B16*100*(R$2<$A16)+100*(1+$B16)*(R$2=$A16) -> 0 | S16: =$B16*100*(S$2<$A16)+100*(1+$B16)*(S$2=$A16) -> 0 | ... CK16: =$B16*100*(CK$2<$A16)+100*(1+$B16)*(CK$2=$A16) -> 0 | CN16: 6.5 | CO16: 0.05 | CP16: -0.020987591 | CQ16: -0.013611751 | CR16: 0.00038453032 | CS16: =SUM(CO16:CR16) -> 0.015785188
... A66: 30 | B66: 0.004 | C66: 43.824 | D66: =SUMPRODUCT(L66:CK66,$L$79:$CK$79) -> 43.117306 | E66: =+D66-C66 -> -0.70669358 | F66: =ABS(C66-D66) -> 0.70669358 | G66: =+IFERROR(IRR(K66:CK66,0),0) -> 0.020264256 | H66: =IFERROR(IRR((J66,L66:CK66),0),0) -> 0.020604289 | I66: =IFERROR(H66-G66,0) -> 0.00034003289 | J66: =-D66 -> -43.117306 | K66: =-C66 -> -43.824 | L66: =$B66*100*(L$2<$A66)+100*(1+$B66)*(L$2=$A66) -> 0.4 | M66: =$B66*100*(M$2<$A66)+100*(1+$B66)*(M$2=$A66) -> 0.4 | N66: =$B66*100*(N$2<$A66)+100*(1+$B66)*(N$2=$A66) -> 0.4 | O66: =$B66*100*(O$2<$A66)+100*(1+$B66)*(O$2=$A66) -> 0.4 | P66: =$B66*100*(P$2<$A66)+100*(1+$B66)*(P$2=$A66) -> 0.4 | Q66: =$B66*100*(Q$2<$A66)+100*(1+$B66)*(Q$2=$A66) -> 0.4 | R66: =$B66*100*(R$2<$A66)+100*(1+$B66)*(R$2=$A66) -> 0.4 | S66: =$B66*100*(S$2<$A66)+100*(1+$B66)*(S$2=$A66) -> 0.4 | ... CK66: =$B66*100*(CK$2<$A66)+100*(1+$B66)*(CK$2=$A66) -> 0 | CN66: 31.5 | CO66: 0.05 | CP66: -0.0055569404 | CQ66: -0.0062752036 | CR66: 7.94302e-05 | CS66: =SUM(CO66:CR66) -> 0.038247286
CN67: 32 | CO67: 0.05 | CP67: -0.0054705137 | CQ67: -0.0061805018 | CR67: 7.8189103e-05 | CS67: =SUM(CO67:CR67) -> 0.038427174
CN68: 32.5 | CO68: 0.05 | CP68: -0.005386703 | CQ68: -0.0060883989 | CR68: 7.6986194e-05 | CS68: =SUM(CO68:CR68) -> 0.038601884
CN69: 33 | CO69: 0.05 | CP69: -0.0053053941 | CQ69: -0.0059988058 | CR69: 7.5819736e-05 | CS69: =SUM(CO69:CR69) -> 0.03877162
CN70: 33.5 | CO70: 0.05 | CP70: -0.0052264791 | CQ70: -0.005911636 | CR70: 7.4688098e-05 | CS70: =SUM(CO70:CR70) -> 0.038936573
CN71: 34 | CO71: 0.05 | CP71: -0.005149856 | CQ71: -0.005826806 | CR71: 7.3589744e-05 | CS71: =SUM(CO71:CR71) -> 0.039096928
CN72: 34.5 | CO72: 0.05 | CP72: -0.0050754283 | CQ72: -0.0057442347 | CR72: 7.2523226e-05 | CS72: =SUM(CO72:CR72) -> 0.03925286
CN73: 35 | CO73: 0.05 | CP73: -0.0050031047 | CQ73: -0.0056638441 | CR73: 7.148718e-05 | CS73: =SUM(CO73:CR73) -> 0.039404538
CN74: 35.5 | CO74: 0.05 | CP74: -0.0049327986 | CQ74: -0.0055855588 | CR74: 7.0480318e-05 | CS74: =SUM(CO74:CR74) -> 0.039552123
CN75: 36 | CO75: 0.05 | CP75: -0.0048644281 | CQ75: -0.0055093058 | CR75: 6.9501425e-05 | CS75: =SUM(CO75:CR75) -> 0.039695767
CN76: 36.5 | CO76: 0.05 | CP76: -0.0047979156 | CQ76: -0.0054350151 | CR76: 6.8549351e-05 | CS76: =SUM(CO76:CR76) -> 0.039835619
B77: INITIAL VALUES | C77: SOLVER VALUES | D77: INITIAL RESULTS | E77: SOLVER RESULTS | CN77: 37 | CO77: 0.05 | CP77: -0.0047331874 | CQ77: -0.0053626191 | CR77: 6.7623008e-05 | CS77: =SUM(CO77:CR77) -> 0.039971816
A78: b0 | B78: 0.05 | C78: 0.055604949 | D78: MAE (Price) | E78: MAE (Price) | I78: r(t) | J78: FITTED | K78: Spot | L78: =+b0_G+b1_G*((1-EXP(-L2/tau1_G))*tau1_G/L2)+b2_G*((1-EXP(-L2/tau1_G))*tau1_G/L2-EXP(-L2/tau1_G))+b3_G*((1-EXP(-L2/tau2_G))*tau2_G/L2-EXP(-L2/tau2_G)) -> 0.015529447 | M78: =+b0_G+b1_G*((1-EXP(-M2/tau1_G))*tau1_G/M2)+b2_G*((1-EXP(-M2/tau1_G))*tau1_G/M2-EXP(-M2/tau1_G)) -> 0.01472599 | N78: =+b0_G+b1_G*((1-EXP(-N2/tau1_G))*tau1_G/N2)+b2_G*((1-EXP(-N2/tau1_G))*tau1_G/N2-EXP(-N2/tau1_G)) -> 0.014879436 | O78: =+b0_G+b1_G*((1-EXP(-O2/tau1_G))*tau1_G/O2)+b2_G*((1-EXP(-O2/tau1_G))*tau1_G/O2-EXP(-O2/tau1_G)) -> 0.015171088 | P78: =+b0_G+b1_G*((1-EXP(-P2/tau1_G))*tau1_G/P2)+b2_G*((1-EXP(-P2/tau1_G))*tau1_G/P2-EXP(-P2/tau1_G)) -> 0.015577405 | Q78: =+b0_G+b1_G*((1-EXP(-Q2/tau1_G))*tau1_G/Q2)+b2_G*((1-EXP(-Q2/tau1_G))*tau1_G/Q2-EXP(-Q2/tau1_G)) -> 0.016077977 | R78: =+b0_G+b1_G*((1-EXP(-R2/tau1_G))*tau1_G/R2)+b2_G*((1-EXP(-R2/tau1_G))*tau1_G/R2-EXP(-R2/tau1_G)) -> 0.016655134 | S78: =+b0_G+b1_G*((1-EXP(-S2/tau1_G))*tau1_G/S2)+b2_G*((1-EXP(-S2/tau1_G))*tau1_G/S2-EXP(-S2/tau1_G)) -> 0.017293616 | T78: =+b0_G+b1_G*((1-EXP(-T2/tau1_G))*tau1_G/T2)+b2_G*((1-EXP(-T2/tau1_G))*tau1_G/T2-EXP(-T2/tau1_G)) -> 0.017980273 | ... CK78: =+b0_G+b1_G*((1-EXP(-CK2/tau1_G))*tau1_G/CK2)+b2_G*((1-EXP(-CK2/tau1_G))*tau1_G/CK2-EXP(-CK2/tau1_G)) -> 0.046023462 | CN78: 37.5 | CO78: 0.05 | CP78: -0.0046701736 | CQ78: -0.0052920527 | CR78: 6.6721368e-05 | CS78: =SUM(CO78:CR78) -> 0.040104495
A79: b1 | B79: -0.04 | C79: -0.040658782 | D79: 6.06 | E79: =AVERAGE(F3:F67) -> 0.33976706 | I79: d(t) | J79: Discount factor | L79: =+(1+L78)^(-L2) -> 0.99232456 | M79: =+(1+M78)^(-M2) -> 0.98548772 | N79: =+(1+N78)^(-N2) -> 0.97808888 | O79: =+(1+O78)^(-O2) -> 0.9703346 | P79: =+(1+P78)^(-P2) -> 0.96209382 | Q79: =+(1+Q78)^(-Q2) -> 0.9532765 | R79: =+(1+R78)^(-R2) -> 0.94382656 | S79: =+(1+S78)^(-S2) -> 0.93371583 | ... CK79: =+(1+CK78)^(-CK2) -> 0.1729356 | CN79: 38 | CO79: 0.05 | CP79: -0.0046088077 | CQ79: -0.0052232532 | CR79: 6.5843455e-05 | CS79: =SUM(CO79:CR79) -> 0.040233783
A80: b2 | B80: 0.05 | C80: -0.046139503 | D80: RMSE (Price) | E80: RMSE (Price) | I80: f(t) | J80: Forward | N80: =L79/N79-1 -> 0.014554587 | O80: =M79/O79-1 -> 0.01561638 | P80: =N79/P79-1 -> 0.016625259 | Q80: =O79/Q79-1 -> 0.017894186 | R80: =P79/R79-1 -> 0.019354461 | S80: =Q79/S79-1 -> 0.020949268 | T80: =R79/T79-1 -> 0.022631875 | U80: =S79/U79-1 -> 0.024364109 | ... CK80: =CI79/CK79-1 -> 0.055589908 | CN80: 38.5 | CO80: 0.05 | CP80: -0.0045490267 | CQ80: -0.0051561603 | CR80: 6.4988345e-05 | CS80: =SUM(CO80:CR80) -> 0.040359801
A81: b3 | B81: -0.05 | C81: 0.0035371483 | D81: 8.08 | E81: =SQRT(SUMSQ(E3:E67)/COUNT(E3:E67)) -> 0.45920723 | J81: Forward credit spread | N81: ='NSS Corporate'!N80-N80 -> 0.0038507626 | O81: ='NSS Corporate'!O80-O80 -> 0.0050934519 | P81: ='NSS Corporate'!P80-P80 -> 0.0058554488 | Q81: ='NSS Corporate'!Q80-Q80 -> 0.006272059 | R81: ='NSS Corporate'!R80-R80 -> 0.0064152642 | S81: ='NSS Corporate'!S80-S80 -> 0.0063450579 | T81: ='NSS Corporate'!T80-T80 -> 0.0061112423 | U81: ='NSS Corporate'!U80-U80 -> 0.0057549624 | ... CK81: ='NSS Corporate'!CK80-CK80 -> -0.0082685261 | CN81: 39 | CO81: 0.05 | CP81: -0.0044907705 | CQ81: -0.005090716 | CR81: 6.4155161e-05 | CS81: =SUM(CO81:CR81) -> 0.040482669
A82: t1 | B82: 5 | C82: 4.3080621 | D82: RMSE (Yield) | E82: RMSE (Yield) | J82: full forward formula | N82: =(((1+N78)^N2)/((1+L78)^L2))^(1/(N2-L2))-1 -> 0.014554587 | O82: =(((1+O78)^O2)/((1+M78)^M2))^(1/(O2-M2))-1 -> 0.01561638 | P82: =(((1+P78)^P2)/((1+N78)^N2))^(1/(P2-N2))-1 -> 0.016625259 | Q82: =(((1+Q78)^Q2)/((1+O78)^O2))^(1/(Q2-O2))-1 -> 0.017894186 | R82: =(((1+R78)^R2)/((1+P78)^P2))^(1/(R2-P2))-1 -> 0.019354461 | S82: =(((1+S78)^S2)/((1+Q78)^Q2))^(1/(S2-Q2))-1 -> 0.020949268 | T82: =(((1+T78)^T2)/((1+R78)^R2))^(1/(T2-R2))-1 -> 0.022631875 | U82: =(((1+U78)^U2)/((1+S78)^S2))^(1/(U2-S2))-1 -> 0.024364109 | ... CK82: =(((1+CK78)^CK2)/((1+CI78)^CI2))^(1/(CK2-CI2))-1 -> 0.055589908 | CN82: 39.5 | CO82: 0.05 | CP82: -0.0044339822 | CQ82: -0.0050268646 | CR82: 6.3343071e-05 | CS82: =SUM(CO82:CR82) -> 0.040602496
A83: t2 | B83: 10 | C83: 0.70736397 | D83: 6895.43 | E83: =SQRT(SUMSQ(I3:I67)/COUNT(I3:I67))*1000000 -> 936.42087 | CN83: 40 | CO83: 0.05 | CP83: -0.0043786074 | CQ83: -0.0049645525 | CR83: 6.2551282e-05 | CS83: =SUM(CO83:CR83) -> 0.040719391
D84: MAE (Yield) | E84: MAE (Yield) | CN84: 40.5 | CO84: 0.05 | CP84: -0.0043245945 | CQ84: -0.004903728 | CR84: 6.1779044e-05 | CS84: =SUM(CO84:CR84) -> 0.040833456
D85: 6293.98 | E85: {=AVERAGE(ABS(G3:G66-H3:H66))*1000000} -> 632.08316 | CN85: 41 | CO85: 0.05 | CP85: -0.0042718943 | CQ85: -0.0048443417 | CR85: 6.1025641e-05 | CS85: =SUM(CO85:CR85) -> 0.04094479
CN86: 41.5 | CO86: 0.05 | CP86: -0.0042204597 | CQ86: -0.0047863459 | CR86: 6.0290393e-05 | CS86: =SUM(CO86:CR86) -> 0.041053485
CN87: 42 | CO87: 0.05 | CP87: -0.0041702461 | CQ87: -0.0047296949 | CR87: 5.957265e-05 | CS87: =SUM(CO87:CR87) -> 0.041159632
CN88: 42.5 | CO88: 0.05 | CP88: -0.0041212107 | CQ88: -0.0046743446 | CR88: 5.8871795e-05 | CS88: =SUM(CO88:CR88) -> 0.041263316
CN89: 43 | CO89: 0.05 | CP89: -0.0040733128 | CQ89: -0.0046202529 | CR89: 5.8187239e-05 | CS89: =SUM(CO89:CR89) -> 0.041364622
...

Sheet DATA Corporate
A1: Instrument | B1: Name | C1: Ticker | D1: Country/Region | E1: Currency | F1: Maturity | G1: Coupon Type | H1: Coupon Frequency | I1: Coupon | J1: Ask Yield to Maturity | K1: Bid Yield to Maturity | L1: Ask Price | M1: Bid Price | N1: Identifier | O1: ISIN | P1: Bloomberg Composite Rating | Q1: Announce | R1: Next Coupon Settle Date | S1: Time | T1: AVG Price | U1: ID | V1: TIME rounded | W1: years ago | X1: Accrued Interest | Y1: Clean price | Z1: AVG yield
A2: BO356982 Corp | B2: Toyota Motor Corp | C2: TOYOTA | D2: JP | E2: JPY | F2: 18/03/2026 | G2: FIXED | H2: 2 | I2: 0.05 | J2: 1.477 | K2: 1.483 | L2: 99.98 | M2: 99.98 | N2: BO3569825 | O2: JP363340BM36 | P2: A+ | Q2: 12/03/2021 | R2: 18/03/2026 | S2: -0.0054757016 | T2: 99.98 | U2: 7 | V2: 0 | W2: 5 | X2: 0.050274725 | Y2: 99.929725 | Z2: 1.48
A3: BO356985 Corp | B3: Toyota Motor Corp | C3: TOYOTA | D3: JP | E3: JPY | F3: 27/03/2026 | G3: FIXED | H3: 2 | I3: 0.1 | J3: 1.173 | K3: 1.176 | L3: 99.958 | M3: 99.958 | N3: BO3569858 | O3: JP363340AM37 | P3: #N/A N/A | Q3: 12/03/2021 | R3: 27/03/2026 | S3: 0.019164956 | T3: 99.958 | U3: 6 | V3: 0 | W3: 5 | X3: 0.095604396 | Y3: 99.862396 | Z3: 1.1745
A4: BO579315 Corp | B4: Toyota Finance Corp | C4: TOYOTA | D4: JP | E4: JPY | F4: 15/04/2026 | G4: FIXED | H4: 2 | I4: 0.06 | J4: 1.099 | K4: 1.1 | L4: 99.906 | M4: 99.906 | N4: BO5793159 | O4: JP363360BM49 | P4: A+ | Q4: 09/04/2021 | R4: 15/04/2026 | S4: 0.07118412 | T4: 99.906 | U4: 31 | V4: 0 | W4: 5 | X4: 0.051428571 | Y4: 99.854571 | Z4: 1.0995
A5: LW169500 Corp | B5: Toyota Motor Corp | C5: TOYOTA | D5: JP | E5: JPY | F5: 03/06/2026 | G5: FIXED | H5: 2 | I5: 0.09 | J5: 0.864 | K5: 1.134 | L5: 99.826 | M5: 99.766 | N5: LW1695003 | O5: JP363340AG68 | P5: A+ | Q5: 27/05/2016 | R5: 03/06/2026 | S5: 0.20533881 | T5: 99.796 | U5: 3 | V5: 0 | W5: 10 | X5: 0.052912088 | Y5: 99.743088 | Z5: 0.999
A6: ZI885852 Corp | B6: Toyota Finance Corp | C6: TOYOTA | D6: JP | E6: JPY | F6: 13/10/2026 | G6: FIXED | H6: 2 | I6: 0.37 | J6: 1.163 | K6: 1.163 | L6: 99.538 | M6: 99.538 | N6: ZI8858527 | O6: JP363360APA1 | P6: A+ | Q6: 06/10/2023 | R6: 13/04/2026 | S6: 0.56673511 | T6: 99.538 | U6: 2 | V6: 0.5 | W6: 3 | X6: 0.32120879 | Y6: 99.216791 | Z6: 1.163
A7: YT821868 Corp | B7: Toyota Finance Corp | C7: TOYOTA | D7: JP | E7: JPY | F7: 11/12/2026 | G7: FIXED | H7: 2 | I7: 0.773 | J7: 1.014 | K7: 1.214 | L7: 99.821 | M7: 99.673 | N7: YT8218687 | O7: JP363360AQQ5 | P7: #N/A N/A | Q7: 06/12/2024 | R7: 12/06/2026 | S7: 0.72826831 | T7: 99.747 | U7: 18 | V7: 0.5 | W7: 2 | X7: 0.41623077 | Y7: 99.330769 | Z7: 1.114
A8: ZD637368 Corp | B8: Toyota Finance Corp | C8: TOYOTA | D8: JP | E8: JPY | F8: 09/04/2027 | G8: FIXED | H8: 2 | I8: 0.414 | J8: 1.259 | K8: 1.281 | L8: 99.104 | M8: 99.081 | N8: ZD6373686 | O8: JP363360AQ46 | P8: A+ | Q8: 05/04/2024 | R8: 10/04/2026 | S8: 1.0540726 | T8: 99.0925 | U8: 26 | V8: 1 | W8: 2 | X8: 0.36623077 | Y8: 98.726269 | Z8: 1.27
A9: AN666209 Corp | B9: Toyota Motor Corp | C9: TOYOTA | D9: JP | E9: JPY | F9: 02/06/2027 | G9: FIXED | H9: 2 | I9: 0.22 | J9: 1.274 | K9: 1.292 | L9: 98.73 | M9: 98.709 | N9: AN6662091 | O9: JP363340CH65 | P9: A+ | Q9: 26/05/2017 | R9: 02/06/2026 | S9: 1.2019165 | T9: 98.7195 | U9: 15 | V9: 1 | W9: 9 | X9: 0.13054945 | Y9: 98.588951 | Z9: 1.283
A10: BW601098 Corp | B10: Toyota Motor Corp | C10: TOYOTA | D10: JP | E10: JPY | F10: 02/06/2027 | G10: FIXED | H10: 2 | I10: 0.11 | J10: 1.273 | K10: 1.291 | L10: 98.599 | M10: 98.578 | N10: BW6010985 | O10: JP363340AN69 | P10: A+ | Q10: 27/05/2022 | R10: 02/06/2026 | S10: 1.2019165 | T10: 98.5885 | U10: 32 | V10: 1 | W10: 4 | X10: 0.065274725 | Y10: 98.523225 | Z10: 1.282
A11: YN599739 Corp | B11: Toyota Finance Corp | C11: TOYOTA | D11: JP | E11: JPY | F11: 22/07/2027 | G11: FIXED | H11: 2 | I11: 0.966 | J11: 1.34 | K11: 1.354 | L11: 99.5 | M11: 99.482 | N11: YN5997393 | O11: JP363360AR78 | P11: A+ | Q11: 15/07/2025 | R11: 22/07/2026 | S11: 1.338809 | T11: 99.491 | U11: 11 | V11: 1 | W11: 1 | X11: 0.30253846 | Y11: 99.188462 | Z11: 1.347
A12: AO295977 Corp | B12: Toyota Finance Corp | C12: TOYOTA | D12: JP | E12: JPY | F12: 23/07/2027 | G12: FIXED | H12: 2 | I12: 0.265 | J12: 1.346 | K12: 1.36 | L12: 98.553 | M12: 98.534 | N12: AO2959770 | O12: JP363360CH78 | P12: A+ | Q12: 14/07/2017 | R12: 24/07/2026 | S12: 1.3415469 | T12: 98.5435 | U12: 29 | V12: 1 | W12: 9 | X12: 0.080082418 | Y12: 98.463418 | Z12: 1.353
A13: YV792963 Corp | B13: Toyota Finance Corp | C13: TOYOTA | D13: JP | E13: JPY | F13: 08/10/2027 | G13: FIXED | H13: 2 | I13: 0.573 | J13: 1.406 | K13: 1.421 | L13: 98.716 | M13: 98.694 | N13: YV7929636 | O13: JP363360AQA9 | P13: A+ | Q13: 04/10/2024 | R13: 10/04/2026 | S13: 1.5523614 | T13: 98.705 | U13: 24 | V13: 1.5 | W13: 2 | X13: 0.50688462 | Y13: 98.198115 | Z13: 1.4135
... A38: AN666227 Corp | B38: Toyota Motor Corp | C38: TOYOTA | D38: JP | E38: JPY | F38: 02/06/2037 | G38: FIXED | H38: 2 | I38: 0.651 | J38: 2.962 | K38: 2.962 | L38: 80.535 | M38: 80.535 | N38: AN6662273 | O38: JP363340DH64 | P38: A+ | Q38: 26/05/2017 | R38: 02/06/2026 | S38: 11.203285 | T38: 80.535 | U38: 4 | V38: 11 | W38: 9 | X38: 0.38630769 | Y38: 80.148692 | Z38: 2.962

Sheet NSS Corporate
A1: Maturity | B1: Coupon | C1: Market Price | D1: Model Price | E1: Error | F1: Abs Error | G1: Yield | H1: Yield Model | I1: Yield Error | J1: - prices | K1: Cash flows | CN1: FITTED VISUALISATION
K2: {=_xlfn.SEQUENCE(1,79,0,0.5)} -> 0 | L2: 0.5 | M2: 1 | N2: 1.5 | O2: 2 | P2: 2.5 | Q2: 3 | R2: 3.5 | S2: 4 | T2: 4.5 | U2: 5 | V2: 5.5 | W2: 6 | X2: 6.5 | Y2: 7 | Z2: 7.5 | AA2: 8 | AB2: 8.5 | AC2: 9 | AD2: 9.5 | AE2: 10 | AF2: 10.5 | AG2: 11 | AH2: 11.5 | AI2: 12 | AJ2: 12.5 | AK2: 13 | AL2: 13.5 | AM2: 14 | AN2: 14.5 | AO2: 15 | AP2: 15.5 | AQ2: 16 | AR2: 16.5 | AS2: 17 | AT2: 17.5 | AU2: 18 | AV2: 18.5 | AW2: 19 | AX2: 19.5 | AY2: 20 | AZ2: 20.5 | BA2: 21 | BB2: 21.5 | BC2: 22 | BD2: 22.5 | BE2: 23 | BF2: 23.5 | BG2: 24 | BH2: 24.5 | BI2: 25 | BJ2: 25.5 | BK2: 26 | BL2: 26.5 | BM2: 27 | BN2: 27.5 | BO2: 28 | BP2: 28.5 | BQ2: 29 | BR2: 29.5 | BS2: 30 | BT2: 30.5 | BU2: 31 | BV2: 31.5 | BW2: 32 | BX2: 32.5 | BY2: 33 | BZ2: 33.5 | CA2: 34 | CB2: 34.5 | CC2: 35 | CD2: 35.5 | CE2: 36 | CF2: 36.5 | CG2: 37 | CH2: 37.5 | CI2: 38 | CJ2: 38.5 | CK2: 39 | CN2: Time discretization | CO2: Long term spot | CP2: Time decay | CQ2: First hump | CR2: Second hump | CS2: Total
A3: 0.5 | B3: 0.0037 | C3: 99.538 | D3: =SUMPRODUCT(L3:CK3,$L$79:$CK$79) -> 99.537994 | E3: =+D3-C3 -> -5.9927328e-06 | F3: =ABS(C3-D3) -> 5.9927328e-06 | G3: =+IFERROR(IRR(K3:CK3,0),0) -> 0.0083586168 | H3: =IFERROR(IRR((J3,L3:CK3),0),0) -> 0.0083586775 | I3: =IFERROR(H3-G3,0) -> 6.0708715e-08 | J3: =-D3 -> -99.537994 | K3: =-C3 -> -99.538 | L3: =$B3*100*(L$2<$A3)+100*(1+$B3)*(L$2=$A3) -> 100.37 | M3: =$B3*100*(M$2<$A3)+100*(1+$B3)*(M$2=$A3) -> 0 | N3: =$B3*100*(N$2<$A3)+100*(1+$B3)*(N$2=$A3) -> 0 | O3: =$B3*100*(O$2<$A3)+100*(1+$B3)*(O$2=$A3) -> 0 | P3: =$B3*100*(P$2<$A3)+100*(1+$B3)*(P$2=$A3) -> 0 | Q3: =$B3*100*(Q$2<$A3)+100*(1+$B3)*(Q$2=$A3) -> 0 | R3: =$B3*100*(R$2<$A3)+100*(1+$B3)*(R$2=$A3) -> 0 | S3: =$B3*100*(S$2<$A3)+100*(1+$B3)*(S$2=$A3) -> 0 | ... CK3: =$B3*100*(CK$2<$A3)+100*(1+$B3)*(CK$2=$A3) -> 0 | CN3: 1e-06 | CO3: =b0_c -> 0.036780013 | CP3: =b1_c*(1-EXP(-CN3/tau1_c))/(CN3/tau1_c) -> -0.021912017 | CQ3: =b2_c*((1-EXP(-CN3/tau1_c))/(CN3/tau1_c)-EXP(-CN3/tau1_c)) -> 1.4819519e-09 | CR3: =+b3_c*((1-EXP(-CN3/tau2_c))/(CN3/tau2_c)-EXP(-CN3/tau2_c)) -> 2.0944027e-09 | CS3: =SUM(CO3:CR3) -> 0.014868
A4: 1 | B4: 0.00414 | C4: 99.0925 | D4: =SUMPRODUCT(L4:CK4,$L$79:$CK$79) -> 99.155932 | E4: =+D4-C4 -> 0.06343152 | F4: =ABS(C4-D4) -> 0.06343152 | G4: =+IFERROR(IRR(K4:CK4,0),0) -> 0.0087370528 | H4: =IFERROR(IRR((J4,L4:CK4),0),0) -> 0.0084136797 | I4: =IFERROR(H4-G4,0) -> -0.00032337309 | J4: =-D4 -> -99.155932 | K4: =-C4 -> -99.0925 | L4: =$B4*100*(L$2<$A4)+100*(1+$B4)*(L$2=$A4) -> 0.414 | M4: =$B4*100*(M$2<$A4)+100*(1+$B4)*(M$2=$A4) -> 100.414 | N4: =$B4*100*(N$2<$A4)+100*(1+$B4)*(N$2=$A4) -> 0 | O4: =$B4*100*(O$2<$A4)+100*(1+$B4)*(O$2=$A4) -> 0 | P4: =$B4*100*(P$2<$A4)+100*(1+$B4)*(P$2=$A4) -> 0 | Q4: =$B4*100*(Q$2<$A4)+100*(1+$B4)*(Q$2=$A4) -> 0 | R4: =$B4*100*(R$2<$A4)+100*(1+$B4)*(R$2=$A4) -> 0 | S4: =$B4*100*(S$2<$A4)+100*(1+$B4)*(S$2=$A4) -> 0 | ... CK4: =$B4*100*(CK$2<$A4)+100*(1+$B4)*(CK$2=$A4) -> 0 | CN4: {=_xlfn.SEQUENCE(500,,0.5,0.5)} -> 0.5 | CO4: {=_xlfn.ANCHORARRAY(CN4)-_xlfn.ANCHORARRAY(CN4)+CO3} -> 0.036780013 | CP4: {=b1_c*(1-EXP(-_xlfn.ANCHORARRAY(CN4)/tau1_c))/(_xlfn.ANCHORARRAY(CN4)/tau1_c)} -> -0.021606522 | CQ4: {=b2_c*((1-EXP(-_xlfn.ANCHORARRAY(CN4)/tau1_c))/(_xlfn.ANCHORARRAY(CN4)/tau1_c)-EXP(-_xlfn.ANCHORARRAY(CN4)/tau1_c))} -> 0.0007259782 | CR4: {=+b3_c*((1-EXP(-_xlfn.ANCHORARRAY(CN4)/tau2_c))/(_xlfn.ANCHORARRAY(CN4)/tau2_c)-EXP(-_xlfn.ANCHORARRAY(CN4)/tau2_c))} -> 0.00088775393 | CS4: =SUM(CO4:CR4) -> 0.016787223
A5: 1 | B5: 0.0022 | C5: 98.7195 | D5: =SUMPRODUCT(L5:CK5,$L$79:$CK$79) -> 98.772763 | E5: =+D5-C5 -> 0.05326347 | F5: =ABS(C5-D5) -> 0.05326347 | G5: =+IFERROR(IRR(K5:CK5,0),0) -> 0.0086860388 | H5: =IFERROR(IRR((J5,L5:CK5),0),0) -> 0.0084137331 | I5: =IFERROR(H5-G5,0) -> -0.00027230569 | J5: =-D5 -> -98.772763 | K5: =-C5 -> -98.7195 | L5: =$B5*100*(L$2<$A5)+100*(1+$B5)*(L$2=$A5) -> 0.22 | M5: =$B5*100*(M$2<$A5)+100*(1+$B5)*(M$2=$A5) -> 100.22 | N5: =$B5*100*(N$2<$A5)+100*(1+$B5)*(N$2=$A5) -> 0 | O5: =$B5*100*(O$2<$A5)+100*(1+$B5)*(O$2=$A5) -> 0 | P5: =$B5*100*(P$2<$A5)+100*(1+$B5)*(P$2=$A5) -> 0 | Q5: =$B5*100*(Q$2<$A5)+100*(1+$B5)*(Q$2=$A5) -> 0 | R5: =$B5*100*(R$2<$A5)+100*(1+$B5)*(R$2=$A5) -> 0 | S5: =$B5*100*(S$2<$A5)+100*(1+$B5)*(S$2=$A5) -> 0 | ... CK5: =$B5*100*(CK$2<$A5)+100*(1+$B5)*(CK$2=$A5) -> 0 | CN5: 1 | CO5: 0.036780013 | CP5: -0.021306693 | CQ5: 0.0014250602 | CR5: 0.0017609214 | CS5: =SUM(CO5:CR5) -> 0.018659301
A6: 1 | B6: 0.0011 | C6: 98.5885 | D6: =SUMPRODUCT(L6:CK6,$L$79:$CK$79) -> 98.555503 | E6: =+D6-C6 -> -0.032996764 | F6: =ABS(C6-D6) -> 0.032996764 | G6: =+IFERROR(IRR(K6:CK6,0),0) -> 0.008244902 | H6: =IFERROR(IRR((J6,L6:CK6),0),0) -> 0.0084137635 | I6: =IFERROR(H6-G6,0) -> 0.00016886147 | J6: =-D6 -> -98.555503 | K6: =-C6 -> -98.5885 | L6: =$B6*100*(L$2<$A6)+100*(1+$B6)*(L$2=$A6) -> 0.11 | M6: =$B6*100*(M$2<$A6)+100*(1+$B6)*(M$2=$A6) -> 100.11 | N6: =$B6*100*(N$2<$A6)+100*(1+$B6)*(N$2=$A6) -> 0 | O6: =$B6*100*(O$2<$A6)+100*(1+$B6)*(O$2=$A6) -> 0 | P6: =$B6*100*(P$2<$A6)+100*(1+$B6)*(P$2=$A6) -> 0 | Q6: =$B6*100*(Q$2<$A6)+100*(1+$B6)*(Q$2=$A6) -> 0 | R6: =$B6*100*(R$2<$A6)+100*(1+$B6)*(R$2=$A6) -> 0 | S6: =$B6*100*(S$2<$A6)+100*(1+$B6)*(S$2=$A6) -> 0 | ... CK6: =$B6*100*(CK$2<$A6)+100*(1+$B6)*(CK$2=$A6) -> 0 | CN6: 1.5 | CO6: 0.036780013 | CP6: -0.021012411 | CQ6: 0.0020980865 | CR6: 0.0026197045 | CS6: =SUM(CO6:CR6) -> 0.020485393
A7: 1 | B7: 0.00265 | C7: 98.5435 | D7: =SUMPRODUCT(L7:CK7,$L$79:$CK$79) -> 98.861643 | E7: =+D7-C7 -> 0.31814266 | F7: =ABS(C7-D7) -> 0.31814266 | G7: =+IFERROR(IRR(K7:CK7,0),0) -> 0.010042383 | H7: =IFERROR(IRR((J7,L7:CK7),0),0) -> 0.0084137207 | I7: =IFERROR(H7-G7,0) -> -0.0016286625 | J7: =-D7 -> -98.861643 | K7: =-C7 -> -98.5435 | L7: =$B7*100*(L$2<$A7)+100*(1+$B7)*(L$2=$A7) -> 0.265 | M7: =$B7*100*(M$2<$A7)+100*(1+$B7)*(M$2=$A7) -> 100.265 | N7: =$B7*100*(N$2<$A7)+100*(1+$B7)*(N$2=$A7) -> 0 | O7: =$B7*100*(O$2<$A7)+100*(1+$B7)*(O$2=$A7) -> 0 | P7: =$B7*100*(P$2<$A7)+100*(1+$B7)*(P$2=$A7) -> 0 | Q7: =$B7*100*(Q$2<$A7)+100*(1+$B7)*(Q$2=$A7) -> 0 | R7: =$B7*100*(R$2<$A7)+100*(1+$B7)*(R$2=$A7) -> 0 | S7: =$B7*100*(S$2<$A7)+100*(1+$B7)*(S$2=$A7) -> 0 | ... CK7: =$B7*100*(CK$2<$A7)+100*(1+$B7)*(CK$2=$A7) -> 0 | CN7: 2 | CO7: 0.036780013 | CP7: -0.020723561 | CQ7: 0.0027458725 | CR7: 0.0034643028 | CS7: =SUM(CO7:CR7) -> 0.022266627
A8: 1.5 | B8: 0.00385 | C8: 98.3625 | D8: =SUMPRODUCT(L8:CK8,$L$79:$CK$79) -> 98.51409 | E8: =+D8-C8 -> 0.15158984 | F8: =ABS(C8-D8) -> 0.15158984 | G8: =+IFERROR(IRR(K8:CK8,0),0) -> 0.0094113952 | H8: =IFERROR(IRR((J8,L8:CK8),0),0) -> 0.0088913723 | I8: =IFERROR(H8-G8,0) -> -0.00052002291 | J8: =-D8 -> -98.51409 | K8: =-C8 -> -98.3625 | L8: =$B8*100*(L$2<$A8)+100*(1+$B8)*(L$2=$A8) -> 0.385 | M8: =$B8*100*(M$2<$A8)+100*(1+$B8)*(M$2=$A8) -> 0.385 | N8: =$B8*100*(N$2<$A8)+100*(1+$B8)*(N$2=$A8) -> 100.385 | O8: =$B8*100*(O$2<$A8)+100*(1+$B8)*(O$2=$A8) -> 0 | P8: =$B8*100*(P$2<$A8)+100*(1+$B8)*(P$2=$A8) -> 0 | Q8: =$B8*100*(Q$2<$A8)+100*(1+$B8)*(Q$2=$A8) -> 0 | R8: =$B8*100*(R$2<$A8)+100*(1+$B8)*(R$2=$A8) -> 0 | S8: =$B8*100*(S$2<$A8)+100*(1+$B8)*(S$2=$A8) -> 0 | ... CK8: =$B8*100*(CK$2<$A8)+100*(1+$B8)*(CK$2=$A8) -> 0 | CN8: 2.5 | CO8: 0.036780013 | CP8: -0.020440031 | CQ8: 0.0033692094 | CR8: 0.0042949132 | CS8: =SUM(CO8:CR8) -> 0.024004104
A9: 1.5 | B9: 0.00265 | C9: 98.172 | D9: =SUMPRODUCT(L9:CK9,$L$79:$CK$79) -> 98.160224 | E9: =+D9-C9 -> -0.01177585 | F9: =ABS(C9-D9) -> 0.01177585 | G9: =+IFERROR(IRR(K9:CK9,0),0) -> 0.0088515207 | H9: =IFERROR(IRR((J9,L9:CK9),0),0) -> 0.0088919695 | I9: =IFERROR(H9-G9,0) -> 4.0448795e-05 | J9: =-D9 -> -98.160224 | K9: =-C9 -> -98.172 | L9: =$B9*100*(L$2<$A9)+100*(1+$B9)*(L$2=$A9) -> 0.265 | M9: =$B9*100*(M$2<$A9)+100*(1+$B9)*(M$2=$A9) -> 0.265 | N9: =$B9*100*(N$2<$A9)+100*(1+$B9)*(N$2=$A9) -> 100.265 | O9: =$B9*100*(O$2<$A9)+100*(1+$B9)*(O$2=$A9) -> 0 | P9: =$B9*100*(P$2<$A9)+100*(1+$B9)*(P$2=$A9) -> 0 | Q9: =$B9*100*(Q$2<$A9)+100*(1+$B9)*(Q$2=$A9) -> 0 | R9: =$B9*100*(R$2<$A9)+100*(1+$B9)*(R$2=$A9) -> 0 | S9: =$B9*100*(S$2<$A9)+100*(1+$B9)*(S$2=$A9) -> 0 | ... CK9: =$B9*100*(CK$2<$A9)+100*(1+$B9)*(CK$2=$A9) -> 0 | CN9: 3 | CO9: 0.036780013 | CP9: -0.020161709 | CQ9: 0.0039688652 | CR9: 0.0051117301 | CS9: =SUM(CO9:CR9) -> 0.025698899
A10: 2 | B10: 0.0033 | C10: 97.514 | D10: =SUMPRODUCT(L10:CK10,$L$79:$CK$79) -> 97.634058 | E10: =+D10-C10 -> 0.12005826 | F10: =ABS(C10-D10) -> 0.12005826 | G10: =+IFERROR(IRR(K10:CK10,0),0) -> 0.0096659063 | H10: =IFERROR(IRR((J10,L10:CK10),0),0) -> 0.0093538143 | I10: =IFERROR(H10-G10,0) -> -0.000312092 | J10: =-D10 -> -97.634058 | K10: =-C10 -> -97.514 | L10: =$B10*100*(L$2<$A10)+100*(1+$B10)*(L$2=$A10) -> 0.33 | M10: =$B10*100*(M$2<$A10)+100*(1+$B10)*(M$2=$A10) -> 0.33 | N10: =$B10*100*(N$2<$A10)+100*(1+$B10)*(N$2=$A10) -> 0.33 | O10: =$B10*100*(O$2<$A10)+100*(1+$B10)*(O$2=$A10) -> 100.33 | P10: =$B10*100*(P$2<$A10)+100*(1+$B10)*(P$2=$A10) -> 0 | Q10: =$B10*100*(Q$2<$A10)+100*(1+$B10)*(Q$2=$A10) -> 0 | R10: =$B10*100*(R$2<$A10)+100*(1+$B10)*(R$2=$A10) -> 0 | S10: =$B10*100*(S$2<$A10)+100*(1+$B10)*(S$2=$A10) -> 0 | ... CK10: =$B10*100*(CK$2<$A10)+100*(1+$B10)*(CK$2=$A10) -> 0 | CN10: 3.5 | CO10: 0.036780013 | CP10: -0.019888488 | CQ10: 0.0045455848 | CR10: 0.0059149451 | CS10: =SUM(CO10:CR10) -> 0.027352054
A11: 2.5 | B11: 0.00319 | C11: 96.854 | D11: =SUMPRODUCT(L11:CK11,$L$79:$CK$79) -> 96.789594 | E11: =+D11-C11 -> -0.064405934 | F11: =ABS(C11-D11) -> 0.064405934 | G11: =+IFERROR(IRR(K11:CK11,0),0) -> 0.0096656182 | H11: =IFERROR(IRR((J11,L11:CK11),0),0) -> 0.0098008271 | I11: =IFERROR(H11-G11,0) -> 0.00013520897 | J11: =-D11 -> -96.789594 | K11: =-C11 -> -96.854 | L11: =$B11*100*(L$2<$A11)+100*(1+$B11)*(L$2=$A11) -> 0.319 | M11: =$B11*100*(M$2<$A11)+100*(1+$B11)*(M$2=$A11) -> 0.319 | N11: =$B11*100*(N$2<$A11)+100*(1+$B11)*(N$2=$A11) -> 0.319 | O11: =$B11*100*(O$2<$A11)+100*(1+$B11)*(O$2=$A11) -> 0.319 | P11: =$B11*100*(P$2<$A11)+100*(1+$B11)*(P$2=$A11) -> 100.319 | Q11: =$B11*100*(Q$2<$A11)+100*(1+$B11)*(Q$2=$A11) -> 0 | R11: =$B11*100*(R$2<$A11)+100*(1+$B11)*(R$2=$A11) -> 0 | S11: =$B11*100*(S$2<$A11)+100*(1+$B11)*(S$2=$A11) -> 0 | ... CK11: =$B11*100*(CK$2<$A11)+100*(1+$B11)*(CK$2=$A11) -> 0 | CN11: 4 | CO11: 0.036780013 | CP11: -0.019620263 | CQ11: 0.0051000912 | CR11: 0.0067047475 | CS11: =SUM(CO11:CR11) -> 0.028964589
A12: 3 | B12: 0.0015 | C12: 95.4175 | D12: =SUMPRODUCT(L12:CK12,$L$79:$CK$79) -> 94.940492 | E12: =+D12-C12 -> -0.47700753 | F12: =ABS(C12-D12) -> 0.47700753 | G12: =+IFERROR(IRR(K12:CK12,0),0) -> 0.0093904742 | H12: =IFERROR(IRR((J12,L12:CK12),0),0) -> 0.010237216 | I12: =IFERROR(H12-G12,0) -> 0.00084674176 | J12: =-D12 -> -94.940492 | K12: =-C12 -> -95.4175 | L12: =$B12*100*(L$2<$A12)+100*(1+$B12)*(L$2=$A12) -> 0.15 | M12: =$B12*100*(M$2<$A12)+100*(1+$B12)*(M$2=$A12) -> 0.15 | N12: =$B12*100*(N$2<$A12)+100*(1+$B12)*(N$2=$A12) -> 0.15 | O12: =$B12*100*(O$2<$A12)+100*(1+$B12)*(O$2=$A12) -> 0.15 | P12: =$B12*100*(P$2<$A12)+100*(1+$B12)*(P$2=$A12) -> 0.15 | Q12: =$B12*100*(Q$2<$A12)+100*(1+$B12)*(Q$2=$A12) -> 100.15 | R12: =$B12*100*(R$2<$A12)+100*(1+$B12)*(R$2=$A12) -> 0 | S12: =$B12*100*(S$2<$A12)+100*(1+$B12)*(S$2=$A12) -> 0 | ... CK12: =$B12*100*(CK$2<$A12)+100*(1+$B12)*(CK$2=$A12) -> 0 | CN12: 4.5 | CO12: 0.036780013 | CP12: -0.019356929 | CQ12: 0.0056330858 | CR12: 0.007481324 | CS12: =SUM(CO12:CR12) -> 0.030537494
A13: 4.5 | B13: 0.00219 | C13: 91.959 | D13: =SUMPRODUCT(L13:CK13,$L$79:$CK$79) -> 92.123966 | E13: =+D13-C13 -> 0.16496619 | F13: =ABS(C13-D13) -> 0.16496619 | G13: =+IFERROR(IRR(K13:CK13,0),0) -> 0.011653052 | H13: =IFERROR(IRR((J13,L13:CK13),0),0) -> 0.011449744 | I13: =IFERROR(H13-G13,0) -> -0.00020330796 | J13: =-D13 -> -92.123966 | K13: =-C13 -> -91.959 | L13: =$B13*100*(L$2<$A13)+100*(1+$B13)*(L$2=$A13) -> 0.219 | M13: =$B13*100*(M$2<$A13)+100*(1+$B13)*(M$2=$A13) -> 0.219 | N13: =$B13*100*(N$2<$A13)+100*(1+$B13)*(N$2=$A13) -> 0.219 | O13: =$B13*100*(O$2<$A13)+100*(1+$B13)*(O$2=$A13) -> 0.219 | P13: =$B13*100*(P$2<$A13)+100*(1+$B13)*(P$2=$A13) -> 0.219 | Q13: =$B13*100*(Q$2<$A13)+100*(1+$B13)*(Q$2=$A13) -> 0.219 | R13: =$B13*100*(R$2<$A13)+100*(1+$B13)*(R$2=$A13) -> 0.219 | S13: =$B13*100*(S$2<$A13)+100*(1+$B13)*(S$2=$A13) -> 0.219 | ... CK13: =$B13*100*(CK$2<$A13)+100*(1+$B13)*(CK$2=$A13) -> 0 | CN13: 5 | CO13: 0.036780013 | CP13: -0.019098386 | CQ13: 0.0061452492 | CR13: 0.008244859 | CS13: =SUM(CO13:CR13) -> 0.032071735
A14: 6 | B14: 0.00324 | C14: 89.954 | D14: =SUMPRODUCT(L14:CK14,$L$79:$CK$79) -> 89.702502 | E14: =+D14-C14 -> -0.25149772 | F14: =ABS(C14-D14) -> 0.25149772 | G14: =+IFERROR(IRR(K14:CK14,0),0) -> 0.012295735 | H14: =IFERROR(IRR((J14,L14:CK14),0),0) -> 0.012536475 | I14: =IFERROR(H14-G14,0) -> 0.00024074008 | J14: =-D14 -> -89.702502 | K14: =-C14 -> -89.954 | L14: =$B14*100*(L$2<$A14)+100*(1+$B14)*(L$2=$A14) -> 0.324 | M14: =$B14*100*(M$2<$A14)+100*(1+$B14)*(M$2=$A14) -> 0.324 | N14: =$B14*100*(N$2<$A14)+100*(1+$B14)*(N$2=$A14) -> 0.324 | O14: =$B14*100*(O$2<$A14)+100*(1+$B14)*(O$2=$A14) -> 0.324 | P14: =$B14*100*(P$2<$A14)+100*(1+$B14)*(P$2=$A14) -> 0.324 | Q14: =$B14*100*(Q$2<$A14)+100*(1+$B14)*(Q$2=$A14) -> 0.324 | R14: =$B14*100*(R$2<$A14)+100*(1+$B14)*(R$2=$A14) -> 0.324 | S14: =$B14*100*(S$2<$A14)+100*(1+$B14)*(S$2=$A14) -> 0.324 | ... CK14: =$B14*100*(CK$2<$A14)+100*(1+$B14)*(CK$2=$A14) -> 0 | CN14: 5.5 | CO14: 0.036780013 | CP14: -0.018844536 | CQ14: 0.0066372416 | CR14: 0.0089955342 | CS14: =SUM(CO14:CR14) -> 0.033568253
A15: 10 | B15: 0.00343 | C15: 80.22 | D15: =SUMPRODUCT(L15:CK15,$L$79:$CK$79) -> 80.220009 | E15: =+D15-C15 -> 9.2599972e-06 | F15: =ABS(C15-D15) -> 9.2599972e-06 | G15: =+IFERROR(IRR(K15:CK15,0),0) -> 0.01494473 | H15: =IFERROR(IRR((J15,L15:CK15),0),0) -> 0.014944724 | I15: =IFERROR(H15-G15,0) -> -6.0810363e-09 | J15: =-D15 -> -80.220009 | K15: =-C15 -> -80.22 | L15: =$B15*100*(L$2<$A15)+100*(1+$B15)*(L$2=$A15) -> 0.343 | M15: =$B15*100*(M$2<$A15)+100*(1+$B15)*(M$2=$A15) -> 0.343 | N15: =$B15*100*(N$2<$A15)+100*(1+$B15)*(N$2=$A15) -> 0.343 | O15: =$B15*100*(O$2<$A15)+100*(1+$B15)*(O$2=$A15) -> 0.343 | P15: =$B15*100*(P$2<$A15)+100*(1+$B15)*(P$2=$A15) -> 0.343 | Q15: =$B15*100*(Q$2<$A15)+100*(1+$B15)*(Q$2=$A15) -> 0.343 | R15: =$B15*100*(R$2<$A15)+100*(1+$B15)*(R$2=$A15) -> 0.343 | S15: =$B15*100*(S$2<$A15)+100*(1+$B15)*(S$2=$A15) -> 0.343 | ... CK15: =$B15*100*(CK$2<$A15)+100*(1+$B15)*(CK$2=$A15) -> 0 | CN15: 6 | CO15: 0.036780013 | CP15: -0.018595281 | CQ15: 0.0071097037 | CR15: 0.0097335292 | CS15: =SUM(CO15:CR15) -> 0.035027964
D16: =SUMPRODUCT(L16:CK16,$L$79:$CK$79) -> 0 | E16: =+D16-C16 -> 0 | F16: =ABS(C16-D16) -> 0 | G16: =+IFERROR(IRR(K16:CK16,0),0) -> 0 | H16: =IFERROR(IRR((J16,L16:CK16),0),0) -> 0 | I16: =IFERROR(H16-G16,0) -> 0 | J16: =-D16 -> 0 | K16: =-C16 -> 0 | L16: =$B16*100*(L$2<$A16)+100*(1+$B16)*(L$2=$A16) -> 0 | M16: =$B16*100*(M$2<$A16)+100*(1+$B16)*(M$2=$A16) -> 0 | N16: =$B16*100*(N$2<$A16)+100*(1+$B16)*(N$2=$A16) -> 0 | O16: =$B16*100*(O$2<$A16)+100*(1+$B16)*(O$2=$A16) -> 0 | P16: =$B16*100*(P$2<$A16)+100*(1+$B16)*(P$2=$A16) -> 0 | Q16: =$B16*100*(Q$2<$A16)+100*(1+$B16)*(Q$2=$A16) -> 0 | R16: =$B16*100*(R$2<$A16)+100*(1+$B16)*(R$2=$A16) -> 0 | S16: =$B16*100*(S$2<$A16)+100*(1+$B16)*(S$2=$A16) -> 0 | ... CK16: =$B16*100*(CK$2<$A16)+100*(1+$B16)*(CK$2=$A16) -> 0 | CN16: 6.5 | CO16: 0.036780013 | CP16: -0.018350528 | CQ16: 0.007563257 | CR16: 0.010459021 | CS16: =SUM(CO16:CR16) -> 0.036451762
D17: =SUMPRODUCT(L17:CK17,$L$79:$CK$79) -> 0 | E17: =+D17-C17 -> 0 | F17: =ABS(C17-D17) -> 0 | G17: =+IFERROR(IRR(K17:CK17,0),0) -> 0 | H17: =IFERROR(IRR((J17,L17:CK17),0),0) -> 0 | I17: =IFERROR(H17-G17,0) -> 0 | J17: =-D17 -> 0 | K17: =-C17 -> 0 | L17: =$B17*100*(L$2<$A17)+100*(1+$B17)*(L$2=$A17) -> 0 | M17: =$B17*100*(M$2<$A17)+100*(1+$B17)*(M$2=$A17) -> 0 | N17: =$B17*100*(N$2<$A17)+100*(1+$B17)*(N$2=$A17) -> 0 | O17: =$B17*100*(O$2<$A17)+100*(1+$B17)*(O$2=$A17) -> 0 | P17: =$B17*100*(P$2<$A17)+100*(1+$B17)*(P$2=$A17) -> 0 | Q17: =$B17*100*(Q$2<$A17)+100*(1+$B17)*(Q$2=$A17) -> 0 | R17: =$B17*100*(R$2<$A17)+100*(1+$B17)*(R$2=$A17) -> 0 | S17: =$B17*100*(S$2<$A17)+100*(1+$B17)*(S$2=$A17) -> 0 | ... CK17: =$B17*100*(CK$2<$A17)+100*(1+$B17)*(CK$2=$A17) -> 0 | CN17: 7 | CO17: 0.036780013 | CP17: -0.018110184 | CQ17: 0.0079985043 | CR17: 0.011172184 | CS17: =SUM(CO17:CR17) -> 0.037840517
D18: =SUMPRODUCT(L18:CK18,$L$79:$CK$79) -> 0 | E18: =+D18-C18 -> 0 | F18: =ABS(C18-D18) -> 0 | G18: =+IFERROR(IRR(K18:CK18,0),0) -> 0 | H18: =IFERROR(IRR((J18,L18:CK18),0),0) -> 0 | I18: =IFERROR(H18-G18,0) -> 0 | J18: =-D18 -> 0 | K18: =-C18 -> 0 | L18: =$B18*100*(L$2<$A18)+100*(1+$B18)*(L$2=$A18) -> 0 | M18: =$B18*100*(M$2<$A18)+100*(1+$B18)*(M$2=$A18) -> 0 | N18: =$B18*100*(N$2<$A18)+100*(1+$B18)*(N$2=$A18) -> 0 | O18: =$B18*100*(O$2<$A18)+100*(1+$B18)*(O$2=$A18) -> 0 | P18: =$B18*100*(P$2<$A18)+100*(1+$B18)*(P$2=$A18) -> 0 | Q18: =$B18*100*(Q$2<$A18)+100*(1+$B18)*(Q$2=$A18) -> 0 | R18: =$B18*100*(R$2<$A18)+100*(1+$B18)*(R$2=$A18) -> 0 | S18: =$B18*100*(S$2<$A18)+100*(1+$B18)*(S$2=$A18) -> 0 | ... CK18: =$B18*100*(CK$2<$A18)+100*(1+$B18)*(CK$2=$A18) -> 0 | CN18: 7.5 | CO18: 0.036780013 | CP18: -0.017874159 | CQ18: 0.0084160308 | CR18: 0.011873192 | CS18: =SUM(CO18:CR18) -> 0.039195076
D19: =SUMPRODUCT(L19:CK19,$L$79:$CK$79) -> 0 | E19: =+D19-C19 -> 0 | F19: =ABS(C19-D19) -> 0 | G19: =+IFERROR(IRR(K19:CK19,0),0) -> 0 | H19: =IFERROR(IRR((J19,L19:CK19),0),0) -> 0 | I19: =IFERROR(H19-G19,0) -> 0 | J19: =-D19 -> 0 | K19: =-C19 -> 0 | L19: =$B19*100*(L$2<$A19)+100*(1+$B19)*(L$2=$A19) -> 0 | M19: =$B19*100*(M$2<$A19)+100*(1+$B19)*(M$2=$A19) -> 0 | N19: =$B19*100*(N$2<$A19)+100*(1+$B19)*(N$2=$A19) -> 0 | O19: =$B19*100*(O$2<$A19)+100*(1+$B19)*(O$2=$A19) -> 0 | P19: =$B19*100*(P$2<$A19)+100*(1+$B19)*(P$2=$A19) -> 0 | Q19: =$B19*100*(Q$2<$A19)+100*(1+$B19)*(Q$2=$A19) -> 0 | R19: =$B19*100*(R$2<$A19)+100*(1+$B19)*(R$2=$A19) -> 0 | S19: =$B19*100*(S$2<$A19)+100*(1+$B19)*(S$2=$A19) -> 0 | ... CK19: =$B19*100*(CK$2<$A19)+100*(1+$B19)*(CK$2=$A19) -> 0 | CN19: 8 | CO19: 0.036780013 | CP19: -0.017642364 | CQ19: 0.0088164038 | CR19: 0.012562213 | CS19: =SUM(CO19:CR19) -> 0.040516266
D20: =SUMPRODUCT(L20:CK20,$L$79:$CK$79) -> 0 | E20: =+D20-C20 -> 0 | F20: =ABS(C20-D20) -> 0 | G20: =+IFERROR(IRR(K20:CK20,0),0) -> 0 | H20: =IFERROR(IRR((J20,L20:CK20),0),0) -> 0 | I20: =IFERROR(H20-G20,0) -> 0 | J20: =-D20 -> 0 | K20: =-C20 -> 0 | L20: =$B20*100*(L$2<$A20)+100*(1+$B20)*(L$2=$A20) -> 0 | M20: =$B20*100*(M$2<$A20)+100*(1+$B20)*(M$2=$A20) -> 0 | N20: =$B20*100*(N$2<$A20)+100*(1+$B20)*(N$2=$A20) -> 0 | O20: =$B20*100*(O$2<$A20)+100*(1+$B20)*(O$2=$A20) -> 0 | P20: =$B20*100*(P$2<$A20)+100*(1+$B20)*(P$2=$A20) -> 0 | Q20: =$B20*100*(Q$2<$A20)+100*(1+$B20)*(Q$2=$A20) -> 0 | R20: =$B20*100*(R$2<$A20)+100*(1+$B20)*(R$2=$A20) -> 0 | S20: =$B20*100*(S$2<$A20)+100*(1+$B20)*(S$2=$A20) -> 0 | ... CK20: =$B20*100*(CK$2<$A20)+100*(1+$B20)*(CK$2=$A20) -> 0 | CN20: 8.5 | CO20: 0.036780013 | CP20: -0.017414713 | CQ20: 0.0092001738 | CR20: 0.013239417 | CS20: =SUM(CO20:CR20) -> 0.041804891
D21: =SUMPRODUCT(L21:CK21,$L$79:$CK$79) -> 0 | E21: =+D21-C21 -> 0 | F21: =ABS(C21-D21) -> 0 | G21: =+IFERROR(IRR(K21:CK21,0),0) -> 0 | H21: =IFERROR(IRR((J21,L21:CK21),0),0) -> 0 | I21: =IFERROR(H21-G21,0) -> 0 | J21: =-D21 -> 0 | K21: =-C21 -> 0 | L21: =$B21*100*(L$2<$A21)+100*(1+$B21)*(L$2=$A21) -> 0 | M21: =$B21*100*(M$2<$A21)+100*(1+$B21)*(M$2=$A21) -> 0 | N21: =$B21*100*(N$2<$A21)+100*(1+$B21)*(N$2=$A21) -> 0 | O21: =$B21*100*(O$2<$A21)+100*(1+$B21)*(O$2=$A21) -> 0 | P21: =$B21*100*(P$2<$A21)+100*(1+$B21)*(P$2=$A21) -> 0 | Q21: =$B21*100*(Q$2<$A21)+100*(1+$B21)*(Q$2=$A21) -> 0 | R21: =$B21*100*(R$2<$A21)+100*(1+$B21)*(R$2=$A21) -> 0 | S21: =$B21*100*(S$2<$A21)+100*(1+$B21)*(S$2=$A21) -> 0 | ... CK21: =$B21*100*(CK$2<$A21)+100*(1+$B21)*(CK$2=$A21) -> 0 | CN21: 9 | CO21: 0.036780013 | CP21: -0.017191121 | CQ21: 0.0095678748 | CR21: 0.013904969 | CS21: =SUM(CO21:CR21) -> 0.043061735
D22: =SUMPRODUCT(L22:CK22,$L$79:$CK$79) -> 0 | E22: =+D22-C22 -> 0 | F22: =ABS(C22-D22) -> 0 | G22: =+IFERROR(IRR(K22:CK22,0),0) -> 0 | H22: =IFERROR(IRR((J22,L22:CK22),0),0) -> 0 | I22: =IFERROR(H22-G22,0) -> 0 | J22: =-D22 -> 0 | K22: =-C22 -> 0 | L22: =$B22*100*(L$2<$A22)+100*(1+$B22)*(L$2=$A22) -> 0 | M22: =$B22*100*(M$2<$A22)+100*(1+$B22)*(M$2=$A22) -> 0 | N22: =$B22*100*(N$2<$A22)+100*(1+$B22)*(N$2=$A22) -> 0 | O22: =$B22*100*(O$2<$A22)+100*(1+$B22)*(O$2=$A22) -> 0 | P22: =$B22*100*(P$2<$A22)+100*(1+$B22)*(P$2=$A22) -> 0 | Q22: =$B22*100*(Q$2<$A22)+100*(1+$B22)*(Q$2=$A22) -> 0 | R22: =$B22*100*(R$2<$A22)+100*(1+$B22)*(R$2=$A22) -> 0 | S22: =$B22*100*(S$2<$A22)+100*(1+$B22)*(S$2=$A22) -> 0 | ... CK22: =$B22*100*(CK$2<$A22)+100*(1+$B22)*(CK$2=$A22) -> 0 | CN22: 9.5 | CO22: 0.036780013 | CP22: -0.016971507 | CQ22: 0.0099200248 | CR22: 0.014559032 | CS22: =SUM(CO22:CR22) -> 0.044287563
D23: =SUMPRODUCT(L23:CK23,$L$79:$CK$79) -> 0 | E23: =+D23-C23 -> 0 | F23: =ABS(C23-D23) -> 0 | G23: =+IFERROR(IRR(K23:CK23,0),0) -> 0 | H23: =IFERROR(IRR((J23,L23:CK23),0),0) -> 0 | I23: =IFERROR(H23-G23,0) -> 0 | J23: =-D23 -> 0 | K23: =-C23 -> 0 | L23: =$B23*100*(L$2<$A23)+100*(1+$B23)*(L$2=$A23) -> 0 | M23: =$B23*100*(M$2<$A23)+100*(1+$B23)*(M$2=$A23) -> 0 | N23: =$B23*100*(N$2<$A23)+100*(1+$B23)*(N$2=$A23) -> 0 | O23: =$B23*100*(O$2<$A23)+100*(1+$B23)*(O$2=$A23) -> 0 | P23: =$B23*100*(P$2<$A23)+100*(1+$B23)*(P$2=$A23) -> 0 | Q23: =$B23*100*(Q$2<$A23)+100*(1+$B23)*(Q$2=$A23) -> 0 | R23: =$B23*100*(R$2<$A23)+100*(1+$B23)*(R$2=$A23) -> 0 | S23: =$B23*100*(S$2<$A23)+100*(1+$B23)*(S$2=$A23) -> 0 | ... CK23: =$B23*100*(CK$2<$A23)+100*(1+$B23)*(CK$2=$A23) -> 0 | CN23: 10 | CO23: 0.036780013 | CP23: -0.016755788 | CQ23: 0.010257126 | CR23: 0.015201768 | CS23: =SUM(CO23:CR23) -> 0.045483118
D24: =SUMPRODUCT(L24:CK24,$L$79:$CK$79) -> 0 | E24: =+D24-C24 -> 0 | F24: =ABS(C24-D24) -> 0 | G24: =+IFERROR(IRR(K24:CK24,0),0) -> 0 | H24: =IFERROR(IRR((J24,L24:CK24),0),0) -> 0 | I24: =IFERROR(H24-G24,0) -> 0 | J24: =-D24 -> 0 | K24: =-C24 -> 0 | L24: =$B24*100*(L$2<$A24)+100*(1+$B24)*(L$2=$A24) -> 0 | M24: =$B24*100*(M$2<$A24)+100*(1+$B24)*(M$2=$A24) -> 0 | N24: =$B24*100*(N$2<$A24)+100*(1+$B24)*(N$2=$A24) -> 0 | O24: =$B24*100*(O$2<$A24)+100*(1+$B24)*(O$2=$A24) -> 0 | P24: =$B24*100*(P$2<$A24)+100*(1+$B24)*(P$2=$A24) -> 0 | Q24: =$B24*100*(Q$2<$A24)+100*(1+$B24)*(Q$2=$A24) -> 0 | R24: =$B24*100*(R$2<$A24)+100*(1+$B24)*(R$2=$A24) -> 0 | S24: =$B24*100*(S$2<$A24)+100*(1+$B24)*(S$2=$A24) -> 0 | ... CK24: =$B24*100*(CK$2<$A24)+100*(1+$B24)*(CK$2=$A24) -> 0 | CN24: 10.5 | CO24: 0.036780013 | CP24: -0.016543887 | CQ24: 0.010579667 | CR24: 0.015833336 | CS24: =SUM(CO24:CR24) -> 0.046649128
D25: =SUMPRODUCT(L25:CK25,$L$79:$CK$79) -> 0 | E25: =+D25-C25 -> 0 | F25: =ABS(C25-D25) -> 0 | G25: =+IFERROR(IRR(K25:CK25,0),0) -> 0 | H25: =IFERROR(IRR((J25,L25:CK25),0),0) -> 0 | I25: =IFERROR(H25-G25,0) -> 0 | J25: =-D25 -> 0 | K25: =-C25 -> 0 | L25: =$B25*100*(L$2<$A25)+100*(1+$B25)*(L$2=$A25) -> 0 | M25: =$B25*100*(M$2<$A25)+100*(1+$B25)*(M$2=$A25) -> 0 | N25: =$B25*100*(N$2<$A25)+100*(1+$B25)*(N$2=$A25) -> 0 | O25: =$B25*100*(O$2<$A25)+100*(1+$B25)*(O$2=$A25) -> 0 | P25: =$B25*100*(P$2<$A25)+100*(1+$B25)*(P$2=$A25) -> 0 | Q25: =$B25*100*(Q$2<$A25)+100*(1+$B25)*(Q$2=$A25) -> 0 | R25: =$B25*100*(R$2<$A25)+100*(1+$B25)*(R$2=$A25) -> 0 | S25: =$B25*100*(S$2<$A25)+100*(1+$B25)*(S$2=$A25) -> 0 | ... CK25: =$B25*100*(CK$2<$A25)+100*(1+$B25)*(CK$2=$A25) -> 0 | CN25: 11 | CO25: 0.036780013 | CP25: -0.016335725 | CQ25: 0.010888118 | CR25: 0.016453892 | CS25: =SUM(CO25:CR25) -> 0.047786299
D26: =SUMPRODUCT(L26:CK26,$L$79:$CK$79) -> 0 | E26: =+D26-C26 -> 0 | F26: =ABS(C26-D26) -> 0 | G26: =+IFERROR(IRR(K26:CK26,0),0) -> 0 | H26: =IFERROR(IRR((J26,L26:CK26),0),0) -> 0 | I26: =IFERROR(H26-G26,0) -> 0 | J26: =-D26 -> 0 | K26: =-C26 -> 0 | L26: =$B26*100*(L$2<$A26)+100*(1+$B26)*(L$2=$A26) -> 0 | M26: =$B26*100*(M$2<$A26)+100*(1+$B26)*(M$2=$A26) -> 0 | N26: =$B26*100*(N$2<$A26)+100*(1+$B26)*(N$2=$A26) -> 0 | O26: =$B26*100*(O$2<$A26)+100*(1+$B26)*(O$2=$A26) -> 0 | P26: =$B26*100*(P$2<$A26)+100*(1+$B26)*(P$2=$A26) -> 0 | Q26: =$B26*100*(Q$2<$A26)+100*(1+$B26)*(Q$2=$A26) -> 0 | R26: =$B26*100*(R$2<$A26)+100*(1+$B26)*(R$2=$A26) -> 0 | S26: =$B26*100*(S$2<$A26)+100*(1+$B26)*(S$2=$A26) -> 0 | ... CK26: =$B26*100*(CK$2<$A26)+100*(1+$B26)*(CK$2=$A26) -> 0 | CN26: 11.5 | CO26: 0.036780013 | CP26: -0.016131227 | CQ26: 0.01118294 | CR26: 0.017063594 | CS26: =SUM(CO26:CR26) -> 0.04889532
