Workbook
Name b0: NSS!$C$248
Name b0: '[1]Nelson Siegel Model'!$B$16
Name b1_: NSS!$C$249
Name b1_: '[1]Nelson Siegel Model'!$B$17
Name b2_: NSS!$C$250
Name b2_: '[1]Nelson Siegel Model'!$B$18
Name b3_: NSS!$C$251
Name b3_: #REF!
Name tau1_: NSS!$C$252
Name tau1_: '[1]Nelson Siegel Model'!$B$19
Name tau2_: NSS!$C$253
Name tau2_: #REF!

Sheet Bloomberg (Online)
A1: Instrument | B1: Name | C1: Ticker | D1: Country/Region | E1: Currency | F1: Maturity | G1: Coupon Type | H1: Coupon Frequency | I1: Coupon | J1: Ask Yield to Maturity | K1: Bid Yield to Maturity | L1: Ask Price | M1: Bid Price | N1: Identifier | O1: ISIN | P1: Bloomberg Composite Rating | Q1: Announce | R1: Next Coupon Settle Date | S1: Time
A2: AL516835 Corp | B2: {=_xll.BDP("AL516835 Corp","DS520")} -> #NAME? | C2: {=_xll.BDP("AL516835 Corp","DS001")} -> #NAME? | D2: {=_xll.BDP("AL516835 Corp","DS458")} -> #NAME? | E2: {=_xll.BDP("AL516835 Corp","DS004")} -> #NAME? | F2: {=_xll.BDP("AL516835 Corp","DS035")} -> #NAME? | G2: {=_xll.BDP("AL516835 Corp","DS086")} -> #NAME? | H2: {=_xll.BDP("AL516835 Corp","DS034")} -> #NAME? | I2: {=_xll.BDP("AL516835 Corp","DS033")} -> #NAME? | J2: {=_xll.BDP("AL516835 Corp","YL018")} -> #NAME? | K2: {=_xll.BDP("AL516835 Corp","YL016")} -> #NAME? | L2: {=_xll.BDP("AL516835 Corp","PR004")} -> #NAME? | M2: {=_xll.BDP("AL516835 Corp","PR002")} -> #NAME? | N2: {=_xll.BDP("AL516835 Corp","ID028")} -> #NAME? | O2: {=_xll.BDP("AL516835 Corp","ID005")} -> #NAME? | P2: {=_xll.BDP(A2,"RA007")} -> #NAME? | Q2: {=_xll.BDP(A2,"DS219")} -> #NAME? | R2: {=_xll.BDP(A2,"DS040")} -> #NAME? | S2: =(F2-TODAY())/365.25 -> #NAME? | T2: =S2-ROUNDDOWN(S2,0) -> #NAME? | U2: =DATE(2026,MONTH(TODAY()),DAY(F2))>DATEVALUE(R2) -> #NAME?
A3: AL662876 Corp | B3: {=_xll.BDP("AL662876 Corp","DS520")} -> #NAME? | C3: {=_xll.BDP("AL662876 Corp","DS001")} -> #NAME? | D3: {=_xll.BDP("AL662876 Corp","DS458")} -> #NAME? | E3: {=_xll.BDP("AL662876 Corp","DS004")} -> #NAME? | F3: {=_xll.BDP("AL662876 Corp","DS035")} -> #NAME? | G3: {=_xll.BDP("AL662876 Corp","DS086")} -> #NAME? | H3: {=_xll.BDP("AL662876 Corp","DS034")} -> #NAME? | I3: {=_xll.BDP("AL662876 Corp","DS033")} -> #NAME? | J3: {=_xll.BDP("AL662876 Corp","YL018")} -> #NAME? | K3: {=_xll.BDP("AL662876 Corp","YL016")} -> #NAME? | L3: {=_xll.BDP("AL662876 Corp","PR004")} -> #NAME? | M3: {=_xll.BDP("AL662876 Corp","PR002")} -> #NAME? | N3: {=_xll.BDP("AL662876 Corp","ID028")} -> #NAME? | O3: {=_xll.BDP("AL662876 Corp","ID005")} -> #NAME? | P3: {=_xll.BDP(A3,"RA007")} -> #NAME? | Q3: {=_xll.BDP(A3,"DS219")} -> #NAME? | R3: {=_xll.BDP(A3,"DS040")} -> #NAME? | S3: =(F3-TODAY())/365.25 -> #NAME? | T3: =S3-ROUNDDOWN(S3,0) -> #NAME? | U3: =DATE(2026,MONTH(TODAY()),DAY(F3))>DATEVALUE(R3) -> #NAME?
A4: AL797512 Corp | B4: {=_xll.BDP("AL797512 Corp","DS520")} -> #NAME? | C4: {=_xll.BDP("AL797512 Corp","DS001")} -> #NAME? | D4: {=_xll.BDP("AL797512 Corp","DS458")} -> #NAME? | E4: {=_xll.BDP("AL797512 Corp","DS004")} -> #NAME? | F4: {=_xll.BDP("AL797512 Corp","DS035")} -> #NAME? | G4: {=_xll.BDP("AL797512 Corp","DS086")} -> #NAME? | H4: {=_xll.BDP("AL797512 Corp","DS034")} -> #NAME? | I4: {=_xll.BDP("AL797512 Corp","DS033")} -> #NAME? | J4: {=_xll.BDP("AL797512 Corp","YL018")} -> #NAME? | K4: {=_xll.BDP("AL797512 Corp","YL016")} -> #NAME? | L4: {=_xll.BDP("AL797512 Corp","PR004")} -> #NAME? | M4: {=_xll.BDP("AL797512 Corp","PR002")} -> #NAME? | N4: {=_xll.BDP("AL797512 Corp","ID028")} -> #NAME? | O4: {=_xll.BDP("AL797512 Corp","ID005")} -> #NAME? | P4: {=_xll.BDP(A4,"RA007")} -> #NAME? | Q4: {=_xll.BDP(A4,"DS219")} -> #NAME? | R4: {=_xll.BDP(A4,"DS040")} -> #NAME? | S4: =(F4-TODAY())/365.25 -> #NAME? | T4: =S4-ROUNDDOWN(S4,0) -> #NAME? | U4: =DATE(2026,MONTH(TODAY()),DAY(F4))>DATEVALUE(R4) -> #NAME?
A5: AM713129 Corp | B5: {=_xll.BDP("AM713129 Corp","DS520")} -> #NAME? | C5: {=_xll.BDP("AM713129 Corp","DS001")} -> #NAME? | D5: {=_xll.BDP("AM713129 Corp","DS458")} -> #NAME? | E5: {=_xll.BDP("AM713129 Corp","DS004")} -> #NAME? | F5: {=_xll.BDP("AM713129 Corp","DS035")} -> #NAME? | G5: {=_xll.BDP("AM713129 Corp","DS086")} -> #NAME? | H5: {=_xll.BDP("AM713129 Corp","DS034")} -> #NAME? | I5: {=_xll.BDP("AM713129 Corp","DS033")} -> #NAME? | J5: {=_xll.BDP("AM713129 Corp","YL018")} -> #NAME? | K5: {=_xll.BDP("AM713129 Corp","YL016")} -> #NAME? | L5: {=_xll.BDP("AM713129 Corp","PR004")} -> #NAME? | M5: {=_xll.BDP("AM713129 Corp","PR002")} -> #NAME? | N5: {=_xll.BDP("AM713129 Corp","ID028")} -> #NAME? | O5: {=_xll.BDP("AM713129 Corp","ID005")} -> #NAME? | P5: {=_xll.BDP(A5,"RA007")} -> #NAME? | Q5: {=_xll.BDP(A5,"DS219")} -> #NAME? | R5: {=_xll.BDP(A5,"DS040")} -> #NAME? | S5: =(F5-TODAY())/365.25 -> #NAME? | T5: =S5-ROUNDDOWN(S5,0) -> #NAME? | U5: =DATE(2026,MONTH(TODAY()),DAY(F5))>DATEVALUE(R5) -> #NAME?
A6: AM766737 Corp | B6: {=_xll.BDP("AM766737 Corp","DS520")} -> #NAME? | C6: {=_xll.BDP("AM766737 Corp","DS001")} -> #NAME? | D6: {=_xll.BDP("AM766737 Corp","DS458")} -> #NAME? | E6: {=_xll.BDP("AM766737 Corp","DS004")} -> #NAME? | F6: {=_xll.BDP("AM766737 Corp","DS035")} -> #NAME? | G6: {=_xll.BDP("AM766737 Corp","DS086")} -> #NAME? | H6: {=_xll.BDP("AM766737 Corp","DS034")} -> #NAME? | I6: {=_xll.BDP("AM766737 Corp","DS033")} -> #NAME? | J6: {=_xll.BDP("AM766737 Corp","YL018")} -> #NAME? | K6: {=_xll.BDP("AM766737 Corp","YL016")} -> #NAME? | L6: {=_xll.BDP("AM766737 Corp","PR004")} -> #NAME? | M6: {=_xll.BDP("AM766737 Corp","PR002")} -> #NAME? | N6: {=_xll.BDP("AM766737 Corp","ID028")} -> #NAME? | O6: {=_xll.BDP("AM766737 Corp","ID005")} -> #NAME? | P6: {=_xll.BDP(A6,"RA007")} -> #NAME? | Q6: {=_xll.BDP(A6,"DS219")} -> #NAME? | R6: {=_xll.BDP(A6,"DS040")} -> #NAME? | S6: =(F6-TODAY())/365.25 -> #NAME? | T6: =S6-ROUNDDOWN(S6,0) -> #NAME? | U6: =DATE(2026,MONTH(TODAY()),DAY(F6))>DATEVALUE(R6) -> #NAME?
A7: AM850328 Corp | B7: {=_xll.BDP("AM850328 Corp","DS520")} -> #NAME? | C7: {=_xll.BDP("AM850328 Corp","DS001")} -> #NAME? | D7: {=_xll.BDP("AM850328 Corp","DS458")} -> #NAME? | E7: {=_xll.BDP("AM850328 Corp","DS004")} -> #NAME? | F7: {=_xll.BDP("AM850328 Corp","DS035")} -> #NAME? | G7: {=_xll.BDP("AM850328 Corp","DS086")} -> #NAME? | H7: {=_xll.BDP("AM850328 Corp","DS034")} -> #NAME? | I7: {=_xll.BDP("AM850328 Corp","DS033")} -> #NAME? | J7: {=_xll.BDP("AM850328 Corp","YL018")} -> #NAME? | K7: {=_xll.BDP("AM850328 Corp","YL016")} -> #NAME? | L7: {=_xll.BDP("AM850328 Corp","PR004")} -> #NAME? | M7: {=_xll.BDP("AM850328 Corp","PR002")} -> #NAME? | N7: {=_xll.BDP("AM850328 Corp","ID028")} -> #NAME? | O7: {=_xll.BDP("AM850328 Corp","ID005")} -> #NAME? | P7: {=_xll.BDP(A7,"RA007")} -> #NAME? | Q7: {=_xll.BDP(A7,"DS219")} -> #NAME? | R7: {=_xll.BDP(A7,"DS040")} -> #NAME? | S7: =(F7-TODAY())/365.25 -> #NAME? | T7: =S7-ROUNDDOWN(S7,0) -> #NAME? | U7: =DATE(2026,MONTH(TODAY()),DAY(F7))>DATEVALUE(R7) -> #NAME?
A8: AN751153 Corp | B8: {=_xll.BDP("AN751153 Corp","DS520")} -> #NAME? | C8: {=_xll.BDP("AN751153 Corp","DS001")} -> #NAME? | D8: {=_xll.BDP("AN751153 Corp","DS458")} -> #NAME? | E8: {=_xll.BDP("AN751153 Corp","DS004")} -> #NAME? | F8: {=_xll.BDP("AN751153 Corp","DS035")} -> #NAME? | G8: {=_xll.BDP("AN751153 Corp","DS086")} -> #NAME? | H8: {=_xll.BDP("AN751153 Corp","DS034")} -> #NAME? | I8: {=_xll.BDP("AN751153 Corp","DS033")} -> #NAME? | J8: {=_xll.BDP("AN751153 Corp","YL018")} -> #NAME? | K8: {=_xll.BDP("AN751153 Corp","YL016")} -> #NAME? | L8: {=_xll.BDP("AN751153 Corp","PR004")} -> #NAME? | M8: {=_xll.BDP("AN751153 Corp","PR002")} -> #NAME? | N8: {=_xll.BDP("AN751153 Corp","ID028")} -> #NAME? | O8: {=_xll.BDP("AN751153 Corp","ID005")} -> #NAME? | P8: {=_xll.BDP(A8,"RA007")} -> #NAME? | Q8: {=_xll.BDP(A8,"DS219")} -> #NAME? | R8: {=_xll.BDP(A8,"DS040")} -> #NAME? | S8: =(F8-TODAY())/365.25 -> #NAME? | T8: =S8-ROUNDDOWN(S8,0) -> #NAME? | U8: =DATE(2026,MONTH(TODAY()),DAY(F8))>DATEVALUE(R8) -> #NAME?
A9: AN821370 Corp | B9: {=_xll.BDP("AN821370 Corp","DS520")} -> #NAME? | C9: {=_xll.BDP("AN821370 Corp","DS001")} -> #NAME? | D9: {=_xll.BDP("AN821370 Corp","DS458")} -> #NAME? | E9: {=_xll.BDP("AN821370 Corp","DS004")} -> #NAME? | F9: {=_xll.BDP("AN821370 Corp","DS035")} -> #NAME? | G9: {=_xll.BDP("AN821370 Corp","DS086")} -> #NAME? | H9: {=_xll.BDP("AN821370 Corp","DS034")} -> #NAME? | I9: {=_xll.BDP("AN821370 Corp","DS033")} -> #NAME? | J9: {=_xll.BDP("AN821370 Corp","YL018")} -> #NAME? | K9: {=_xll.BDP("AN821370 Corp","YL016")} -> #NAME? | L9: {=_xll.BDP("AN821370 Corp","PR004")} -> #NAME? | M9: {=_xll.BDP("AN821370 Corp","PR002")} -> #NAME? | N9: {=_xll.BDP("AN821370 Corp","ID028")} -> #NAME? | O9: {=_xll.BDP("AN821370 Corp","ID005")} -> #NAME? | P9: {=_xll.BDP(A9,"RA007")} -> #NAME? | Q9: {=_xll.BDP(A9,"DS219")} -> #NAME? | R9: {=_xll.BDP(A9,"DS040")} -> #NAME? | S9: =(F9-TODAY())/365.25 -> #NAME? | T9: =S9-ROUNDDOWN(S9,0) -> #NAME? | U9: =DATE(2026,MONTH(TODAY()),DAY(F9))>DATEVALUE(R9) -> #NAME?
A10: AN861997 Corp | B10: {=_xll.BDP("AN861997 Corp","DS520")} -> #NAME? | C10: {=_xll.BDP("AN861997 Corp","DS001")} -> #NAME? | D10: {=_xll.BDP("AN861997 Corp","DS458")} -> #NAME? | E10: {=_xll.BDP("AN861997 Corp","DS004")} -> #NAME? | F10: {=_xll.BDP("AN861997 Corp","DS035")} -> #NAME? | G10: {=_xll.BDP("AN861997 Corp","DS086")} -> #NAME? | H10: {=_xll.BDP("AN861997 Corp","DS034")} -> #NAME? | I10: {=_xll.BDP("AN861997 Corp","DS033")} -> #NAME? | J10: {=_xll.BDP("AN861997 Corp","YL018")} -> #NAME? | K10: {=_xll.BDP("AN861997 Corp","YL016")} -> #NAME? | L10: {=_xll.BDP("AN861997 Corp","PR004")} -> #NAME? | M10: {=_xll.BDP("AN861997 Corp","PR002")} -> #NAME? | N10: {=_xll.BDP("AN861997 Corp","ID028")} -> #NAME? | O10: {=_xll.BDP("AN861997 Corp","ID005")} -> #NAME? | P10: {=_xll.BDP(A10,"RA007")} -> #NAME? | Q10: {=_xll.BDP(A10,"DS219")} -> #NAME? | R10: {=_xll.BDP(A10,"DS040")} -> #NAME? | S10: =(F10-TODAY())/365.25 -> #NAME? | T10: =S10-ROUNDDOWN(S10,0) -> #NAME? | U10: =DATE(2026,MONTH(TODAY()),DAY(F10))>DATEVALUE(R10) -> #NAME?
A11: AN958432 Corp | B11: {=_xll.BDP("AN958432 Corp","DS520")} -> #NAME? | C11: {=_xll.BDP("AN958432 Corp","DS001")} -> #NAME? | D11: {=_xll.BDP("AN958432 Corp","DS458")} -> #NAME? | E11: {=_xll.BDP("AN958432 Corp","DS004")} -> #NAME? | F11: {=_xll.BDP("AN958432 Corp","DS035")} -> #NAME? | G11: {=_xll.BDP("AN958432 Corp","DS086")} -> #NAME? | H11: {=_xll.BDP("AN958432 Corp","DS034")} -> #NAME? | I11: {=_xll.BDP("AN958432 Corp","DS033")} -> #NAME? | J11: {=_xll.BDP("AN958432 Corp","YL018")} -> #NAME? | K11: {=_xll.BDP("AN958432 Corp","YL016")} -> #NAME? | L11: {=_xll.BDP("AN958432 Corp","PR004")} -> #NAME? | M11: {=_xll.BDP("AN958432 Corp","PR002")} -> #NAME? | N11: {=_xll.BDP("AN958432 Corp","ID028")} -> #NAME? | O11: {=_xll.BDP("AN958432 Corp","ID005")} -> #NAME? | P11: {=_xll.BDP(A11,"RA007")} -> #NAME? | Q11: {=_xll.BDP(A11,"DS219")} -> #NAME? | R11: {=_xll.BDP(A11,"DS040")} -> #NAME? | S11: =(F11-TODAY())/365.25 -> #NAME? | T11: =S11-ROUNDDOWN(S11,0) -> #NAME? | U11: =DATE(2026,MONTH(TODAY()),DAY(F11))>DATEVALUE(R11) -> #NAME?
A12: AP027592 Corp | B12: {=_xll.BDP("AP027592 Corp","DS520")} -> #NAME? | C12: {=_xll.BDP("AP027592 Corp","DS001")} -> #NAME? | D12: {=_xll.BDP("AP027592 Corp","DS458")} -> #NAME? | E12: {=_xll.BDP("AP027592 Corp","DS004")} -> #NAME? | F12: {=_xll.BDP("AP027592 Corp","DS035")} -> #NAME? | G12: {=_xll.BDP("AP027592 Corp","DS086")} -> #NAME? | H12: {=_xll.BDP("AP027592 Corp","DS034")} -> #NAME? | I12: {=_xll.BDP("AP027592 Corp","DS033")} -> #NAME? | J12: {=_xll.BDP("AP027592 Corp","YL018")} -> #NAME? | K12: {=_xll.BDP("AP027592 Corp","YL016")} -> #NAME? | L12: {=_xll.BDP("AP027592 Corp","PR004")} -> #NAME? | M12: {=_xll.BDP("AP027592 Corp","PR002")} -> #NAME? | N12: {=_xll.BDP("AP027592 Corp","ID028")} -> #NAME? | O12: {=_xll.BDP("AP027592 Corp","ID005")} -> #NAME? | P12: {=_xll.BDP(A12,"RA007")} -> #NAME? | Q12: {=_xll.BDP(A12,"DS219")} -> #NAME? | R12: {=_xll.BDP(A12,"DS040")} -> #NAME? | S12: =(F12-TODAY())/365.25 -> #NAME? | T12: =S12-ROUNDDOWN(S12,0) -> #NAME? | U12: =DATE(2026,MONTH(TODAY()),DAY(F12))>DATEVALUE(R12) -> #NAME?
A13: AP059339 Corp | B13: {=_xll.BDP("AP059339 Corp","DS520")} -> #NAME? | C13: {=_xll.BDP("AP059339 Corp","DS001")} -> #NAME? | D13: {=_xll.BDP("AP059339 Corp","DS458")} -> #NAME? | E13: {=_xll.BDP("AP059339 Corp","DS004")} -> #NAME? | F13: {=_xll.BDP("AP059339 Corp","DS035")} -> #NAME? | G13: {=_xll.BDP("AP059339 Corp","DS086")} -> #NAME? | H13: {=_xll.BDP("AP059339 Corp","DS034")} -> #NAME? | I13: {=_xll.BDP("AP059339 Corp","DS033")} -> #NAME? | J13: {=_xll.BDP("AP059339 Corp","YL018")} -> #NAME? | K13: {=_xll.BDP("AP059339 Corp","YL016")} -> #NAME? | L13: {=_xll.BDP("AP059339 Corp","PR004")} -> #NAME? | M13: {=_xll.BDP("AP059339 Corp","PR002")} -> #NAME? | N13: {=_xll.BDP("AP059339 Corp","ID028")} -> #NAME? | O13: {=_xll.BDP("AP059339 Corp","ID005")} -> #NAME? | P13: {=_xll.BDP(A13,"RA007")} -> #NAME? | Q13: {=_xll.BDP(A13,"DS219")} -> #NAME? | R13: {=_xll.BDP(A13,"DS040")} -> #NAME? | S13: =(F13-TODAY())/365.25 -> #NAME? | T13: =S13-ROUNDDOWN(S13,0) -> #NAME? | U13: =DATE(2026,MONTH(TODAY()),DAY(F13))>DATEVALUE(R13) -> #NAME?
A14: AP155275 Corp | B14: {=_xll.BDP("AP155275 Corp","DS520")} -> #NAME? | C14: {=_xll.BDP("AP155275 Corp","DS001")} -> #NAME? | D14: {=_xll.BDP("AP155275 Corp","DS458")} -> #NAME? | E14: {=_xll.BDP("AP155275 Corp","DS004")} -> #NAME? | F14: {=_xll.BDP("AP155275 Corp","DS035")} -> #NAME? | G14: {=_xll.BDP("AP155275 Corp","DS086")} -> #NAME? | H14: {=_xll.BDP("AP155275 Corp","DS034")} -> #NAME? | I14: {=_xll.BDP("AP155275 Corp","DS033")} -> #NAME? | J14: {=_xll.BDP("AP155275 Corp","YL018")} -> #NAME? | K14: {=_xll.BDP("AP155275 Corp","YL016")} -> #NAME? | L14: {=_xll.BDP("AP155275 Corp","PR004")} -> #NAME? | M14: {=_xll.BDP("AP155275 Corp","PR002")} -> #NAME? | N14: {=_xll.BDP("AP155275 Corp","ID028")} -> #NAME? | O14: {=_xll.BDP("AP155275 Corp","ID005")} -> #NAME? | P14: {=_xll.BDP(A14,"RA007")} -> #NAME? | Q14: {=_xll.BDP(A14,"DS219")} -> #NAME? | R14: {=_xll.BDP(A14,"DS040")} -> #NAME? | S14: =(F14-TODAY())/365.25 -> #NAME? | T14: =S14-ROUNDDOWN(S14,0) -> #NAME? | U14: =DATE(2026,MONTH(TODAY()),DAY(F14))>DATEVALUE(R14) -> #NAME?
A15: AQ307103 Corp | B15: {=_xll.BDP("AQ307103 Corp","DS520")} -> #NAME? | C15: {=_xll.BDP("AQ307103 Corp","DS001")} -> #NAME? | D15: {=_xll.BDP("AQ307103 Corp","DS458")} -> #NAME? | E15: {=_xll.BDP("AQ307103 Corp","DS004")} -> #NAME? | F15: {=_xll.BDP("AQ307103 Corp","DS035")} -> #NAME? | G15: {=_xll.BDP("AQ307103 Corp","DS086")} -> #NAME? | H15: {=_xll.BDP("AQ307103 Corp","DS034")} -> #NAME? | I15: {=_xll.BDP("AQ307103 Corp","DS033")} -> #NAME? | J15: {=_xll.BDP("AQ307103 Corp","YL018")} -> #NAME? | K15: {=_xll.BDP("AQ307103 Corp","YL016")} -> #NAME? | L15: {=_xll.BDP("AQ307103 Corp","PR004")} -> #NAME? | M15: {=_xll.BDP("AQ307103 Corp","PR002")} -> #NAME? | N15: {=_xll.BDP("AQ307103 Corp","ID028")} -> #NAME? | O15: {=_xll.BDP("AQ307103 Corp","ID005")} -> #NAME? | P15: {=_xll.BDP(A15,"RA007")} -> #NAME? | Q15: {=_xll.BDP(A15,"DS219")} -> #NAME? | R15: {=_xll.BDP(A15,"DS040")} -> #NAME? | S15: =(F15-TODAY())/365.25 -> #NAME? | T15: =S15-ROUNDDOWN(S15,0) -> #NAME? | U15: =DATE(2026,MONTH(TODAY()),DAY(F15))>DATEVALUE(R15) -> #NAME?
A16: AQ340832 Corp | B16: {=_xll.BDP("AQ340832 Corp","DS520")} -> #NAME? | C16: {=_xll.BDP("AQ340832 Corp","DS001")} -> #NAME? | D16: {=_xll.BDP("AQ340832 Corp","DS458")} -> #NAME? | E16: {=_xll.BDP("AQ340832 Corp","DS004")} -> #NAME? | F16: {=_xll.BDP("AQ340832 Corp","DS035")} -> #NAME? | G16: {=_xll.BDP("AQ340832 Corp","DS086")} -> #NAME? | H16: {=_xll.BDP("AQ340832 Corp","DS034")} -> #NAME? | I16: {=_xll.BDP("AQ340832 Corp","DS033")} -> #NAME? | J16: {=_xll.BDP("AQ340832 Corp","YL018")} -> #NAME? | K16: {=_xll.BDP("AQ340832 Corp","YL016")} -> #NAME? | L16: {=_xll.BDP("AQ340832 Corp","PR004")} -> #NAME? | M16: {=_xll.BDP("AQ340832 Corp","PR002")} -> #NAME? | N16: {=_xll.BDP("AQ340832 Corp","ID028")} -> #NAME? | O16: {=_xll.BDP("AQ340832 Corp","ID005")} -> #NAME? | P16: {=_xll.BDP(A16,"RA007")} -> #NAME? | Q16: {=_xll.BDP(A16,"DS219")} -> #NAME? | R16: {=_xll.BDP(A16,"DS040")} -> #NAME? | S16: =(F16-TODAY())/365.25 -> #NAME? | T16: =S16-ROUNDDOWN(S16,0) -> #NAME? | U16: =DATE(2026,MONTH(TODAY()),DAY(F16))>DATEVALUE(R16) -> #NAME?
A17: AQ417830 Corp | B17: {=_xll.BDP("AQ417830 Corp","DS520")} -> #NAME? | C17: {=_xll.BDP("AQ417830 Corp","DS001")} -> #NAME? | D17: {=_xll.BDP("AQ417830 Corp","DS458")} -> #NAME? | E17: {=_xll.BDP("AQ417830 Corp","DS004")} -> #NAME? | F17: {=_xll.BDP("AQ417830 Corp","DS035")} -> #NAME? | G17: {=_xll.BDP("AQ417830 Corp","DS086")} -> #NAME? | H17: {=_xll.BDP("AQ417830 Corp","DS034")} -> #NAME? | I17: {=_xll.BDP("AQ417830 Corp","DS033")} -> #NAME? | J17: {=_xll.BDP("AQ417830 Corp","YL018")} -> #NAME? | K17: {=_xll.BDP("AQ417830 Corp","YL016")} -> #NAME? | L17: {=_xll.BDP("AQ417830 Corp","PR004")} -> #NAME? | M17: {=_xll.BDP("AQ417830 Corp","PR002")} -> #NAME? | N17: {=_xll.BDP("AQ417830 Corp","ID028")} -> #NAME? | O17: {=_xll.BDP("AQ417830 Corp","ID005")} -> #NAME? | P17: {=_xll.BDP(A17,"RA007")} -> #NAME? | Q17: {=_xll.BDP(A17,"DS219")} -> #NAME? | R17: {=_xll.BDP(A17,"DS040")} -> #NAME? | S17: =(F17-TODAY())/365.25 -> #NAME? | T17: =S17-ROUNDDOWN(S17,0) -> #NAME? | U17: =DATE(2026,MONTH(TODAY()),DAY(F17))>DATEVALUE(R17) -> #NAME?
A18: AR545005 Corp | B18: {=_xll.BDP("AR545005 Corp","DS520")} -> #NAME? | C18: {=_xll.BDP("AR545005 Corp","DS001")} -> #NAME? | D18: {=_xll.BDP("AR545005 Corp","DS458")} -> #NAME? | E18: {=_xll.BDP("AR545005 Corp","DS004")} -> #NAME? | F18: {=_xll.BDP("AR545005 Corp","DS035")} -> #NAME? | G18: {=_xll.BDP("AR545005 Corp","DS086")} -> #NAME? | H18: {=_xll.BDP("AR545005 Corp","DS034")} -> #NAME? | I18: {=_xll.BDP("AR545005 Corp","DS033")} -> #NAME? | J18: {=_xll.BDP("AR545005 Corp","YL018")} -> #NAME? | K18: {=_xll.BDP("AR545005 Corp","YL016")} -> #NAME? | L18: {=_xll.BDP("AR545005 Corp","PR004")} -> #NAME? | M18: {=_xll.BDP("AR545005 Corp","PR002")} -> #NAME? | N18: {=_xll.BDP("AR545005 Corp","ID028")} -> #NAME? | O18: {=_xll.BDP("AR545005 Corp","ID005")} -> #NAME? | P18: {=_xll.BDP(A18,"RA007")} -> #NAME? | Q18: {=_xll.BDP(A18,"DS219")} -> #NAME? | R18: {=_xll.BDP(A18,"DS040")} -> #NAME? | S18: =(F18-TODAY())/365.25 -> #NAME? | T18: =S18-ROUNDDOWN(S18,0) -> #NAME? | U18: =DATE(2026,MONTH(TODAY()),DAY(F18))>DATEVALUE(R18) -> #NAME?
A19: AR620065 Corp | B19: {=_xll.BDP("AR620065 Corp","DS520")} -> #NAME? | C19: {=_xll.BDP("AR620065 Corp","DS001")} -> #NAME? | D19: {=_xll.BDP("AR620065 Corp","DS458")} -> #NAME? | E19: {=_xll.BDP("AR620065 Corp","DS004")} -> #NAME? | F19: {=_xll.BDP("AR620065 Corp","DS035")} -> #NAME? | G19: {=_xll.BDP("AR620065 Corp","DS086")} -> #NAME? | H19: {=_xll.BDP("AR620065 Corp","DS034")} -> #NAME? | I19: {=_xll.BDP("AR620065 Corp","DS033")} -> #NAME? | J19: {=_xll.BDP("AR620065 Corp","YL018")} -> #NAME? | K19: {=_xll.BDP("AR620065 Corp","YL016")} -> #NAME? | L19: {=_xll.BDP("AR620065 Corp","PR004")} -> #NAME? | M19: {=_xll.BDP("AR620065 Corp","PR002")} -> #NAME? | N19: {=_xll.BDP("AR620065 Corp","ID028")} -> #NAME? | O19: {=_xll.BDP("AR620065 Corp","ID005")} -> #NAME? | P19: {=_xll.BDP(A19,"RA007")} -> #NAME? | Q19: {=_xll.BDP(A19,"DS219")} -> #NAME? | R19: {=_xll.BDP(A19,"DS040")} -> #NAME? | S19: =(F19-TODAY())/365.25 -> #NAME? | T19: =S19-ROUNDDOWN(S19,0) -> #NAME? | U19: =DATE(2026,MONTH(TODAY()),DAY(F19))>DATEVALUE(R19) -> #NAME?
A20: AR775109 Corp | B20: {=_xll.BDP("AR775109 Corp","DS520")} -> #NAME? | C20: {=_xll.BDP("AR775109 Corp","DS001")} -> #NAME? | D20: {=_xll.BDP("AR775109 Corp","DS458")} -> #NAME? | E20: {=_xll.BDP("AR775109 Corp","DS004")} -> #NAME? | F20: {=_xll.BDP("AR775109 Corp","DS035")} -> #NAME? | G20: {=_xll.BDP("AR775109 Corp","DS086")} -> #NAME? | H20: {=_xll.BDP("AR775109 Corp","DS034")} -> #NAME? | I20: {=_xll.BDP("AR775109 Corp","DS033")} -> #NAME? | J20: {=_xll.BDP("AR775109 Corp","YL018")} -> #NAME? | K20: {=_xll.BDP("AR775109 Corp","YL016")} -> #NAME? | L20: {=_xll.BDP("AR775109 Corp","PR004")} -> #NAME? | M20: {=_xll.BDP("AR775109 Corp","PR002")} -> #NAME? | N20: {=_xll.BDP("AR775109 Corp","ID028")} -> #NAME? | O20: {=_xll.BDP("AR775109 Corp","ID005")} -> #NAME? | P20: {=_xll.BDP(A20,"RA007")} -> #NAME? | Q20: {=_xll.BDP(A20,"DS219")} -> #NAME? | R20: {=_xll.BDP(A20,"DS040")} -> #NAME? | S20: =(F20-TODAY())/365.25 -> #NAME? | T20: =S20-ROUNDDOWN(S20,0) -> #NAME? | U20: =DATE(2026,MONTH(TODAY()),DAY(F20))>DATEVALUE(R20) -> #NAME?
A21: AS843222 Corp | B21: {=_xll.BDP("AS843222 Corp","DS520")} -> #NAME? | C21: {=_xll.BDP("AS843222 Corp","DS001")} -> #NAME? | D21: {=_xll.BDP("AS843222 Corp","DS458")} -> #NAME? | E21: {=_xll.BDP("AS843222 Corp","DS004")} -> #NAME? | F21: {=_xll.BDP("AS843222 Corp","DS035")} -> #NAME? | G21: {=_xll.BDP("AS843222 Corp","DS086")} -> #NAME? | H21: {=_xll.BDP("AS843222 Corp","DS034")} -> #NAME? | I21: {=_xll.BDP("AS843222 Corp","DS033")} -> #NAME? | J21: {=_xll.BDP("AS843222 Corp","YL018")} -> #NAME? | K21: {=_xll.BDP("AS843222 Corp","YL016")} -> #NAME? | L21: {=_xll.BDP("AS843222 Corp","PR004")} -> #NAME? | M21: {=_xll.BDP("AS843222 Corp","PR002")} -> #NAME? | N21: {=_xll.BDP("AS843222 Corp","ID028")} -> #NAME? | O21: {=_xll.BDP("AS843222 Corp","ID005")} -> #NAME? | P21: {=_xll.BDP(A21,"RA007")} -> #NAME? | Q21: {=_xll.BDP(A21,"DS219")} -> #NAME? | R21: {=_xll.BDP(A21,"DS040")} -> #NAME? | S21: =(F21-TODAY())/365.25 -> #NAME? | T21: =S21-ROUNDDOWN(S21,0) -> #NAME? | U21: =DATE(2026,MONTH(TODAY()),DAY(F21))>DATEVALUE(R21) -> #NAME?
A22: AT427280 Corp | B22: {=_xll.BDP("AT427280 Corp","DS520")} -> #NAME? | C22: {=_xll.BDP("AT427280 Corp","DS001")} -> #NAME? | D22: {=_xll.BDP("AT427280 Corp","DS458")} -> #NAME? | E22: {=_xll.BDP("AT427280 Corp","DS004")} -> #NAME? | F22: {=_xll.BDP("AT427280 Corp","DS035")} -> #NAME? | G22: {=_xll.BDP("AT427280 Corp","DS086")} -> #NAME? | H22: {=_xll.BDP("AT427280 Corp","DS034")} -> #NAME? | I22: {=_xll.BDP("AT427280 Corp","DS033")} -> #NAME? | J22: {=_xll.BDP("AT427280 Corp","YL018")} -> #NAME? | K22: {=_xll.BDP("AT427280 Corp","YL016")} -> #NAME? | L22: {=_xll.BDP("AT427280 Corp","PR004")} -> #NAME? | M22: {=_xll.BDP("AT427280 Corp","PR002")} -> #NAME? | N22: {=_xll.BDP("AT427280 Corp","ID028")} -> #NAME? | O22: {=_xll.BDP("AT427280 Corp","ID005")} -> #NAME? | P22: {=_xll.BDP(A22,"RA007")} -> #NAME? | Q22: {=_xll.BDP(A22,"DS219")} -> #NAME? | R22: {=_xll.BDP(A22,"DS040")} -> #NAME? | S22: =(F22-TODAY())/365.25 -> #NAME? | T22: =S22-ROUNDDOWN(S22,0) -> #NAME? | U22: =DATE(2026,MONTH(TODAY()),DAY(F22))>DATEVALUE(R22) -> #NAME?
A23: AT476518 Corp | B23: {=_xll.BDP("AT476518 Corp","DS520")} -> #NAME? | C23: {=_xll.BDP("AT476518 Corp","DS001")} -> #NAME? | D23: {=_xll.BDP("AT476518 Corp","DS458")} -> #NAME? | E23: {=_xll.BDP("AT476518 Corp","DS004")} -> #NAME? | F23: {=_xll.BDP("AT476518 Corp","DS035")} -> #NAME? | G23: {=_xll.BDP("AT476518 Corp","DS086")} -> #NAME? | H23: {=_xll.BDP("AT476518 Corp","DS034")} -> #NAME? | I23: {=_xll.BDP("AT476518 Corp","DS033")} -> #NAME? | J23: {=_xll.BDP("AT476518 Corp","YL018")} -> #NAME? | K23: {=_xll.BDP("AT476518 Corp","YL016")} -> #NAME? | L23: {=_xll.BDP("AT476518 Corp","PR004")} -> #NAME? | M23: {=_xll.BDP("AT476518 Corp","PR002")} -> #NAME? | N23: {=_xll.BDP("AT476518 Corp","ID028")} -> #NAME? | O23: {=_xll.BDP("AT476518 Corp","ID005")} -> #NAME? | P23: {=_xll.BDP(A23,"RA007")} -> #NAME? | Q23: {=_xll.BDP(A23,"DS219")} -> #NAME? | R23: {=_xll.BDP(A23,"DS040")} -> #NAME? | S23: =(F23-TODAY())/365.25 -> #NAME? | T23: =S23-ROUNDDOWN(S23,0) -> #NAME? | U23: =DATE(2026,MONTH(TODAY()),DAY(F23))>DATEVALUE(R23) -> #NAME?
A24: AT578853 Corp | B24: {=_xll.BDP("AT578853 Corp","DS520")} -> #NAME? | C24: {=_xll.BDP("AT578853 Corp","DS001")} -> #NAME? | D24: {=_xll.BDP("AT578853 Corp","DS458")} -> #NAME? | E24: {=_xll.BDP("AT578853 Corp","DS004")} -> #NAME? | F24: {=_xll.BDP("AT578853 Corp","DS035")} -> #NAME? | G24: {=_xll.BDP("AT578853 Corp","DS086")} -> #NAME? | H24: {=_xll.BDP("AT578853 Corp","DS034")} -> #NAME? | I24: {=_xll.BDP("AT578853 Corp","DS033")} -> #NAME? | J24: {=_xll.BDP("AT578853 Corp","YL018")} -> #NAME? | K24: {=_xll.BDP("AT578853 Corp","YL016")} -> #NAME? | L24: {=_xll.BDP("AT578853 Corp","PR004")} -> #NAME? | M24: {=_xll.BDP("AT578853 Corp","PR002")} -> #NAME? | N24: {=_xll.BDP("AT578853 Corp","ID028")} -> #NAME? | O24: {=_xll.BDP("AT578853 Corp","ID005")} -> #NAME? | P24: {=_xll.BDP(A24,"RA007")} -> #NAME? | Q24: {=_xll.BDP(A24,"DS219")} -> #NAME? | R24: {=_xll.BDP(A24,"DS040")} -> #NAME? | S24: =(F24-TODAY())/365.25 -> #NAME? | T24: =S24-ROUNDDOWN(S24,0) -> #NAME? | U24: =DATE(2026,MONTH(TODAY()),DAY(F24))>DATEVALUE(R24) -> #NAME?
A25: AU788839 Corp | B25: {=_xll.BDP("AU788839 Corp","DS520")} -> #NAME? | C25: {=_xll.BDP("AU788839 Corp","DS001")} -> #NAME? | D25: {=_xll.BDP("AU788839 Corp","DS458")} -> #NAME? | E25: {=_xll.BDP("AU788839 Corp","DS004")} -> #NAME? | F25: {=_xll.BDP("AU788839 Corp","DS035")} -> #NAME? | G25: {=_xll.BDP("AU788839 Corp","DS086")} -> #NAME? | H25: {=_xll.BDP("AU788839 Corp","DS034")} -> #NAME? | I25: {=_xll.BDP("AU788839 Corp","DS033")} -> #NAME? | J25: {=_xll.BDP("AU788839 Corp","YL018")} -> #NAME? | K25: {=_xll.BDP("AU788839 Corp","YL016")} -> #NAME? | L25: {=_xll.BDP("AU788839 Corp","PR004")} -> #NAME? | M25: {=_xll.BDP("AU788839 Corp","PR002")} -> #NAME? | N25: {=_xll.BDP("AU788839 Corp","ID028")} -> #NAME? | O25: {=_xll.BDP("AU788839 Corp","ID005")} -> #NAME? | P25: {=_xll.BDP(A25,"RA007")} -> #NAME? | Q25: {=_xll.BDP(A25,"DS219")} -> #NAME? | R25: {=_xll.BDP(A25,"DS040")} -> #NAME? | S25: =(F25-TODAY())/365.25 -> #NAME? | T25: =S25-ROUNDDOWN(S25,0) -> #NAME? | U25: =DATE(2026,MONTH(TODAY()),DAY(F25))>DATEVALUE(R25) -> #NAME?
A26: AU951286 Corp | B26: {=_xll.BDP("AU951286 Corp","DS520")} -> #NAME? | C26: {=_xll.BDP("AU951286 Corp","DS001")} -> #NAME? | D26: {=_xll.BDP("AU951286 Corp","DS458")} -> #NAME? | E26: {=_xll.BDP("AU951286 Corp","DS004")} -> #NAME? | F26: {=_xll.BDP("AU951286 Corp","DS035")} -> #NAME? | G26: {=_xll.BDP("AU951286 Corp","DS086")} -> #NAME? | H26: {=_xll.BDP("AU951286 Corp","DS034")} -> #NAME? | I26: {=_xll.BDP("AU951286 Corp","DS033")} -> #NAME? | J26: {=_xll.BDP("AU951286 Corp","YL018")} -> #NAME? | K26: {=_xll.BDP("AU951286 Corp","YL016")} -> #NAME? | L26: {=_xll.BDP("AU951286 Corp","PR004")} -> #NAME? | M26: {=_xll.BDP("AU951286 Corp","PR002")} -> #NAME? | N26: {=_xll.BDP("AU951286 Corp","ID028")} -> #NAME? | O26: {=_xll.BDP("AU951286 Corp","ID005")} -> #NAME? | P26: {=_xll.BDP(A26,"RA007")} -> #NAME? | Q26: {=_xll.BDP(A26,"DS219")} -> #NAME? | R26: {=_xll.BDP(A26,"DS040")} -> #NAME? | S26: =(F26-TODAY())/365.25 -> #NAME? | T26: =S26-ROUNDDOWN(S26,0) -> #NAME? | U26: =DATE(2026,MONTH(TODAY()),DAY(F26))>DATEVALUE(R26) -> #NAME?
A27: AV122750 Corp | B27: {=_xll.BDP("AV122750 Corp","DS520")} -> #NAME? | C27: {=_xll.BDP("AV122750 Corp","DS001")} -> #NAME? | D27: {=_xll.BDP("AV122750 Corp","DS458")} -> #NAME? | E27: {=_xll.BDP("AV122750 Corp","DS004")} -> #NAME? | F27: {=_xll.BDP("AV122750 Corp","DS035")} -> #NAME? | G27: {=_xll.BDP("AV122750 Corp","DS086")} -> #NAME? | H27: {=_xll.BDP("AV122750 Corp","DS034")} -> #NAME? | I27: {=_xll.BDP("AV122750 Corp","DS033")} -> #NAME? | J27: {=_xll.BDP("AV122750 Corp","YL018")} -> #NAME? | K27: {=_xll.BDP("AV122750 Corp","YL016")} -> #NAME? | L27: {=_xll.BDP("AV122750 Corp","PR004")} -> #NAME? | M27: {=_xll.BDP("AV122750 Corp","PR002")} -> #NAME? | N27: {=_xll.BDP("AV122750 Corp","ID028")} -> #NAME? | O27: {=_xll.BDP("AV122750 Corp","ID005")} -> #NAME? | P27: {=_xll.BDP(A27,"RA007")} -> #NAME? | Q27: {=_xll.BDP(A27,"DS219")} -> #NAME? | R27: {=_xll.BDP(A27,"DS040")} -> #NAME? | S27: =(F27-TODAY())/365.25 -> #NAME? | T27: =S27-ROUNDDOWN(S27,0) -> #NAME? | U27: =DATE(2026,MONTH(TODAY()),DAY(F27))>DATEVALUE(R27) -> #NAME?
A28: AW566680 Corp | B28: {=_xll.BDP("AW566680 Corp","DS520")} -> #NAME? | C28: {=_xll.BDP("AW566680 Corp","DS001")} -> #NAME? | D28: {=_xll.BDP("AW566680 Corp","DS458")} -> #NAME? | E28: {=_xll.BDP("AW566680 Corp","DS004")} -> #NAME? | F28: {=_xll.BDP("AW566680 Corp","DS035")} -> #NAME? | G28: {=_xll.BDP("AW566680 Corp","DS086")} -> #NAME? | H28: {=_xll.BDP("AW566680 Corp","DS034")} -> #NAME? | I28: {=_xll.BDP("AW566680 Corp","DS033")} -> #NAME? | J28: {=_xll.BDP("AW566680 Corp","YL018")} -> #NAME? | K28: {=_xll.BDP("AW566680 Corp","YL016")} -> #NAME? | L28: {=_xll.BDP("AW566680 Corp","PR004")} -> #NAME? | M28: {=_xll.BDP("AW566680 Corp","PR002")} -> #NAME? | N28: {=_xll.BDP("AW566680 Corp","ID028")} -> #NAME? | O28: {=_xll.BDP("AW566680 Corp","ID005")} -> #NAME? | P28: {=_xll.BDP(A28,"RA007")} -> #NAME? | Q28: {=_xll.BDP(A28,"DS219")} -> #NAME? | R28: {=_xll.BDP(A28,"DS040")} -> #NAME? | S28: =(F28-TODAY())/365.25 -> #NAME? | T28: =S28-ROUNDDOWN(S28,0) -> #NAME? | U28: =DATE(2026,MONTH(TODAY()),DAY(F28))>DATEVALUE(R28) -> #NAME?
A29: AW634174 Corp | B29: {=_xll.BDP("AW634174 Corp","DS520")} -> #NAME? | C29: {=_xll.BDP("AW634174 Corp","DS001")} -> #NAME? | D29: {=_xll.BDP("AW634174 Corp","DS458")} -> #NAME? | E29: {=_xll.BDP("AW634174 Corp","DS004")} -> #NAME? | F29: {=_xll.BDP("AW634174 Corp","DS035")} -> #NAME? | G29: {=_xll.BDP("AW634174 Corp","DS086")} -> #NAME? | H29: {=_xll.BDP("AW634174 Corp","DS034")} -> #NAME? | I29: {=_xll.BDP("AW634174 Corp","DS033")} -> #NAME? | J29: {=_xll.BDP("AW634174 Corp","YL018")} -> #NAME? | K29: {=_xll.BDP("AW634174 Corp","YL016")} -> #NAME? | L29: {=_xll.BDP("AW634174 Corp","PR004")} -> #NAME? | M29: {=_xll.BDP("AW634174 Corp","PR002")} -> #NAME? | N29: {=_xll.BDP("AW634174 Corp","ID028")} -> #NAME? | O29: {=_xll.BDP("AW634174 Corp","ID005")} -> #NAME? | P29: {=_xll.BDP(A29,"RA007")} -> #NAME? | Q29: {=_xll.BDP(A29,"DS219")} -> #NAME? | R29: {=_xll.BDP(A29,"DS040")} -> #NAME? | S29: =(F29-TODAY())/365.25 -> #NAME? | T29: =S29-ROUNDDOWN(S29,0) -> #NAME? | U29: =DATE(2026,MONTH(TODAY()),DAY(F29))>DATEVALUE(R29) -> #NAME?
A30: AW892884 Corp | B30: {=_xll.BDP("AW892884 Corp","DS520")} -> #NAME? | C30: {=_xll.BDP("AW892884 Corp","DS001")} -> #NAME? | D30: {=_xll.BDP("AW892884 Corp","DS458")} -> #NAME? | E30: {=_xll.BDP("AW892884 Corp","DS004")} -> #NAME? | F30: {=_xll.BDP("AW892884 Corp","DS035")} -> #NAME? | G30: {=_xll.BDP("AW892884 Corp","DS086")} -> #NAME? | H30: {=_xll.BDP("AW892884 Corp","DS034")} -> #NAME? | I30: {=_xll.BDP("AW892884 Corp","DS033")} -> #NAME? | J30: {=_xll.BDP("AW892884 Corp","YL018")} -> #NAME? | K30: {=_xll.BDP("AW892884 Corp","YL016")} -> #NAME? | L30: {=_xll.BDP("AW892884 Corp","PR004")} -> #NAME? | M30: {=_xll.BDP("AW892884 Corp","PR002")} -> #NAME? | N30: {=_xll.BDP("AW892884 Corp","ID028")} -> #NAME? | O30: {=_xll.BDP("AW892884 Corp","ID005")} -> #NAME? | P30: {=_xll.BDP(A30,"RA007")} -> #NAME? | Q30: {=_xll.BDP(A30,"DS219")} -> #NAME? | R30: {=_xll.BDP(A30,"DS040")} -> #NAME? | S30: =(F30-TODAY())/365.25 -> #NAME? | T30: =S30-ROUNDDOWN(S30,0) -> #NAME? | U30: =DATE(2026,MONTH(TODAY()),DAY(F30))>DATEVALUE(R30) -> #NAME?
A31: AX991345 Corp | B31: {=_xll.BDP("AX991345 Corp","DS520")} -> #NAME? | C31: {=_xll.BDP("AX991345 Corp","DS001")} -> #NAME? | D31: {=_xll.BDP("AX991345 Corp","DS458")} -> #NAME? | E31: {=_xll.BDP("AX991345 Corp","DS004")} -> #NAME? | F31: {=_xll.BDP("AX991345 Corp","DS035")} -> #NAME? | G31: {=_xll.BDP("AX991345 Corp","DS086")} -> #NAME? | H31: {=_xll.BDP("AX991345 Corp","DS034")} -> #NAME? | I31: {=_xll.BDP("AX991345 Corp","DS033")} -> #NAME? | J31: {=_xll.BDP("AX991345 Corp","YL018")} -> #NAME? | K31: {=_xll.BDP("AX991345 Corp","YL016")} -> #NAME? | L31: {=_xll.BDP("AX991345 Corp","PR004")} -> #NAME? | M31: {=_xll.BDP("AX991345 Corp","PR002")} -> #NAME? | N31: {=_xll.BDP("AX991345 Corp","ID028")} -> #NAME? | O31: {=_xll.BDP("AX991345 Corp","ID005")} -> #NAME? | P31: {=_xll.BDP(A31,"RA007")} -> #NAME? | Q31: {=_xll.BDP(A31,"DS219")} -> #NAME? | R31: {=_xll.BDP(A31,"DS040")} -> #NAME? | S31: =(F31-TODAY())/365.25 -> #NAME? | T31: =S31-ROUNDDOWN(S31,0) -> #NAME? | U31: =DATE(2026,MONTH(TODAY()),DAY(F31))>DATEVALUE(R31) -> #NAME?
A32: AZ459860 Corp | B32: {=_xll.BDP("AZ459860 Corp","DS520")} -> #NAME? | C32: {=_xll.BDP("AZ459860 Corp","DS001")} -> #NAME? | D32: {=_xll.BDP("AZ459860 Corp","DS458")} -> #NAME? | E32: {=_xll.BDP("AZ459860 Corp","DS004")} -> #NAME? | F32: {=_xll.BDP("AZ459860 Corp","DS035")} -> #NAME? | G32: {=_xll.BDP("AZ459860 Corp","DS086")} -> #NAME? | H32: {=_xll.BDP("AZ459860 Corp","DS034")} -> #NAME? | I32: {=_xll.BDP("AZ459860 Corp","DS033")} -> #NAME? | J32: {=_xll.BDP("AZ459860 Corp","YL018")} -> #NAME? | K32: {=_xll.BDP("AZ459860 Corp","YL016")} -> #NAME? | L32: {=_xll.BDP("AZ459860 Corp","PR004")} -> #NAME? | M32: {=_xll.BDP("AZ459860 Corp","PR002")} -> #NAME? | N32: {=_xll.BDP("AZ459860 Corp","ID028")} -> #NAME? | O32: {=_xll.BDP("AZ459860 Corp","ID005")} -> #NAME? | P32: {=_xll.BDP(A32,"RA007")} -> #NAME? | Q32: {=_xll.BDP(A32,"DS219")} -> #NAME? | R32: {=_xll.BDP(A32,"DS040")} -> #NAME? | S32: =(F32-TODAY())/365.25 -> #NAME? | T32: =S32-ROUNDDOWN(S32,0) -> #NAME? | U32: =DATE(2026,MONTH(TODAY()),DAY(F32))>DATEVALUE(R32) -> #NAME?
A33: AZ527231 Corp | B33: {=_xll.BDP("AZ527231 Corp","DS520")} -> #NAME? | C33: {=_xll.BDP("AZ527231 Corp","DS001")} -> #NAME? | D33: {=_xll.BDP("AZ527231 Corp","DS458")} -> #NAME? | E33: {=_xll.BDP("AZ527231 Corp","DS004")} -> #NAME? | F33: {=_xll.BDP("AZ527231 Corp","DS035")} -> #NAME? | G33: {=_xll.BDP("AZ527231 Corp","DS086")} -> #NAME? | H33: {=_xll.BDP("AZ527231 Corp","DS034")} -> #NAME? | I33: {=_xll.BDP("AZ527231 Corp","DS033")} -> #NAME? | J33: {=_xll.BDP("AZ527231 Corp","YL018")} -> #NAME? | K33: {=_xll.BDP("AZ527231 Corp","YL016")} -> #NAME? | L33: {=_xll.BDP("AZ527231 Corp","PR004")} -> #NAME? | M33: {=_xll.BDP("AZ527231 Corp","PR002")} -> #NAME? | N33: {=_xll.BDP("AZ527231 Corp","ID028")} -> #NAME? | O33: {=_xll.BDP("AZ527231 Corp","ID005")} -> #NAME? | P33: {=_xll.BDP(A33,"RA007")} -> #NAME? | Q33: {=_xll.BDP(A33,"DS219")} -> #NAME? | R33: {=_xll.BDP(A33,"DS040")} -> #NAME? | S33: =(F33-TODAY())/365.25 -> #NAME? | T33: =S33-ROUNDDOWN(S33,0) -> #NAME? | U33: =DATE(2026,MONTH(TODAY()),DAY(F33))>DATEVALUE(R33) -> #NAME?
A34: AZ694472 Corp | B34: {=_xll.BDP("AZ694472 Corp","DS520")} -> #NAME? | C34: {=_xll.BDP("AZ694472 Corp","DS001")} -> #NAME? | D34: {=_xll.BDP("AZ694472 Corp","DS458")} -> #NAME? | E34: {=_xll.BDP("AZ694472 Corp","DS004")} -> #NAME? | F34: {=_xll.BDP("AZ694472 Corp","DS035")} -> #NAME? | G34: {=_xll.BDP("AZ694472 Corp","DS086")} -> #NAME? | H34: {=_xll.BDP("AZ694472 Corp","DS034")} -> #NAME? | I34: {=_xll.BDP("AZ694472 Corp","DS033")} -> #NAME? | J34: {=_xll.BDP("AZ694472 Corp","YL018")} -> #NAME? | K34: {=_xll.BDP("AZ694472 Corp","YL016")} -> #NAME? | L34: {=_xll.BDP("AZ694472 Corp","PR004")} -> #NAME? | M34: {=_xll.BDP("AZ694472 Corp","PR002")} -> #NAME? | N34: {=_xll.BDP("AZ694472 Corp","ID028")} -> #NAME? | O34: {=_xll.BDP("AZ694472 Corp","ID005")} -> #NAME? | P34: {=_xll.BDP(A34,"RA007")} -> #NAME? | Q34: {=_xll.BDP(A34,"DS219")} -> #NAME? | R34: {=_xll.BDP(A34,"DS040")} -> #NAME? | S34: =(F34-TODAY())/365.25 -> #NAME? | T34: =S34-ROUNDDOWN(S34,0) -> #NAME? | U34: =DATE(2026,MONTH(TODAY()),DAY(F34))>DATEVALUE(R34) -> #NAME?
A35: BH527948 Corp | B35: {=_xll.BDP("BH527948 Corp","DS520")} -> #NAME? | C35: {=_xll.BDP("BH527948 Corp","DS001")} -> #NAME? | D35: {=_xll.BDP("BH527948 Corp","DS458")} -> #NAME? | E35: {=_xll.BDP("BH527948 Corp","DS004")} -> #NAME? | F35: {=_xll.BDP("BH527948 Corp","DS035")} -> #NAME? | G35: {=_xll.BDP("BH527948 Corp","DS086")} -> #NAME? | H35: {=_xll.BDP("BH527948 Corp","DS034")} -> #NAME? | I35: {=_xll.BDP("BH527948 Corp","DS033")} -> #NAME? | J35: {=_xll.BDP("BH527948 Corp","YL018")} -> #NAME? | K35: {=_xll.BDP("BH527948 Corp","YL016")} -> #NAME? | L35: {=_xll.BDP("BH527948 Corp","PR004")} -> #NAME? | M35: {=_xll.BDP("BH527948 Corp","PR002")} -> #NAME? | N35: {=_xll.BDP("BH527948 Corp","ID028")} -> #NAME? | O35: {=_xll.BDP("BH527948 Corp","ID005")} -> #NAME? | P35: {=_xll.BDP(A35,"RA007")} -> #NAME? | Q35: {=_xll.BDP(A35,"DS219")} -> #NAME? | R35: {=_xll.BDP(A35,"DS040")} -> #NAME? | S35: =(F35-TODAY())/365.25 -> #NAME? | T35: =S35-ROUNDDOWN(S35,0) -> #NAME? | U35: =DATE(2026,MONTH(TODAY()),DAY(F35))>DATEVALUE(R35) -> #NAME?
A36: BH620692 Corp | B36: {=_xll.BDP("BH620692 Corp","DS520")} -> #NAME? | C36: {=_xll.BDP("BH620692 Corp","DS001")} -> #NAME? | D36: {=_xll.BDP("BH620692 Corp","DS458")} -> #NAME? | E36: {=_xll.BDP("BH620692 Corp","DS004")} -> #NAME? | F36: {=_xll.BDP("BH620692 Corp","DS035")} -> #NAME? | G36: {=_xll.BDP("BH620692 Corp","DS086")} -> #NAME? | H36: {=_xll.BDP("BH620692 Corp","DS034")} -> #NAME? | I36: {=_xll.BDP("BH620692 Corp","DS033")} -> #NAME? | J36: {=_xll.BDP("BH620692 Corp","YL018")} -> #NAME? | K36: {=_xll.BDP("BH620692 Corp","YL016")} -> #NAME? | L36: {=_xll.BDP("BH620692 Corp","PR004")} -> #NAME? | M36: {=_xll.BDP("BH620692 Corp","PR002")} -> #NAME? | N36: {=_xll.BDP("BH620692 Corp","ID028")} -> #NAME? | O36: {=_xll.BDP("BH620692 Corp","ID005")} -> #NAME? | P36: {=_xll.BDP(A36,"RA007")} -> #NAME? | Q36: {=_xll.BDP(A36,"DS219")} -> #NAME? | R36: {=_xll.BDP(A36,"DS040")} -> #NAME? | S36: =(F36-TODAY())/365.25 -> #NAME? | T36: =S36-ROUNDDOWN(S36,0) -> #NAME? | U36: =DATE(2026,MONTH(TODAY()),DAY(F36))>DATEVALUE(R36) -> #NAME?
A37: BI018471 Corp | B37: {=_xll.BDP("BI018471 Corp","DS520")} -> #NAME? | C37: {=_xll.BDP("BI018471 Corp","DS001")} -> #NAME? | D37: {=_xll.BDP("BI018471 Corp","DS458")} -> #NAME? | E37: {=_xll.BDP("BI018471 Corp","DS004")} -> #NAME? | F37: {=_xll.BDP("BI018471 Corp","DS035")} -> #NAME? | G37: {=_xll.BDP("BI018471 Corp","DS086")} -> #NAME? | H37: {=_xll.BDP("BI018471 Corp","DS034")} -> #NAME? | I37: {=_xll.BDP("BI018471 Corp","DS033")} -> #NAME? | J37: {=_xll.BDP("BI018471 Corp","YL018")} -> #NAME? | K37: {=_xll.BDP("BI018471 Corp","YL016")} -> #NAME? | L37: {=_xll.BDP("BI018471 Corp","PR004")} -> #NAME? | M37: {=_xll.BDP("BI018471 Corp","PR002")} -> #NAME? | N37: {=_xll.BDP("BI018471 Corp","ID028")} -> #NAME? | O37: {=_xll.BDP("BI018471 Corp","ID005")} -> #NAME? | P37: {=_xll.BDP(A37,"RA007")} -> #NAME? | Q37: {=_xll.BDP(A37,"DS219")} -> #NAME? | R37: {=_xll.BDP(A37,"DS040")} -> #NAME? | S37: =(F37-TODAY())/365.25 -> #NAME? | T37: =S37-ROUNDDOWN(S37,0) -> #NAME? | U37: =DATE(2026,MONTH(TODAY()),DAY(F37))>DATEVALUE(R37) -> #NAME?
A38: BJ706274 Corp | B38: {=_xll.BDP("BJ706274 Corp","DS520")} -> #NAME? | C38: {=_xll.BDP("BJ706274 Corp","DS001")} -> #NAME? | D38: {=_xll.BDP("BJ706274 Corp","DS458")} -> #NAME? | E38: {=_xll.BDP("BJ706274 Corp","DS004")} -> #NAME? | F38: {=_xll.BDP("BJ706274 Corp","DS035")} -> #NAME? | G38: {=_xll.BDP("BJ706274 Corp","DS086")} -> #NAME? | H38: {=_xll.BDP("BJ706274 Corp","DS034")} -> #NAME? | I38: {=_xll.BDP("BJ706274 Corp","DS033")} -> #NAME? | J38: {=_xll.BDP("BJ706274 Corp","YL018")} -> #NAME? | K38: {=_xll.BDP("BJ706274 Corp","YL016")} -> #NAME? | L38: {=_xll.BDP("BJ706274 Corp","PR004")} -> #NAME? | M38: {=_xll.BDP("BJ706274 Corp","PR002")} -> #NAME? | N38: {=_xll.BDP("BJ706274 Corp","ID028")} -> #NAME? | O38: {=_xll.BDP("BJ706274 Corp","ID005")} -> #NAME? | P38: {=_xll.BDP(A38,"RA007")} -> #NAME? | Q38: {=_xll.BDP(A38,"DS219")} -> #NAME? | R38: {=_xll.BDP(A38,"DS040")} -> #NAME? | S38: =(F38-TODAY())/365.25 -> #NAME? | T38: =S38-ROUNDDOWN(S38,0) -> #NAME? | U38: =DATE(2026,MONTH(TODAY()),DAY(F38))>DATEVALUE(R38) -> #NAME?
A39: BK340998 Corp | B39: {=_xll.BDP("BK340998 Corp","DS520")} -> #NAME? | C39: {=_xll.BDP("BK340998 Corp","DS001")} -> #NAME? | D39: {=_xll.BDP("BK340998 Corp","DS458")} -> #NAME? | E39: {=_xll.BDP("BK340998 Corp","DS004")} -> #NAME? | F39: {=_xll.BDP("BK340998 Corp","DS035")} -> #NAME? | G39: {=_xll.BDP("BK340998 Corp","DS086")} -> #NAME? | H39: {=_xll.BDP("BK340998 Corp","DS034")} -> #NAME? | I39: {=_xll.BDP("BK340998 Corp","DS033")} -> #NAME? | J39: {=_xll.BDP("BK340998 Corp","YL018")} -> #NAME? | K39: {=_xll.BDP("BK340998 Corp","YL016")} -> #NAME? | L39: {=_xll.BDP("BK340998 Corp","PR004")} -> #NAME? | M39: {=_xll.BDP("BK340998 Corp","PR002")} -> #NAME? | N39: {=_xll.BDP("BK340998 Corp","ID028")} -> #NAME? | O39: {=_xll.BDP("BK340998 Corp","ID005")} -> #NAME? | P39: {=_xll.BDP(A39,"RA007")} -> #NAME? | Q39: {=_xll.BDP(A39,"DS219")} -> #NAME? | R39: {=_xll.BDP(A39,"DS040")} -> #NAME? | S39: =(F39-TODAY())/365.25 -> #NAME? | T39: =S39-ROUNDDOWN(S39,0) -> #NAME? | U39: =DATE(2026,MONTH(TODAY()),DAY(F39))>DATEVALUE(R39) -> #NAME?
A40: BK411989 Corp | B40: {=_xll.BDP("BK411989 Corp","DS520")} -> #NAME? | C40: {=_xll.BDP("BK411989 Corp","DS001")} -> #NAME? | D40: {=_xll.BDP("BK411989 Corp","DS458")} -> #NAME? | E40: {=_xll.BDP("BK411989 Corp","DS004")} -> #NAME? | F40: {=_xll.BDP("BK411989 Corp","DS035")} -> #NAME? | G40: {=_xll.BDP("BK411989 Corp","DS086")} -> #NAME? | H40: {=_xll.BDP("BK411989 Corp","DS034")} -> #NAME? | I40: {=_xll.BDP("BK411989 Corp","DS033")} -> #NAME? | J40: {=_xll.BDP("BK411989 Corp","YL018")} -> #NAME? | K40: {=_xll.BDP("BK411989 Corp","YL016")} -> #NAME? | L40: {=_xll.BDP("BK411989 Corp","PR004")} -> #NAME? | M40: {=_xll.BDP("BK411989 Corp","PR002")} -> #NAME? | N40: {=_xll.BDP("BK411989 Corp","ID028")} -> #NAME? | O40: {=_xll.BDP("BK411989 Corp","ID005")} -> #NAME? | P40: {=_xll.BDP(A40,"RA007")} -> #NAME? | Q40: {=_xll.BDP(A40,"DS219")} -> #NAME? | R40: {=_xll.BDP(A40,"DS040")} -> #NAME? | S40: =(F40-TODAY())/365.25 -> #NAME? | T40: =S40-ROUNDDOWN(S40,0) -> #NAME? | U40: =DATE(2026,MONTH(TODAY()),DAY(F40))>DATEVALUE(R40) -> #NAME?
...

Sheet Offline
A1: Instrument | B1: Name | C1: Ticker | D1: Country/Region | E1: Currency | F1: Maturity | G1: Coupon Type | H1: Coupon Frequency | I1: Coupon | J1: Ask Yield to Maturity | K1: Bid Yield to Maturity | L1: Ask Price | M1: Bid Price | N1: Identifier | O1: ISIN | P1: Bloomberg Composite Rating | Q1: Announce | R1: Next Coupon Settle Date | S1: Time | T1: AVG price | U1: id | V1: TIMEish | W1: years ago | X1: Accrued Interest | Y1: Clean price | Z1: AVG yield
A2: AL516835 Corp | B2: Japan Government Ten Year Bond | C2: JGB | D2: JP | E2: JPY | F2: 20/12/2026 | G2: FIXED | H2: 2 | I2: 0.1 | J2: 0.957 | K2: 0.979 | L2: 99.34 | M2: 99.323 | N2: AL5168359 | O2: JP1103451GC0 | P2: A+ | Q2: 42705 | R2: 46193 | S2: =(F2-TODAY())/365.25 -> 0.72553046 | T2: =AVERAGE(L2:M2) -> 99.3315 | U2: {=_xlfn.SEQUENCE(COUNTA(A2:A327))} -> 1 | V2: =ROUNDDOWN(S2,0)+IF(S2-ROUNDDOWN(S2,0)>0.5,0.5,0) -> 0.5 | W2: =YEAR(TODAY())-YEAR(Q2) -> 10 | X2: =(TODAY()-DATE(YEAR(R2),MONTH(R2)-6,DAY(R2)))/182*(I2) -> 0.054945055 | Y2: =T2-X2 -> 99.276555 | Z2: =AVERAGE(J2:K2) -> 0.968
A3: AL662876 Corp | B3: Japan Government Thirty Year Bond | C3: JGB | D3: JP | E3: JPY | F3: 20/12/2046 | G3: FIXED | H3: 2 | I3: 0.6 | J3: 3.94 | K3: 3.975 | L3: 61.843 | M3: 61.597 | N3: AL6628765 | O3: JP1300531GC0 | P3: A+ | Q3: 42712 | R3: 46193 | S3: =(F3-TODAY())/365.25 -> 20.72553 | T3: =AVERAGE(L3:M3) -> 61.72 | U3: 2 | V3: =ROUNDDOWN(S3,0)+IF(S3-ROUNDDOWN(S3,0)>0.5,0.5,0) -> 20.5 | W3: =YEAR(TODAY())-YEAR(Q3) -> 10 | X3: =(TODAY()-DATE(YEAR(R3),MONTH(R3)-6,DAY(R3)))/182*(I3) -> 0.32967033 | Y3: =T3-X3 -> 61.39033 | Z3: =AVERAGE(J3:K3) -> 3.9575
A4: AL797512 Corp | B4: Japan Government Twenty Year Bond | C4: JGB | D4: JP | E4: JPY | F4: 20/12/2036 | G4: FIXED | H4: 2 | I4: 0.6 | J4: 2.469 | K4: 2.493 | L4: 84.092 | M4: 83.921 | N4: AL7975124 | O4: JP1201591GC4 | P4: A+ | Q4: 42719 | R4: 46193 | S4: =(F4-TODAY())/365.25 -> 10.726899 | T4: =AVERAGE(L4:M4) -> 84.0065 | U4: 3 | V4: =ROUNDDOWN(S4,0)+IF(S4-ROUNDDOWN(S4,0)>0.5,0.5,0) -> 10.5 | W4: =YEAR(TODAY())-YEAR(Q4) -> 10 | X4: =(TODAY()-DATE(YEAR(R4),MONTH(R4)-6,DAY(R4)))/182*(I4) -> 0.32967033 | Y4: =T4-X4 -> 83.67683 | Z4: =AVERAGE(J4:K4) -> 2.481
A5: AM713129 Corp | B5: Japan Government Ten Year Bond | C5: JGB | D5: JP | E5: JPY | F5: 20/03/2027 | G5: FIXED | H5: 2 | I5: 0.1 | J5: 1 | K5: 1.021 | L5: 99.089 | M5: 99.068 | N5: AM7131296 | O5: JP1103461H35 | P5: A+ | Q5: 42796 | R5: 46101 | S5: =(F5-TODAY())/365.25 -> 0.97193703 | T5: =AVERAGE(L5:M5) -> 99.0785 | U5: 4 | V5: =ROUNDDOWN(S5,0)+IF(S5-ROUNDDOWN(S5,0)>0.5,0.5,0) -> 0.5 | W5: =YEAR(TODAY())-YEAR(Q5) -> 9 | X5: =(TODAY()-DATE(YEAR(R5),MONTH(R5)-6,DAY(R5)))/182*(I5) -> 0.10494505 | Y5: =T5-X5 -> 98.973555 | Z5: =AVERAGE(J5:K5) -> 1.0105
A6: AM766737 Corp | B6: Japan Government Thirty Year Bond | C6: JGB | D6: JP | E6: JPY | F6: 20/03/2047 | G6: FIXED | H6: 2 | I6: 0.8 | J6: 3.862 | K6: 3.901 | L6: 64.473 | M6: 64.183 | N6: AM7667372 | O6: JP1300541H31 | P6: A+ | Q6: 42801 | R6: 46101 | S6: =(F6-TODAY())/365.25 -> 20.971937 | T6: =AVERAGE(L6:M6) -> 64.328 | U6: 5 | V6: =ROUNDDOWN(S6,0)+IF(S6-ROUNDDOWN(S6,0)>0.5,0.5,0) -> 20.5 | W6: =YEAR(TODAY())-YEAR(Q6) -> 9 | X6: =(TODAY()-DATE(YEAR(R6),MONTH(R6)-6,DAY(R6)))/182*(I6) -> 0.83956044 | Y6: =T6-X6 -> 63.48844 | Z6: =AVERAGE(J6:K6) -> 3.8815
A7: AM850328 Corp | B7: Japan Government Twenty Year Bond | C7: JGB | D7: JP | E7: JPY | F7: 20/03/2037 | G7: FIXED | H7: 2 | I7: 0.7 | J7: 2.49 | K7: 2.516 | L7: 84.519 | M7: 84.329 | N7: AM8503287 | O7: JP1201601H38 | P7: A+ | Q7: 42808 | R7: 46101 | S7: =(F7-TODAY())/365.25 -> 10.973306 | T7: =AVERAGE(L7:M7) -> 84.424 | U7: 6 | V7: =ROUNDDOWN(S7,0)+IF(S7-ROUNDDOWN(S7,0)>0.5,0.5,0) -> 10.5 | W7: =YEAR(TODAY())-YEAR(Q7) -> 9 | X7: =(TODAY()-DATE(YEAR(R7),MONTH(R7)-6,DAY(R7)))/182*(I7) -> 0.73461538 | Y7: =T7-X7 -> 83.689385 | Z7: =AVERAGE(J7:K7) -> 2.503
A8: AN751153 Corp | B8: Japan Government Forty Year Bond | C8: JGB | D8: JP | E8: JPY | F8: 20/03/2057 | G8: FIXED | H8: 2 | I8: 0.9 | J8: 4.63 | K8: 4.69 | L8: 52.505 | M8: 52.107 | N8: AN7511537 | O8: JP1400101H56 | P8: A+ | Q8: 42880 | R8: 46101 | S8: =(F8-TODAY())/365.25 -> 30.973306 | T8: =AVERAGE(L8:M8) -> 52.306 | U8: 7 | V8: =ROUNDDOWN(S8,0)+IF(S8-ROUNDDOWN(S8,0)>0.5,0.5,0) -> 30.5 | W8: =YEAR(TODAY())-YEAR(Q8) -> 9 | X8: =(TODAY()-DATE(YEAR(R8),MONTH(R8)-6,DAY(R8)))/182*(I8) -> 0.94450549 | Y8: =T8-X8 -> 51.361495 | Z8: =AVERAGE(J8:K8) -> 4.66
A9: AN821370 Corp | B9: Japan Government Ten Year Bond | C9: JGB | D9: JP | E9: JPY | F9: 20/06/2027 | G9: FIXED | H9: 2 | I9: 0.1 | J9: 1.062 | K9: 1.085 | L9: 98.79 | M9: 98.762 | N9: AN8213703 | O9: JP1103471H66 | P9: A+ | Q9: 42887 | R9: 46193 | S9: =(F9-TODAY())/365.25 -> 1.2238193 | T9: =AVERAGE(L9:M9) -> 98.776 | U9: 8 | V9: =ROUNDDOWN(S9,0)+IF(S9-ROUNDDOWN(S9,0)>0.5,0.5,0) -> 1 | W9: =YEAR(TODAY())-YEAR(Q9) -> 9 | X9: =(TODAY()-DATE(YEAR(R9),MONTH(R9)-6,DAY(R9)))/182*(I9) -> 0.054945055 | Y9: =T9-X9 -> 98.721055 | Z9: =AVERAGE(J9:K9) -> 1.0735
A10: AN861997 Corp | B10: Japan Government Thirty Year Bond | C10: JGB | D10: JP | E10: JPY | F10: 20/06/2047 | G10: FIXED | H10: 2 | I10: 0.8 | J10: 3.895 | K10: 3.934 | L10: 63.993 | M10: 63.704 | N10: AN8619974 | O10: JP1300551H61 | P10: A+ | Q10: 42892 | R10: 46193 | S10: =(F10-TODAY())/365.25 -> 21.223819 | T10: =AVERAGE(L10:M10) -> 63.8485 | U10: 9 | V10: =ROUNDDOWN(S10,0)+IF(S10-ROUNDDOWN(S10,0)>0.5,0.5,0) -> 21 | W10: =YEAR(TODAY())-YEAR(Q10) -> 9 | X10: =(TODAY()-DATE(YEAR(R10),MONTH(R10)-6,DAY(R10)))/182*(I10) -> 0.43956044 | Y10: =T10-X10 -> 63.40894 | Z10: =AVERAGE(J10:K10) -> 3.9145
A11: AN958432 Corp | B11: Japan Government Twenty Year Bond | C11: JGB | D11: JP | E11: JPY | F11: 20/06/2037 | G11: FIXED | H11: 2 | I11: 0.6 | J11: 2.551 | K11: 2.576 | L11: 82.917 | M11: 82.736 | N11: AN9584326 | O11: JP1201611H69 | P11: A+ | Q11: 42899 | R11: 46193 | S11: =(F11-TODAY())/365.25 -> 11.225188 | T11: =AVERAGE(L11:M11) -> 82.8265 | U11: 10 | V11: =ROUNDDOWN(S11,0)+IF(S11-ROUNDDOWN(S11,0)>0.5,0.5,0) -> 11 | W11: =YEAR(TODAY())-YEAR(Q11) -> 9 | X11: =(TODAY()-DATE(YEAR(R11),MONTH(R11)-6,DAY(R11)))/182*(I11) -> 0.32967033 | Y11: =T11-X11 -> 82.49683 | Z11: =AVERAGE(J11:K11) -> 2.5635
A12: AP027592 Corp | B12: Japan Government Ten Year Bond | C12: JGB | D12: JP | E12: JPY | F12: 20/09/2027 | G12: FIXED | H12: 2 | I12: 0.1 | J12: 1.138 | K12: 1.161 | L12: 98.443 | M12: 98.409 | N12: AP0275929 | O12: JP1103481H98 | P12: A+ | Q12: 42983 | R12: 46101 | S12: =(F12-TODAY())/365.25 -> 1.4757016 | T12: =AVERAGE(L12:M12) -> 98.426 | U12: 11 | V12: =ROUNDDOWN(S12,0)+IF(S12-ROUNDDOWN(S12,0)>0.5,0.5,0) -> 1 | W12: =YEAR(TODAY())-YEAR(Q12) -> 9 | X12: =(TODAY()-DATE(YEAR(R12),MONTH(R12)-6,DAY(R12)))/182*(I12) -> 0.10494505 | Y12: =T12-X12 -> 98.321055 | Z12: =AVERAGE(J12:K12) -> 1.1495
A13: AP059339 Corp | B13: Japan Government Thirty Year Bond | C13: JGB | D13: JP | E13: JPY | F13: 20/09/2047 | G13: FIXED | H13: 2 | I13: 0.8 | J13: 3.927 | K13: 3.964 | L13: 63.523 | M13: 63.25 | N13: AP0593396 | O13: JP1300561H93 | P13: A+ | Q13: 42985 | R13: 46101 | S13: =(F13-TODAY())/365.25 -> 21.475702 | T13: =AVERAGE(L13:M13) -> 63.3865 | U13: 12 | V13: =ROUNDDOWN(S13,0)+IF(S13-ROUNDDOWN(S13,0)>0.5,0.5,0) -> 21 | W13: =YEAR(TODAY())-YEAR(Q13) -> 9 | X13: =(TODAY()-DATE(YEAR(R13),MONTH(R13)-6,DAY(R13)))/182*(I13) -> 0.83956044 | Y13: =T13-X13 -> 62.54694 | Z13: =AVERAGE(J13:K13) -> 3.9455
A14: AP155275 Corp | B14: Japan Government Twenty Year Bond | C14: JGB | D14: JP | E14: JPY | F14: 20/09/2037 | G14: FIXED | H14: 2 | I14: 0.6 | J14: 2.584 | K14: 2.61 | L14: 82.38 | M14: 82.19 | N14: AP1552755 | O14: JP1201621H91 | P14: A+ | Q14: 42992 | R14: 46101 | S14: =(F14-TODAY())/365.25 -> 11.47707 | T14: =AVERAGE(L14:M14) -> 82.285 | U14: 13 | V14: =ROUNDDOWN(S14,0)+IF(S14-ROUNDDOWN(S14,0)>0.5,0.5,0) -> 11 | W14: =YEAR(TODAY())-YEAR(Q14) -> 9 | X14: =(TODAY()-DATE(YEAR(R14),MONTH(R14)-6,DAY(R14)))/182*(I14) -> 0.62967033 | Y14: =T14-X14 -> 81.65533 | Z14: =AVERAGE(J14:K14) -> 2.597
... A327: ZS877644 Corp | B327: Japan Government Forty Year Bond | C327: JGB | D327: JP | E327: JPY | F327: 20/03/2059 | G327: FIXED | H327: 2 | I327: 0.5 | J327: 5.212 | K327: 5.281 | L327: 42.817 | M327: 42.462 | N327: ZS8776446 | O327: JP1400121K57 | P327: A+ | Q327: 43613 | R327: 46101 | S327: =(F327-TODAY())/365.25 -> 32.971937 | T327: =AVERAGE(L327:M327) -> 42.6395 | U327: 326 | V327: =ROUNDDOWN(S327,0)+IF(S327-ROUNDDOWN(S327,0)>0.5,0.5,0) -> 32.5 | W327: =YEAR(TODAY())-YEAR(Q327) -> 7 | X327: =(TODAY()-DATE(YEAR(R327),MONTH(R327)-6,DAY(R327)))/182*(I327) -> 0.52472527 | Y327: =T327-X327 -> 42.114775 | Z327: =AVERAGE(J327:K327) -> 5.2465

Sheet SORT
A1: {=+OFFSET(Offline!A1,,,1,COUNTA(Offline!1:1))} -> Instrument | B1: Name | C1: Ticker | D1: Country/Region | E1: Currency | F1: Maturity | G1: Coupon Type | H1: Coupon Frequency | I1: Coupon | J1: Ask Yield to Maturity | K1: Bid Yield to Maturity | L1: Ask Price | M1: Bid Price | N1: Identifier | O1: ISIN | P1: Bloomberg Composite Rating | Q1: Announce | R1: Next Coupon Settle Date | S1: Time | T1: AVG price | U1: id | V1: TIMEish | W1: years ago | X1: Accrued Interest | Y1: Clean price | Z1: AVG yield
A2: {=_xlfn._xlws.SORT(OFFSET(Offline!A2,,,COUNTA(Offline!A:A)-1,COUNTA(Offline!1:1)),COLUMN(Offline!S1))} -> BO997638 Corp | B2: Japan Government Five Year Bond | C2: JGB | D2: JP | E2: JPY | F2: 20/03/2026 | G2: FIXED | H2: 2 | I2: 0.005 | J2: 0.74800001 | K2: 0.76600001 | L2: 99.983 | M2: 99.983 | N2: BO9976388 | O2: JP1051471M45 | P2: A+ | Q2: 44287 | R2: 46101 | S2: -0.027378508 | T2: 99.983 | U2: 47 | V2: 0 | W2: 5 | X2: 0.0052472527 | Y2: 99.977753 | Z2: 0.75700001
A3: EF329501 Corp | B3: Japan Government Twenty Year Bond | C3: JGB | D3: JP | E3: JPY | F3: 20/03/2026 | G3: FIXED | H3: 2 | I3: 2.1 | J3: 0.748 | K3: 0.771 | L3: 100.029 | M3: 100.029 | N3: EF3295013 | O3: JP1200851630 | P3: A+ | Q3: 38792 | R3: 46101 | S3: -0.027378508 | T3: 100.029 | U3: 103 | V3: 0 | W3: 20 | X3: 2.2038462 | Y3: 97.825154 | Z3: 0.7595
A4: EF381218 Corp | B4: Japan Government Twenty Year Bond | C4: JGB | D4: JP | E4: JPY | F4: 20/03/2026 | G4: FIXED | H4: 2 | I4: 2.3 | J4: 0.736 | K4: 0.768 | L4: 100.034 | M4: 100.033 | N4: EF3812189 | O4: JP1200861647 | P4: A+ | Q4: 38832 | R4: 46101 | S4: -0.027378508 | T4: 100.0335 | U4: 105 | V4: 0 | W4: 20 | X4: 2.4137363 | Y4: 97.619764 | Z4: 0.752
A5: EF452796 Corp | B5: Japan Government Twenty Year Bond | C5: JGB | D5: JP | E5: JPY | F5: 20/03/2026 | G5: FIXED | H5: 2 | I5: 2.2 | J5: 0.737 | K5: 0.762 | L5: 100.032 | M5: 100.031 | N5: EF4527968 | O5: JP1200871653 | P5: A+ | Q5: 38862 | R5: 46101 | S5: -0.027378508 | T5: 100.0315 | U5: 106 | V5: 0 | W5: 20 | X5: 2.3087912 | Y5: 97.722709 | Z5: 0.7495
A6: JK298261 Corp | B6: Japan Government Ten Year Bond | C6: JGB | D6: JP | E6: JPY | F6: 20/03/2026 | G6: FIXED | H6: 2 | I6: 0.1 | J6: 0.74 | K6: 0.763 | L6: 99.985 | M6: 99.985 | N6: JK2982615 | O6: JP1103421G35 | P6: A+ | Q6: 42430 | R6: 46101 | S6: -0.027378508 | T6: 99.985 | U6: 206 | V6: 0 | W6: 10 | X6: 0.10494505 | Y6: 99.880055 | Z6: 0.7515
A7: ZB137529 Corp | B7: Japan Government Two Year Bond | C7: JGB | D7: JP | E7: JPY | F7: 01/04/2026 | G7: FIXED | H7: 2 | I7: 0.2 | J7: 0.735 | K7: 0.75800001 | L7: 99.97 | M7: 99.969 | N7: ZB1375292 | O7: JP1024591Q43 | P7: A+ | Q7: 45373 | R7: 46113 | S7: 0.0054757016 | T7: 99.9695 | U7: 280 | V7: 0 | W7: 2 | X7: 0.1978022 | Y7: 99.771698 | Z7: 0.7465
A8: ZB651229 Corp | B8: Japan Government Two Year Bond | C8: JGB | D8: JP | E8: JPY | F8: 01/05/2026 | G8: FIXED | H8: 2 | I8: 0.3 | J8: 0.75 | K8: 0.773 | L8: 99.938 | M8: 99.935 | N8: ZB6512295 | O8: JP1024601Q58 | P8: A+ | Q8: 45398 | R8: 46143 | S8: 0.087611225 | T8: 99.9365 | U8: 285 | V8: 0 | W8: 2 | X8: 0.2456044 | Y8: 99.690896 | Z8: 0.7615
A9: YX440521 Corp | B9: Japan Government Two Year Bond | C9: JGB | D9: JP | E9: JPY | F9: 01/06/2026 | G9: FIXED | H9: 2 | I9: 0.4 | J9: 0.763 | K9: 0.785 | L9: 99.919 | M9: 99.914 | N9: YX4405214 | O9: JP1024611Q64 | P9: A+ | Q9: 45435 | R9: 46174 | S9: 0.1724846 | T9: 99.9165 | U9: 278 | V9: 0 | W9: 2 | X9: 0.26153846 | Y9: 99.654962 | Z9: 0.774
A10: BQ447894 Corp | B10: Japan Government Five Year Bond | C10: JGB | D10: JP | E10: JPY | F10: 20/06/2026 | G10: FIXED | H10: 2 | I10: 0.005 | J10: 0.78 | K10: 0.803 | L10: 99.788 | M10: 99.781 | N10: BQ4478948 | O10: JP1051481M76 | P10: NR | Q10: 44378 | R10: 46193 | S10: 0.22450376 | T10: 99.7845 | U10: 52 | V10: 0 | W10: 5 | X10: 0.0027472527 | Y10: 99.781753 | Z10: 0.7915
A11: EF500367 Corp | B11: Japan Government Twenty Year Bond | C11: JGB | D11: JP | E11: JPY | F11: 20/06/2026 | G11: FIXED | H11: 2 | I11: 2.3 | J11: 0.786 | K11: 0.81 | L11: 100.413 | M11: 100.407 | N11: EF5003670 | O11: JP1200881660 | P11: A+ | Q11: 38888 | R11: 46193 | S11: 0.22450376 | T11: 100.41 | U11: 107 | V11: 0 | W11: 20 | X11: 1.2637363 | Y11: 99.146264 | Z11: 0.798
A12: EF659299 Corp | B12: Japan Government Twenty Year Bond | C12: JGB | D12: JP | E12: JPY | F12: 20/06/2026 | G12: FIXED | H12: 2 | I12: 2.2 | J12: 0.78 | K12: 0.81 | L12: 100.388 | M12: 100.379 | N12: EF6592994 | O12: JP1200891685 | P12: A+ | Q12: 38953 | R12: 46193 | S12: 0.22450376 | T12: 100.3835 | U12: 109 | V12: 0 | W12: 20 | X12: 1.2087912 | Y12: 99.174709 | Z12: 0.795
A13: LW316486 Corp | B13: Japan Government Ten Year Bond | C13: JGB | D13: JP | E13: JPY | F13: 20/06/2026 | G13: FIXED | H13: 2 | I13: 0.1 | J13: 0.772 | K13: 0.794 | L13: 99.816 | M13: 99.81 | N13: LW3164867 | O13: JP1103431G66 | P13: A+ | Q13: 42523 | R13: 46193 | S13: 0.22450376 | T13: 99.813 | U13: 212 | V13: 0 | W13: 10 | X13: 0.054945055 | Y13: 99.758055 | Z13: 0.783
A14: YW041715 Corp | B14: Japan Government Two Year Bond | C14: JGB | D14: JP | E14: JPY | F14: 01/07/2026 | G14: FIXED | H14: 2 | I14: 0.4 | J14: 0.79 | K14: 0.813 | L14: 99.881 | M14: 99.874 | N14: YW0417157 | O14: JP1024621Q70 | P14: A+ | Q14: 45463 | R14: 46204 | S14: 0.25462012 | T14: 99.8775 | U14: 268 | V14: 0 | W14: 2 | X14: 0.19340659 | Y14: 99.684093 | Z14: 0.8015
... A327: YO939740 Corp | B327: Japan Government Forty Year Bond | C327: JGB | D327: JP | E327: JPY | F327: 20/03/2065 | G327: FIXED | H327: 2 | I327: 3.1 | J327: 3.611 | K327: 3.669 | L327: 91.722 | M327: 90.869 | N327: YO9397408 | O327: JP1400181R57 | P327: A+ | Q327: 45798 | R327: 46101 | S327: 38.973306 | T327: 91.2955 | U327: 241 | V327: 38.5 | W327: 1 | X327: 3.2532967 | Y327: 88.042203 | Z327: 3.64

Sheet ID filter
A1: ID | B1: {=_xlfn.ANCHORARRAY(SORT!A1)} -> Instrument | C1: Name | D1: Ticker | E1: Country/Region | F1: Currency | G1: Maturity | H1: Coupon Type | I1: Coupon Frequency | J1: Coupon | K1: Ask Yield to Maturity | L1: Bid Yield to Maturity | M1: Ask Price | N1: Bid Price | O1: Identifier | P1: ISIN | Q1: Bloomberg Composite Rating | R1: Announce | S1: Next Coupon Settle Date | T1: Time | U1: AVG price | V1: id | W1: TIMEish | X1: years ago | Y1: Accrued Interest | Z1: Clean price | AA1: AVG yield
A2: 251 | B2: {=_xlfn.XLOOKUP(A2,SORT!$U$2:$U$327,_xlfn.ANCHORARRAY(SORT!$A$2),,0)} -> YR907955 Corp | C2: Japan Government Two Year Bond | D2: JGB | E2: JP | F2: JPY | G2: 01/03/2027 | H2: FIXED | I2: 2 | J2: 0.8 | K2: 0.976 | L2: 0.999 | M2: 99.83 | N2: 99.808 | O2: YR9079553 | P2: JP1024701R31 | Q2: A+ | R2: 45708 | S2: 46266 | T2: 0.91991786 | U2: 99.819 | V2: 251 | W2: 0.5 | X2: 1 | Y2: 0.12747253 | Z2: 99.691527 | AA2: 0.9875
A3: 232 | B3: {=_xlfn.XLOOKUP(A3,SORT!$U$2:$U$327,_xlfn.ANCHORARRAY(SORT!$A$2),,0)} -> YL701515 Corp | C3: Japan Government Two Year Bond | D3: JGB | E3: JP | F3: JPY | G3: 01/09/2027 | H3: FIXED | I3: 2 | J3: 0.9 | K3: 1.132 | L3: 1.151 | M3: 99.663 | N3: 99.636 | O3: YL7015156 | P3: JP1024761R95 | Q3: A+ | R3: 45890 | S3: 46266 | T3: 1.4236824 | U3: 99.6495 | V3: 232 | W3: 1 | X3: 1 | Y3: 0.14340659 | Z3: 99.506093 | AA3: 1.1415
A4: 17 | B4: {=_xlfn.XLOOKUP(A4,SORT!$U$2:$U$327,_xlfn.ANCHORARRAY(SORT!$A$2),,0)} -> AR545005 Corp | C4: Japan Government Ten Year Bond | D4: JGB | E4: JP | F4: JPY | G4: 20/03/2028 | H4: FIXED | I4: 2 | J4: 0.1 | K4: 1.213 | L4: 1.236 | M4: 97.803 | N4: 97.759 | O4: AR5450051 | P4: JP1103501J35 | Q4: A+ | R4: 43160 | S4: 46101 | T4: 1.9739904 | U4: 97.781 | V4: 17 | W4: 1.5 | X4: 8 | Y4: 0.10494505 | Z4: 97.676055 | AA4: 1.2245
A5: 21 | B5: {=_xlfn.XLOOKUP(A5,SORT!$U$2:$U$327,_xlfn.ANCHORARRAY(SORT!$A$2),,0)} -> AT427280 Corp | C5: Japan Government Ten Year Bond | D5: JGB | E5: JP | F5: JPY | G5: 20/06/2028 | H5: FIXED | I5: 2 | J5: 0.1 | K5: 1.241 | L5: 1.262 | M5: 97.476 | N5: 97.431 | O5: AT4272809 | P5: JP1103511J74 | Q5: A+ | R5: 43284 | S5: 46193 | T5: 2.2258727 | U5: 97.4535 | V5: 21 | W5: 2 | X5: 8 | Y5: 0.054945055 | Z5: 97.398555 | AA5: 1.2515
A6: 27 | B6: {=_xlfn.XLOOKUP(A6,SORT!$U$2:$U$327,_xlfn.ANCHORARRAY(SORT!$A$2),,0)} -> AW566680 Corp | C6: Japan Government Ten Year Bond | D6: JGB | E6: JP | F6: JPY | G6: 20/12/2028 | H6: FIXED | I6: 2 | J6: 0.1 | K6: 1.322 | L6: 1.344 | M6: 96.728 | N6: 96.671 | O6: AW5666804 | P6: JP1103531K10 | Q6: A+ | R6: 43473 | S6: 46193 | T6: 2.7268994 | U6: 96.6995 | V6: 27 | W6: 2.5 | X6: 7 | Y6: 0.054945055 | Z6: 96.644555 | AA6: 1.333
A7: 31 | B7: {=_xlfn.XLOOKUP(A7,SORT!$U$2:$U$327,_xlfn.ANCHORARRAY(SORT!$A$2),,0)} -> AZ459860 Corp | C7: Japan Government Ten Year Bond | D7: JGB | E7: JP | F7: JPY | G7: 20/06/2029 | H7: FIXED | I7: 2 | J7: 0.1 | K7: 1.416 | L7: 1.44 | M7: 95.882 | N7: 95.81 | O7: AZ4598605 | P7: JP1103551K72 | Q7: A+ | R7: 43648 | S7: 46193 | T7: 3.2251882 | U7: 95.846 | V7: 31 | W7: 3 | X7: 7 | Y7: 0.054945055 | Z7: 95.791055 | AA7: 1.428
A8: 323 | B8: {=_xlfn.XLOOKUP(A8,SORT!$U$2:$U$327,_xlfn.ANCHORARRAY(SORT!$A$2),,0)} -> ZR885925 Corp | C8: Japan Government Ten Year Bond | D8: JGB | E8: JP | F8: JPY | G8: 20/09/2029 | H8: FIXED | I8: 2 | J8: 0.1 | K8: 1.46 | L8: 1.482 | M8: 95.439 | N8: 95.369 | O8: ZR8859251 | P8: JP1103561KA2 | Q8: A+ | R8: 43739 | S8: 46101 | T8: 3.4770705 | U8: 95.404 | V8: 323 | W8: 3 | X8: 7 | Y8: 0.10494505 | Z8: 95.299055 | AA8: 1.471
A9: 38 | B9: {=_xlfn.XLOOKUP(A9,SORT!$U$2:$U$327,_xlfn.ANCHORARRAY(SORT!$A$2),,0)} -> BK340998 Corp | C9: Japan Government Ten Year Bond | D9: JGB | E9: JP | F9: JPY | G9: 20/06/2030 | H9: FIXED | I9: 2 | J9: 0.1 | K9: 1.58 | L9: 1.603 | M9: 94.074 | N9: 93.988 | O9: BK3409988 | P9: JP1103591L73 | Q9: A+ | R9: 44007 | S9: 46193 | T9: 4.2245038 | U9: 94.031 | V9: 38 | W9: 4 | X9: 6 | Y9: 0.054945055 | Z9: 93.976055 | AA9: 1.5915
